File: TestData.csv
Time,Crosshead separation,Load,Extensometer elongation
(sec),(mm),(kN),(%)
0,-0.00004,0.26954,-0.06349
0.2,0.00328,0.27345,-0.06345
0.4,0.00936,0.30209,-0.06336
0.6,0.02004,0.47899,-0.06257
0.762,0.0322,0.68219,-0.06163
0.912,0.04628,0.88486,-0.06072
1.042,0.061,1.08906,-0.05986
1.154,0.07536,1.29291,-0.05911
1.256,0.08972,1.4976,-0.05823
1.35,0.10396,1.70074,-0.05742
1.436,0.11792,1.90293,-0.05655
1.518,0.13184,2.10705,-0.05571
1.6,0.1464,2.31301,-0.05487
1.7,0.16508,2.51518,-0.05404
1.804,0.18576,2.72213,-0.05322
1.898,0.20548,2.92717,-0.0524
1.984,0.22428,3.13488,-0.0516
2.064,0.24236,3.33978,-0.05076
2.138,0.25968,3.54556,-0.04994
2.208,0.27644,3.7498,-0.0491
2.276,0.29316,3.9555,-0.04825
2.34,0.30928,4.15918,-0.04747
2.402,0.32532,4.36326,-0.04662
2.462,0.34104,4.56716,-0.04578
2.522,0.35708,4.77746,-0.04491
2.578,0.37232,4.98085,-0.0441
2.634,0.38784,5.18941,-0.04319
2.69,0.40348,5.40223,-0.04237
2.742,0.41796,5.60396,-0.04154
2.794,0.4326,5.80871,-0.04072
2.846,0.44748,6.01986,-0.03989
2.896,0.46196,6.22759,-0.0391
2.946,0.4766,6.43659,-0.03829
2.994,0.49076,6.64091,-0.03748
3.042,0.50504,6.84969,-0.0366
3.09,0.51948,7.0592,-0.03573
3.138,0.53396,7.27105,-0.03487
3.186,0.54852,7.48551,-0.03402
3.234,0.56316,7.69896,-0.03315
3.282,0.578,7.91541,-0.03234
3.326,0.59164,8.11688,-0.03151
3.374,0.6066,8.3323,-0.03064
3.422,0.62168,8.54881,-0.02984
3.468,0.63624,8.75758,-0.02902
3.516,0.65156,8.97354,-0.02814
3.56,0.66568,9.17562,-0.02734
3.604,0.67992,9.38207,-0.02652
3.648,0.6942,9.59026,-0.02567
3.692,0.70864,9.79836,-0.02481
3.736,0.72304,10.00766,-0.02398
3.78,0.73748,10.21477,-0.02316
3.824,0.75204,10.42009,-0.02232
3.868,0.76672,10.6277,-0.02149
3.912,0.78144,10.83115,-0.02068
3.958,0.79696,11.03924,-0.01992
4.006,0.81316,11.25372,-0.01904
4.054,0.82956,11.46723,-0.01826
4.102,0.84608,11.67803,-0.01742
4.15,0.86264,11.89441,-0.01653
4.194,0.87792,12.09587,-0.01578
4.238,0.89332,12.30304,-0.01494
4.282,0.90876,12.51882,-0.01409
4.326,0.9242,12.73685,-0.01319
4.368,0.939,12.94707,-0.01234
4.408,0.95312,13.15225,-0.01155
4.448,0.96732,13.35692,-0.01075
4.488,0.98156,13.56335,-0.00992
4.528,0.99584,13.77431,-0.00911
4.568,1.01016,13.98294,-0.00829
4.608,1.02456,14.19414,-0.00748
4.648,1.039,14.40801,-0.00669
4.688,1.0534,14.62322,-0.00583
4.728,1.06788,14.83696,-0.005
4.768,1.08236,15.05348,-0.00417
4.808,1.09688,15.27192,-0.00328
4.848,1.11148,15.49086,-0.00245
4.886,1.12536,15.70005,-0.00162
4.926,1.14,15.92069,-0.00076
4.966,1.15472,16.14104,0.0001
5.004,1.16868,16.35119,0.00091
5.04,1.18192,16.55427,0.00173
5.076,1.19512,16.75609,0.00253
5.112,1.20836,16.95793,0.0033
5.148,1.22156,17.16292,0.00413
5.184,1.23484,17.36841,0.00489
5.22,1.24808,17.57364,0.00578
5.256,1.26132,17.77895,0.00659
5.292,1.2746,17.98852,0.00739
5.328,1.28792,18.19485,0.00821
5.364,1.30124,18.40084,0.00903
5.4,1.3146,18.61029,0.00981
5.436,1.32788,18.81705,0.01062
5.472,1.3412,19.0244,0.0114
5.508,1.35456,19.23525,0.01218
5.544,1.36792,19.4493,0.01297
5.58,1.38132,19.66143,0.01383
5.616,1.39468,19.87363,0.01468
5.652,1.40808,20.09005,0.01552
5.688,1.42148,20.30461,0.01644
5.724,1.43492,20.51777,0.01731
5.76,1.44832,20.73499,0.01818
5.796,1.46168,20.95046,0.01904
5.832,1.47508,21.16083,0.01987
5.868,1.48844,21.37317,0.0207
5.904,1.5018,21.58903,0.02155
5.94,1.5152,21.80545,0.02235
5.976,1.5286,22.02211,0.02316
6.012,1.542,22.24304,0.02403
6.048,1.55544,22.46249,0.0248
6.084,1.56888,22.68356,0.02564
6.12,1.58228,22.9057,0.02654
6.156,1.59568,23.12833,0.02744
6.192,1.60904,23.34821,0.02829
6.228,1.62244,23.56783,0.02919
6.264,1.63584,23.7908,0.03008
6.3,1.64924,24.01124,0.03093
6.336,1.6626,24.2297,0.03179
6.37,1.67528,24.44143,0.03265
6.402,1.68724,24.64214,0.03348
6.436,1.69996,24.85416,0.0343
6.468,1.71188,25.05673,0.03507
6.502,1.7244,25.26895,0.03591
6.538,1.73768,25.48965,0.03682
6.574,1.75092,25.71114,0.0377
6.608,1.76344,25.92369,0.03852
6.64,1.77528,26.12492,0.03932
6.676,1.78852,26.34685,0.04024
6.712,1.80184,26.56741,0.04108
6.746,1.81436,26.77961,0.0419
6.78,1.82696,26.99233,0.04279
6.814,1.83956,27.20451,0.04364
6.846,1.85132,27.40633,0.04444
6.878,1.86308,27.6098,0.0453
6.91,1.87484,27.8119,0.04607
6.942,1.8866,28.01382,0.04691
6.974,1.89836,28.21718,0.0477
7.006,1.91004,28.42066,0.04861
7.04,1.92244,28.6331,0.04945
7.076,1.93556,28.85617,0.05039
7.108,1.9472,29.05756,0.05119
7.142,1.95956,29.26999,0.05201
7.178,1.97268,29.49348,0.05297
7.214,1.9858,29.71775,0.05383
7.246,1.99744,29.91826,0.05468
7.278,2.00908,30.11961,0.05547
7.31,2.02068,30.32121,0.05628
7.342,2.03228,30.52378,0.05716
7.374,2.04376,30.72508,0.05802
7.41,2.05668,30.94941,0.05898
7.446,2.0696,31.17376,0.05998
7.478,2.08108,31.37501,0.06084
7.51,2.09256,31.57631,0.06161
7.544,2.10476,31.78915,0.0625
7.58,2.11764,32.01169,0.06342
7.616,2.13044,32.23438,0.06438
7.652,2.14324,32.45611,0.06534
7.688,2.15604,32.67748,0.06628
7.724,2.1688,32.90113,0.06726
7.76,2.18152,33.1254,0.06821
7.796,2.1942,33.34895,0.0692
7.832,2.20688,33.57248,0.07018
7.866,2.21884,33.7842,0.07112
7.902,2.23148,34.00657,0.07211
7.938,2.24404,34.22772,0.07309
7.974,2.25664,34.44801,0.07403
8.01,2.26916,34.67102,0.07503
8.046,2.28168,34.88898,0.07602
8.082,2.2942,35.1058,0.077
8.118,2.3066,35.32305,0.078
8.154,2.319,35.54097,0.07902
8.19,2.33136,35.75633,0.08004
8.226,2.34372,35.97235,0.08101
8.262,2.35608,36.19314,0.08205
8.298,2.36836,36.4109,0.08307
8.334,2.38064,36.6256,0.08409
8.37,2.39284,36.84187,0.08513
8.406,2.40496,37.05787,0.08615
8.442,2.41712,37.27019,0.08715
8.478,2.42924,37.48157,0.0881
8.514,2.44124,37.69295,0.0892
8.55,2.45324,37.90256,0.09026
8.586,2.4652,38.11088,0.09126
8.622,2.47712,38.31699,0.09227
8.658,2.48904,38.52679,0.09328
8.694,2.50084,38.73578,0.09432
8.73,2.5126,38.94046,0.09535
8.766,2.52436,39.14697,0.09639
8.802,2.536,39.35539,0.09746
8.838,2.54764,39.56177,0.09859
8.874,2.55916,39.76279,0.09973
8.912,2.57128,39.97402,0.10081
8.948,2.58272,40.17503,0.10184
8.988,2.5954,40.39585,0.103
9.028,2.60804,40.61114,0.10418
9.068,2.62068,40.82969,0.10527
9.108,2.6332,41.04517,0.10643
9.148,2.64564,41.25611,0.1076
9.188,2.658,41.46413,0.10878
9.228,2.67028,41.67451,0.10995
9.268,2.68256,41.88452,0.11117
9.308,2.69476,42.09139,0.11238
9.348,2.70692,42.29511,0.11359
9.388,2.719,42.49699,0.11487
9.432,2.73212,42.71262,0.11638
9.476,2.74528,42.9264,0.11777
9.52,2.75828,43.13663,0.11918
9.564,2.77108,43.34249,0.12065
9.612,2.78492,43.55842,0.12216
9.66,2.7986,43.77147,0.1236
9.708,2.81224,43.9832,0.12514
9.756,2.82576,44.18991,0.12659
9.806,2.83972,44.39725,0.12813
9.858,2.85412,44.6093,0.12974
9.91,2.86844,44.81501,0.13137
9.966,2.88376,45.02818,0.13303
10.024,2.89948,45.23557,0.1347
10.086,2.9162,45.44158,0.13642
10.152,2.93384,45.64809,0.13841
10.222,2.95232,45.85595,0.14077
10.304,2.97348,46.06427,0.14366
10.396,2.99676,46.26624,0.14713
10.524,3.0284,46.47086,0.14919
10.668,3.06392,46.67234,0.15498
10.868,3.10768,46.73958,0.16523
11.068,3.14464,46.70859,0.17521
11.268,3.17536,46.69252,0.18448
11.468,3.20128,46.71885,0.19274
11.668,3.22344,46.75986,0.19988
11.868,3.24368,46.82862,0.20632
12.068,3.2614,46.88208,0.21315
12.268,3.27712,46.93024,0.21938
12.468,3.29136,46.97565,0.22558
12.668,3.30432,47.01637,0.23129
12.868,3.31636,47.05993,0.23692
13.068,3.32784,47.10694,0.2423
13.268,3.3388,47.15622,0.24757
13.468,3.35008,47.2204,0.25084
13.668,3.3622,47.3236,0.25667
13.868,3.37304,47.36423,0.26263
14.068,3.3828,47.3861,0.26825
14.268,3.39204,47.41492,0.27358
14.468,3.40084,47.44682,0.27872
14.668,3.40952,47.48328,0.28374
14.868,3.418,47.52109,0.28896
15.068,3.42624,47.55401,0.29398
15.268,3.43432,47.59278,0.29904
15.468,3.44208,47.62347,0.30413
15.668,3.44988,47.65789,0.30909
15.868,3.45912,47.73985,0.31262
16.068,3.46824,47.80496,0.31876
16.268,3.47596,47.81115,0.32446
16.468,3.48268,47.80361,0.33002
16.668,3.4892,47.80844,0.33503
16.868,3.49568,47.82345,0.34003
17.068,3.50228,47.85242,0.34481
17.268,3.50888,47.887,0.34982
17.468,3.51568,47.9266,0.35471
17.668,3.52232,47.96015,0.35991
17.868,3.5288,47.98584,0.36494
18.068,3.53496,48.0007,0.37014
18.268,3.54116,48.02087,0.37499
18.468,3.54748,48.04562,0.38
18.668,3.55508,48.11417,0.38361
18.868,3.56236,48.16011,0.38964
19.068,3.56836,48.15119,0.39541
19.268,3.57352,48.12166,0.40084
19.468,3.57864,48.10708,0.40575
19.668,3.58396,48.11453,0.4108
19.868,3.58932,48.12379,0.41576
20.068,3.59468,48.1365,0.42083
20.268,3.59984,48.13797,0.4259
20.468,3.60472,48.13336,0.43099
20.668,3.6096,48.13269,0.43578
20.868,3.61456,48.13858,0.44075
21.068,3.6196,48.1464,0.44569
21.268,3.62464,48.15503,0.45076
21.468,3.62992,48.15564,0.45439
21.668,3.63644,48.21545,0.45976
21.868,3.64168,48.20455,0.46586
22.068,3.64604,48.16636,0.47143
22.268,3.65012,48.13471,0.47657
22.468,3.6542,48.11722,0.48146
22.668,3.65848,48.11496,0.4862
22.868,3.66292,48.12336,0.49116
23.068,3.66732,48.12584,0.49614
23.268,3.67172,48.12929,0.50113
23.468,3.67596,48.12387,0.5063
23.668,3.68016,48.11965,0.51132
23.868,3.68428,48.11555,0.51628
24.068,3.68852,48.11827,0.5212
24.268,3.69268,48.11849,0.52625
24.468,3.69684,48.12089,0.53122
24.668,3.701,48.11917,0.53569
24.868,3.70684,48.18122,0.54012
25.068,3.71156,48.18749,0.54629
25.268,3.7152,48.14794,0.55198
25.468,3.71832,48.09952,0.55728
25.668,3.7214,48.06311,0.56217
25.868,3.72476,48.04881,0.56695
26.068,3.72848,48.05548,0.57166
26.268,3.73224,48.06556,0.57665
26.468,3.73604,48.07024,0.58158
26.668,3.73972,48.06938,0.58679
26.868,3.7432,48.0567,0.59187
27.068,3.74672,48.0541,0.59686
27.268,3.75016,48.04999,0.60189
27.468,3.75352,48.04543,0.60696
27.668,3.75684,48.0365,0.6119
27.868,3.76016,48.03074,0.61693
28.068,3.7634,48.02609,0.62183
28.268,3.76676,48.02604,0.62671
28.468,3.77016,48.02793,0.63159
28.668,3.7736,48.03279,0.63669
28.868,3.777,48.02833,0.6418
29.068,3.78036,48.02929,0.64692
29.268,3.78352,48.0197,0.65197
29.468,3.78668,48.01586,0.65694
29.668,3.78988,48.01097,0.66181
29.868,3.793,48.01034,0.66683
30.068,3.79608,48.00432,0.67172
30.268,3.79932,48.00673,0.67662
30.468,3.80244,48.0082,0.68175
30.668,3.8056,48.00601,0.68666
30.868,3.8088,48.00873,0.69162
31.068,3.81204,48.01719,0.69662
31.268,3.81524,48.01958,0.70166
31.468,3.8184,48.02132,0.70665
31.668,3.82152,48.02131,0.71168
31.868,3.82464,48.02291,0.71667
32.068,3.82772,48.02438,0.72168
32.268,3.8308,48.02378,0.72666
32.468,3.83384,48.0235,0.73173
32.668,3.83688,48.02423,0.73668
32.868,3.83996,48.0267,0.74178
33.068,3.84312,48.03114,0.74678
33.268,3.8462,48.03393,0.75194
33.468,3.84916,48.02872,0.75701
33.668,3.852,48.02057,0.76223
33.868,3.85472,48.0071,0.76726
34.068,3.85752,48.00223,0.77212
34.268,3.86028,47.99818,0.77709
34.468,3.86316,47.99865,0.78197
34.668,3.86612,48.00296,0.78679
34.868,3.86912,48.00974,0.79176
35.068,3.87212,48.01601,0.79664
35.268,3.87516,48.02197,0.80164
35.468,3.8782,48.02756,0.80665
35.668,3.88124,48.03531,0.81168
35.868,3.88424,48.03956,0.81673
36.068,3.88716,48.04062,0.82176
36.268,3.88992,48.03469,0.82674
36.468,3.89272,48.03135,0.83169
36.668,3.89544,48.02336,0.83678
36.868,3.89808,48.01111,0.8418
37.068,3.90076,48.00534,0.84672
37.268,3.90364,48.00737,0.85167
37.468,3.9066,48.01356,0.85667
37.668,3.90964,48.02296,0.86171
37.868,3.9126,48.02312,0.8668
38.068,3.91544,48.0215,0.87194
38.268,3.91804,48.0096,0.87711
38.468,3.9206,47.99553,0.88208
38.668,3.92312,47.98431,0.88702
38.868,3.92572,47.97174,0.89185
39.068,3.92848,47.97556,0.89669
39.268,3.93132,47.98078,0.90168
39.468,3.93412,47.97914,0.90663
39.668,3.93688,47.9802,0.91166
39.868,3.93964,47.9786,0.9167
40.068,3.94232,47.97104,0.92171
40.268,3.94496,47.96604,0.92672
40.468,3.94764,47.96061,0.93175
40.668,3.95024,47.95371,0.93677
40.868,3.95292,47.95014,0.94175
41.068,3.95568,47.94966,0.94663
41.268,3.95836,47.94782,0.95164
41.468,3.96108,47.94687,0.95656
41.668,3.96384,47.94675,0.96155
41.868,3.96652,47.94442,0.96664
42.068,3.96928,47.94374,0.97161
42.268,3.97216,47.94918,0.97663
42.468,3.975,47.9528,0.98179
42.668,3.9778,47.95306,0.98688
42.868,3.98044,47.94724,0.992
43.068,3.98308,47.93997,0.99702
43.268,3.98564,47.93293,1.00206
43.468,3.98824,47.92589,1.00701
43.668,3.99084,47.92041,1.01204
43.868,3.99344,47.91337,1.01703
44.068,3.99608,47.91171,1.02183
44.268,3.99884,47.91563,1.02684
44.468,4.00164,47.91999,1.03184
44.668,4.00448,47.92515,1.03683
44.868,4.00732,47.92854,1.04196
45.068,4.01012,47.93237,1.04693
45.268,4.0156,48.0208,1.04867
45.468,4.02068,48.10272,1.05619
45.668,4.02268,48.03329,1.06319
45.868,4.0234,47.92396,1.06882
46.068,4.02428,47.83298,1.07321
46.268,4.0262,47.80509,1.07713
46.468,4.02916,47.83866,1.0813
46.668,4.03292,47.90028,1.08606
46.868,4.0366,47.94891,1.09135
47.068,4.0398,47.96548,1.09693
47.268,4.0424,47.95092,1.10239
47.468,4.04464,47.92413,1.10759
47.668,4.04688,47.89948,1.1125
47.868,4.0492,47.88444,1.11728
48.068,4.05188,47.88901,1.122
48.268,4.05464,47.89969,1.12688
48.468,4.05748,47.90647,1.13178
48.668,4.06032,47.9151,1.13685
48.868,4.06296,47.91355,1.14197
49.068,4.06552,47.90716,1.14693
49.268,4.06804,47.90168,1.15192
49.468,4.0706,47.89757,1.15683
49.668,4.07328,47.90148,1.16169
49.868,4.07604,47.90876,1.16666
50.068,4.0788,47.91454,1.1716
50.268,4.08152,47.91548,1.17665
50.468,4.08408,47.90917,1.18172
50.668,4.08664,47.90498,1.18659
50.868,4.08928,47.9034,1.19149
51.068,4.092,47.90733,1.19635
51.268,4.09488,47.92045,1.20131
51.468,4.09776,47.93001,1.20638
51.668,4.1006,47.93191,1.21155
51.868,4.10332,47.93132,1.21662
52.068,4.10596,47.92925,1.22184
52.268,4.1086,47.92143,1.22675
52.468,4.1112,47.91936,1.23191
52.668,4.11376,47.9163,1.23683
52.868,4.11648,47.91572,1.24177
53.068,4.1192,47.92443,1.24672
53.268,4.12192,47.92446,1.25175
53.468,4.1246,47.92688,1.25669
53.668,4.12724,47.92471,1.26176
53.868,4.12988,47.92301,1.26667
54.068,4.13256,47.92604,1.27166
54.268,4.13528,47.92954,1.27666
54.468,4.13808,47.93405,1.28163
54.668,4.14088,47.93762,1.2867
54.868,4.14368,47.94183,1.29185
55.068,4.14636,47.94101,1.29687
55.268,4.14892,47.93541,1.30192
55.468,4.15148,47.92887,1.30684
55.668,4.15412,47.93011,1.31177
55.868,4.15668,47.92608,1.31675
56.068,4.15944,47.93077,1.32158
56.268,4.1622,47.93732,1.32656
56.468,4.16496,47.9423,1.33163
56.668,4.1678,47.94729,1.33665
56.868,4.1706,47.95243,1.34183
57.068,4.17328,47.95268,1.34687
57.268,4.176,47.95331,1.35187
57.468,4.1786,47.94992,1.35691
57.668,4.18128,47.95011,1.36177
57.868,4.18396,47.95261,1.36683
58.068,4.18668,47.95447,1.37168
58.268,4.1894,47.95822,1.37672
58.468,4.19216,47.96062,1.38172
58.668,4.1948,47.96008,1.38678
58.868,4.19748,47.95786,1.39165
59.068,4.20008,47.96009,1.3967
59.268,4.2028,47.96178,1.40159
59.468,4.20544,47.96104,1.4067
59.668,4.20804,47.95464,1.41173
59.868,4.2106,47.95167,1.41676
60.068,4.2132,47.94688,1.42174
60.268,4.21572,47.94189,1.42677
60.468,4.21824,47.93276,1.43174
60.668,4.22064,47.91977,1.4369
60.868,4.22296,47.90184,1.44191
61.068,4.22528,47.88553,1.44696
61.268,4.22752,47.86335,1.45203
61.468,4.2298,47.84304,1.45708
61.668,4.23192,47.81645,1.46224
61.868,4.234,47.78767,1.46737
62.068,4.23616,47.7608,1.47238
62.268,4.2382,47.72976,1.4776
62.468,4.24008,47.69353,1.4826
62.668,4.24208,47.66425,1.48758
62.868,4.244,47.63236,1.49263
63.068,4.24608,47.60697,1.49755
63.268,4.24808,47.5801,1.50247
63.468,4.2502,47.56084,1.50735
63.668,4.25248,47.54758,1.51222
63.868,4.25484,47.54061,1.51719
64.068,4.25708,47.52846,1.52217
64.268,4.25948,47.51925,1.52704
64.468,4.26184,47.51244,1.53205
64.668,4.26448,47.51905,1.53686
64.868,4.2672,47.52894,1.54186
65.068,4.27004,47.54072,1.54674
65.268,4.273,47.5634,1.55178
65.468,4.276,47.58593,1.55683
65.66801,4.27888,47.60109,1.56189
65.868,4.28192,47.62294,1.56676
66.068,4.28504,47.65406,1.5718
66.26801,4.2882,47.68517,1.57673
66.468,4.29144,47.71796,1.58175
66.66801,4.29468,47.75062,1.58675
66.868,4.29792,47.78143,1.59182
67.068,4.30128,47.81885,1.59671
67.26801,4.30468,47.85817,1.60185
67.468,4.30804,47.8939,1.60677
67.66801,4.3114,47.93018,1.6119
67.868,4.31468,47.95842,1.61679
68.068,4.31804,47.99353,1.62163
68.26801,4.3214,48.02829,1.62658
68.468,4.32476,48.06019,1.63138
68.66801,4.32804,48.09063,1.63622
68.868,4.33148,48.12578,1.641
69.068,4.335,48.16463,1.64584
69.26801,4.3386,48.20499,1.65077
69.468,4.34212,48.23755,1.65587
69.66801,4.34564,48.2708,1.66072
69.868,4.34916,48.30137,1.66578
70.068,4.35264,48.32986,1.67065
70.26801,4.35628,48.36281,1.6756
70.468,4.36004,48.39752,1.68061
70.66801,4.36388,48.43234,1.68574
70.868,4.3678,48.47034,1.69081
71.068,4.37152,48.49725,1.69612
71.26801,4.3752,48.52029,1.70112
71.468,4.37884,48.54162,1.70619
71.66801,4.38236,48.56099,1.71112
71.868,4.38596,48.58469,1.71607
72.068,4.38956,48.60592,1.72093
72.26801,4.39332,48.63254,1.72582
72.468,4.3972,48.66155,1.7307
72.66801,4.40112,48.69053,1.73583
72.868,4.40508,48.71782,1.74079
73.068,4.40892,48.74063,1.74591
73.26801,4.4126,48.75462,1.75094
73.468,4.4164,48.77474,1.75574
73.66801,4.42024,48.79554,1.7607
73.868,4.42416,48.82136,1.76567
74.068,4.4282,48.84667,1.77059
74.26801,4.43232,48.8732,1.7757
74.468,4.43632,48.89035,1.7808
74.66801,4.44024,48.91028,1.78576
74.868,4.44408,48.9221,1.79077
75.068,4.44792,48.93813,1.79558
75.26801,4.452,48.95926,1.80051
75.468,4.45608,48.98117,1.80541
75.66801,4.46016,49.00228,1.81042
75.868,4.46428,49.02354,1.81535
76.068,4.46844,49.04242,1.82037
76.26801,4.47256,49.06217,1.82532
76.468,4.4766,49.07722,1.83041
76.66801,4.48068,49.09195,1.83519
76.868,4.4848,49.10937,1.84016
77.068,4.489,49.1284,1.84509
77.26801,4.4934,49.15307,1.85002
77.468,4.498,49.18166,1.85512
77.66801,4.50244,49.20133,1.86037
77.868,4.5068,49.21509,1.86534
78.068,4.51108,49.22818,1.87045
78.26801,4.516,49.2456,1.87316
78.468,4.52284,49.35713,1.87879
78.66801,4.5278,49.35965,1.88516
78.868,4.53164,49.32668,1.89077
79.068,4.53536,49.30518,1.89566
79.26801,4.53932,49.30634,1.90037
79.468,4.54356,49.32203,1.90503
79.66801,4.54808,49.34959,1.90987
79.868,4.55268,49.37404,1.91481
80.068,4.55736,49.39825,1.91979
80.26801,4.56204,49.42053,1.92492
80.468,4.5668,49.44026,1.93
80.66801,4.57132,49.45267,1.9351
80.868,4.57576,49.46213,1.94009
81.068,4.58024,49.47321,1.94496
81.26801,4.58496,49.49325,1.94984
81.468,4.58968,49.5112,1.95484
81.66801,4.59452,49.53137,1.95978
81.868,4.59936,49.55358,1.96491
82.068,4.60408,49.56498,1.96989
82.26801,4.60876,49.58172,1.97488
82.468,4.61348,49.5952,1.97978
82.66801,4.61816,49.60921,1.98477
82.868,4.623,49.62891,1.98965
83.068,4.628,49.65267,1.99472
83.26801,4.63288,49.66804,1.99972
83.468,4.6378,49.6835,2.00477
83.66801,4.64272,49.69945,2.00969
83.868,4.64772,49.71974,2.01479
84.068,4.65256,49.7325,2.0198
84.26801,4.65748,49.7478,2.02477
84.468,4.6624,49.76399,2.0297
84.66801,4.66748,49.78452,2.03477
84.868,4.67248,49.8014,2.03967
85.068,4.67752,49.81841,2.04475
85.26801,4.68256,49.83383,2.04978
85.468,4.68764,49.85238,2.05469
85.66801,4.6928,49.87139,2.05976
85.868,4.69792,49.8897,2.06481
86.068,4.70296,49.90327,2.0697
86.26801,4.708,49.91819,2.07469
86.468,4.71304,49.93196,2.07954
86.66801,4.71924,49.97789,2.0826
86.868,4.72588,50.04298,2.08878
87.068,4.73128,50.04178,2.09454
87.26801,4.736,50.02286,2.09988
87.468,4.7406,50.01302,2.10476
87.66801,4.74536,50.0196,2.10957
87.868,4.7504,50.03664,2.11436
88.068,4.75572,50.06675,2.11935
88.26801,4.7612,50.09605,2.12445
88.468,4.76648,50.11154,2.12964
88.66801,4.77168,50.12659,2.13466
88.868,4.77676,50.13805,2.13974
89.068,4.7818,50.14646,2.14461
89.26801,4.787,50.16487,2.1496
89.468,4.79232,50.18872,2.15457
89.66801,4.79764,50.2094,2.15973
89.868,4.8028,50.22178,2.16471
90.068,4.80792,50.23319,2.16969
90.26801,4.813,50.24304,2.17464
90.468,4.81828,50.2648,2.17958
90.66801,4.82368,50.28809,2.18459
90.868,4.82912,50.30865,2.1897
91.068,4.83432,50.32076,2.19475
91.26801,4.83944,50.33088,2.19973
91.468,4.84456,50.34291,2.20461
91.66801,4.84972,50.35787,2.20958
91.868,4.85504,50.37851,2.21445
92.068,4.86044,50.40103,2.21952
92.26801,4.86572,50.41627,2.22455
92.468,4.87096,50.43062,2.22953
92.66801,4.8762,50.44329,2.23453
92.868,4.88148,50.46115,2.23945
93.068,4.88696,50.48379,2.24445
93.26801,4.89252,50.50865,2.24956
93.468,4.89792,50.52222,2.25466
93.66801,4.90324,50.53524,2.25972
93.868,4.90848,50.54685,2.26467
94.068,4.91364,50.55776,2.2696
94.26801,4.91976,50.59019,2.27271
94.468,4.92692,50.66848,2.27868
94.66801,4.93256,50.6677,2.28463
94.868,4.93736,50.64277,2.28992
95.068,4.94208,50.63147,2.29481
95.26801,4.94712,50.64064,2.29958
95.468,4.95248,50.66584,2.30443
95.66801,4.958,50.69202,2.3095
95.868,4.9634,50.7093,2.31464
96.068,4.9686,50.71783,2.31955
96.26801,4.97384,50.732,2.32451
96.468,4.97912,50.74687,2.32946
96.66801,4.98444,50.76521,2.33446
96.868,4.98984,50.78422,2.33944
97.06801,4.99524,50.80039,2.34448
97.26801,5.00048,50.81323,2.3495
97.468,5.00576,50.82739,2.3544
97.66801,5.01112,50.84312,2.35937
97.868,5.01656,50.86364,2.36441
98.06801,5.02216,50.88596,2.36949
98.26801,5.02764,50.90392,2.37462
98.468,5.03296,50.91475,2.37971
98.66801,5.0382,50.92351,2.38471
98.868,5.04344,50.9359,2.38966
99.06801,5.04868,50.95114,2.39466
99.26801,5.05404,50.96746,2.39956
99.468,5.05952,50.98989,2.40458
99.66801,5.06476,51.00098,2.40967
99.868,5.06988,51.00949,2.41454
100.06801,5.075,51.02138,2.41936
100.26801,5.08028,51.03887,2.42428
100.468,5.08572,51.0604,2.42917
100.66801,5.0912,51.08107,2.43416
100.868,5.09656,51.09605,2.43916
101.06801,5.1018,51.104,2.44405
101.26801,5.10712,51.12024,2.44898
101.468,5.11252,51.13436,2.45384
101.66801,5.11796,51.15517,2.45886
101.868,5.12352,51.17638,2.46379
102.06801,5.12912,51.19196,2.46859
102.26801,5.13632,51.26335,2.47259
102.468,5.14256,51.28124,2.47851
102.66801,5.14812,51.27319,2.48411
102.868,5.15324,51.26242,2.48945
103.06801,5.15832,51.26125,2.49431
103.26801,5.16348,51.26839,2.49922
103.468,5.16868,51.28161,2.50413
103.66801,5.17396,51.29594,2.509
103.868,5.17936,51.3164,2.5139
104.06801,5.1848,51.33494,2.51895
104.26801,5.19028,51.35223,2.5239
104.468,5.1956,51.36444,2.52903
104.66801,5.2008,51.37466,2.53398
104.868,5.20604,51.38891,2.53888
105.06801,5.2114,51.40528,2.54381
105.26801,5.21696,51.4274,2.54884
105.468,5.2224,51.44361,2.55394
105.66801,5.22768,51.45385,2.55897
105.868,5.23292,51.46384,2.56389
106.06801,5.23816,51.47704,2.56888
106.26801,5.24344,51.49159,2.57371
106.468,5.24884,51.51218,2.57871
106.66801,5.2542,51.52828,2.58378
106.868,5.25944,51.53909,2.58878
107.06801,5.26472,51.55109,2.59372
107.26801,5.27,51.56556,2.59872
107.468,5.27548,51.58334,2.60356
107.66801,5.28116,51.61013,2.60874
107.868,5.2868,51.6291,2.61393
108.06801,5.2922,51.63794,2.61905
108.26801,5.29748,51.64664,2.62407
108.468,5.30268,51.65415,2.62908
108.66801,5.30804,51.66739,2.63396
108.868,5.31356,51.6881,2.63892
109.06801,5.31928,51.71096,2.64398
109.26801,5.32484,51.72738,2.64916
109.468,5.3302,51.73549,2.65417
109.66801,5.3356,51.7477,2.65913
109.868,5.34132,51.76664,2.66323
110.06801,5.34872,51.84616,2.66819
110.26801,5.35476,51.85503,2.67416
110.468,5.3598,51.83049,2.6797
110.66801,5.36456,51.81173,2.68457
110.868,5.36956,51.81407,2.68941
111.06801,5.37468,51.82684,2.69429
111.26801,5.38008,51.84879,2.69904
111.468,5.38544,51.86884,2.7041
111.66801,5.39064,51.87986,2.70908
111.868,5.3958,51.8888,2.7139
112.06801,5.40104,51.90377,2.71874
112.26801,5.40648,51.92436,2.72379
112.468,5.41212,51.9477,2.72879
112.66801,5.41764,51.96665,2.73404
112.868,5.42308,51.97932,2.73909
113.06801,5.42832,51.98697,2.74424
113.26801,5.43344,51.99299,2.7491
113.468,5.43868,52.00241,2.75402
113.66801,5.444,52.0199,2.75899
113.868,5.44948,52.04006,2.764
114.06801,5.45492,52.05518,2.76899
114.26801,5.46016,52.06581,2.77413
114.468,5.4654,52.07421,2.77898
114.66801,5.4708,52.0933,2.784
114.868,5.47624,52.11041,2.78906
115.06801,5.48168,52.12635,2.79409
115.26801,5.48704,52.13742,2.79919
115.468,5.49224,52.14584,2.80421
115.66801,5.49748,52.15498,2.80908
115.868,5.5028,52.17134,2.81401
116.06801,5.50812,52.18462,2.81896
116.26801,5.51356,52.20447,2.82392
116.468,5.51892,52.21846,2.829
116.66801,5.5242,52.23005,2.834
116.868,5.52956,52.24501,2.83897
117.06801,5.53496,52.26054,2.844
117.26801,5.54056,52.27855,2.849
117.468,5.5462,52.29849,2.85413
117.66801,5.55316,52.35844,2.85796
117.868,5.55952,52.38565,2.86394
118.06801,5.56456,52.36176,2.86961
118.26801,5.56932,52.3421,2.87462
118.468,5.5742,52.33999,2.87956
118.66801,5.57936,52.35378,2.88439
118.868,5.58464,52.37209,2.8894
119.06801,5.59,52.38945,2.89436
119.26801,5.59536,52.40519,2.89949
119.468,5.6008,52.42397,2.90446
119.66801,5.60624,52.43786,2.9097
119.868,5.6116,52.45333,2.91474
120.06801,5.6168,52.46002,2.91987
120.26801,5.62188,52.46503,2.9248
120.468,5.62696,52.47537,2.92974
120.66801,5.63196,52.48209,2.93456
120.868,5.63688,52.48868,2.9394
121.06801,5.642,52.50341,2.94411
121.26801,5.64728,52.52471,2.94909
121.468,5.65248,52.54015,2.95396
121.66801,5.6578,52.55709,2.95894
121.868,5.66304,52.57142,2.96394
122.06801,5.66844,52.59005,2.96895
122.26801,5.674,52.61146,2.97409
122.468,5.67944,52.62478,2.97937
122.66801,5.68472,52.63319,2.98442
122.868,5.69,52.64323,2.98952
123.06801,5.69504,52.64638,2.99448
123.26801,5.70024,52.65791,2.99938
123.468,5.70548,52.67243,3.00438
123.66801,5.71088,52.69134,3.00938
123.868,5.71616,52.70461,3.01438
124.06801,5.7214,52.71397,3.01934
124.26801,5.7266,52.72272,3.02424
124.468,5.73204,52.7427,3.02917
124.66801,5.73756,52.76176,3.0343
124.868,5.74312,52.7808,3.03931
125.06801,5.74868,52.79087,3.04347
125.26801,5.75548,52.85162,3.04843
125.468,5.7612,52.85819,3.05419
125.66801,5.7662,52.8388,3.05958
125.868,5.77104,52.8265,3.06453
126.06801,5.77612,52.83287,3.06938
126.26801,5.78116,52.84202,3.07431
126.468,5.7864,52.85473,3.0791
126.66801,5.79164,52.87154,3.08412
126.868,5.79696,52.88462,3.08908
127.06801,5.8024,52.90554,3.0941
127.26801,5.80792,52.92533,3.09922
127.468,5.81328,52.93675,3.10439
127.66801,5.8186,52.94491,3.10939
127.868,5.82372,52.95055,3.11447
128.06801,5.82888,52.95697,3.1193
128.26801,5.83416,52.97239,3.12431
128.468,5.83952,52.98916,3.12923
128.668,5.84484,53.00383,3.13433
128.86801,5.84996,53.01018,3.13929
129.06801,5.85508,53.01875,3.14423
129.26801,5.86036,53.03238,3.14918
129.468,5.86576,53.05088,3.15418
129.668,5.87112,53.06706,3.1592
129.86801,5.87648,53.08082,3.1643
130.06801,5.8816,53.08564,3.16932
130.26801,5.88672,53.09396,3.17419
130.468,5.8918,53.10307,3.17917
130.668,5.89704,53.11506,3.18407
130.86801,5.9024,53.13486,3.18903
131.06801,5.9078,53.15089,3.19409
131.268,5.91292,53.15679,3.19912
131.468,5.91812,53.168,3.204
131.668,5.92336,53.17956,3.20899
131.86802,5.92872,53.19668,3.21393
132.06802,5.9342,53.21516,3.21906
132.268,5.93956,53.22665,3.22406
132.468,5.94472,53.23375,3.22906
132.668,5.95,53.24273,3.23366
132.86802,5.957,53.3112,3.23782
133.06802,5.96304,53.32874,3.24367
133.268,5.96828,53.3156,3.24924
133.468,5.97316,53.30027,3.2543
133.668,5.97796,53.29258,3.25929
133.86802,5.9828,53.29491,3.26406
134.06802,5.98796,53.3106,3.26891
134.268,5.99332,53.3326,3.27386
134.468,5.9988,53.35371,3.27895
134.668,6.0042,53.36794,3.284
134.86802,6.00936,53.37591,3.28914
135.06802,6.0144,53.37808,3.29402
135.268,6.01952,53.38616,3.29892
135.468,6.0246,53.39608,3.30382
135.668,6.02984,53.41313,3.30873
135.86802,6.03512,53.43009,3.31373
136.06802,6.04036,53.44263,3.31877
136.268,6.04548,53.44977,3.32375
136.468,6.05064,53.4624,3.32873
136.668,6.0558,53.47122,3.33366
136.86802,6.06116,53.49061,3.33867
137.06802,6.06652,53.50655,3.34381
137.268,6.07176,53.5173,3.34886
137.468,6.07692,53.52406,3.35396
137.668,6.08204,53.53082,3.35892
137.86802,6.08712,53.54036,3.3639
138.06802,6.09236,53.55171,3.36883
138.268,6.09764,53.56708,3.37392
138.468,6.10304,53.58277,3.37889
138.668,6.1082,53.59422,3.38402
138.86802,6.11328,53.59907,3.3889
139.06802,6.11844,53.60764,3.39388
139.268,6.12368,53.62226,3.39876
139.468,6.12912,53.64149,3.40379
139.668,6.13456,53.6567,3.40887
139.86802,6.13976,53.66415,3.41399
140.06802,6.1454,53.67563,3.41748
140.268,6.1522,53.74157,3.42296
140.468,6.15788,53.74526,3.42868
140.668,6.16292,53.72891,3.43411
140.86802,6.16776,53.71746,3.43917
141.06802,6.17264,53.71549,3.44404
141.268,6.1776,53.72284,3.44892
141.468,6.18272,53.73609,3.45379
141.668,6.18804,53.75329,3.45874
141.86802,6.19352,53.77597,3.46382
142.06802,6.19884,53.79039,3.46902
142.268,6.204,53.79825,3.4741
142.468,6.20904,53.80171,3.47913
142.668,6.21404,53.80793,3.4841
142.86802,6.21904,53.81506,3.489
143.06802,6.22416,53.82931,3.494
143.268,6.2294,53.8455,3.49898
143.468,6.23464,53.8591,3.50404
143.668,6.2396,53.86497,3.50907
143.86802,6.24456,53.86956,3.51389
144.06802,6.24948,53.87849,3.51888
144.268,6.25464,53.89335,3.52378
144.468,6.25988,53.91143,3.5288
144.668,6.26512,53.9274,3.53388
144.86802,6.2702,53.93389,3.53898
145.06802,6.2752,53.93992,3.54391
145.268,6.28032,53.94804,3.54887
145.468,6.28544,53.95772,3.55378
145.66802,6.29064,53.97394,3.55882
145.86802,6.29588,53.98734,3.56375
146.06802,6.301,53.99719,3.56882
146.268,6.30608,54.00393,3.57373
146.468,6.31124,54.01536,3.57869
146.66802,6.31656,54.02951,3.58364
146.86802,6.322,54.04873,3.58872
147.06802,6.32752,54.06465,3.59384
147.268,6.33296,54.07723,3.59891
147.468,6.3396,54.12823,3.60298
147.66802,6.34544,54.14094,3.60879
147.86802,6.35048,54.12221,3.61427
148.06802,6.35524,54.10888,3.61945
148.268,6.3602,54.10835,3.62428
148.468,6.36528,54.11824,3.62924
148.66802,6.37024,54.12315,3.63421
148.86802,6.37524,54.13033,3.63911
149.06802,6.38028,54.14379,3.64401
149.268,6.3854,54.15808,3.64895
149.468,6.3906,54.17271,3.65401
149.66802,6.3958,54.18641,3.65907
149.86802,6.40084,54.19281,3.66401
150.06802,6.40576,54.19582,3.66893
150.268,6.4108,54.20519,3.67383
150.468,6.41592,54.2188,3.67868
150.66802,6.42112,54.23276,3.68368
150.86802,6.42636,54.24861,3.68865
151.06802,6.43144,54.25721,3.69374
151.268,6.43644,54.26217,3.69868
151.468,6.44148,54.26894,3.7036
151.66802,6.44668,54.28334,3.70851
151.86802,6.45204,54.30057,3.7136
152.06802,6.45752,54.31727,3.71869
152.268,6.46284,54.32814,3.72384
152.468,6.46804,54.33522,3.72894
152.66802,6.47308,54.34017,3.73399
152.86802,6.47812,54.34198,3.73891
153.06802,6.48316,54.35029,3.74381
153.268,6.48828,54.36189,3.74876
153.468,6.49368,54.37953,3.75374
153.66802,6.49892,54.39001,3.75874
153.86802,6.50404,54.39831,3.76367
154.06802,6.5092,54.40657,3.7686
154.268,6.51444,54.41844,3.77358
154.468,6.51988,54.43481,3.77848
154.66802,6.52668,54.4955,3.78254
154.86802,6.53264,54.5118,3.7884
155.06802,6.53768,54.49184,3.79393
155.268,6.5424,54.47416,3.79898
155.31402,6.54348,54.47035,3.80009
155.514,6.54108,54.31271,3.80349
155.714,6.5432,54.18834,3.80565
155.914,6.5466,54.19104,3.80805
156.11402,6.55048,54.24973,3.81092
156.31402,6.55452,54.2978,3.81416
156.514,6.55848,54.33236,3.81749
156.714,6.56248,54.36092,3.82101
156.914,6.56644,54.38318,3.82455
157.11402,6.57044,54.40235,3.82825
157.31402,6.57444,54.41773,3.83188
157.514,6.57848,54.43266,3.83567
157.714,6.58252,54.44677,3.83949
157.914,6.58656,54.45889,3.84334
158.11402,6.59064,54.46918,3.84709
158.31402,6.59464,54.47785,3.85098
158.514,6.5986,54.48427,3.85485
158.714,6.60256,54.49137,3.85868
158.914,6.60656,54.49938,3.86243
159.11402,6.61052,54.5086,3.86625
159.31402,6.61456,54.51755,3.87013
159.514,6.6186,54.52638,3.87393
159.714,6.62264,54.53507,3.87781
159.914,6.62664,54.54067,3.88163
160.11402,6.6306,54.5468,3.88545
160.31402,6.6346,54.55183,3.88924
160.514,6.6386,54.55756,3.89296
160.714,6.6426,54.5665,3.89681
160.914,6.64668,54.57507,3.90059
161.11402,6.65076,54.58468,3.90445
161.25802,6.65364,54.59096,3.90719
161.28202,6.65412,54.59138,3.90765