File: Coupon(GU)/C-2DPS-2.csv
Time*,C-2DPS-2 Instron Force (kN),C-2DPS-2 Extensometer (mm/mm)
0,0.015064735,-2.91E-07
5,0.01507904,-1.45E-06
10,0.015036125,-4.00E-06
15,0.015036125,-5.70E-06
20,0.014696378,-8.52E-06
25,0.032173653,-0.000246876
30,0.088110232,-0.000307449
35,0.949213818,-0.000186526
40,1.022298653,-0.000154921
45,1.020757277,-0.000155234
50,1.019391139,-0.000154518
55,1.020932515,-0.000154608
60,1.020771582,-0.00015434
65,1.022159178,-0.000154563
70,1.503798115,-7.70E-05
75,1.954387799,1.34E-05
80,2.388301294,8.24E-05
85,2.813989348,0.000151119
90,3.230708094,0.000226579
95,3.637491938,0.000305078
100,4.034719964,0.00038541
105,4.416991992,0.000457785
110,4.783946817,0.000526182
115,5.130348768,0.000595159
120,5.449034557,0.000664718
125,5.733820798,0.000731862
130,5.977236645,0.000822655
135,6.170144705,0.000919215
140,6.313124336,0.001039825
145,6.412344617,0.001206971
150,6.473473953,0.001386321
155,6.345067659,0.001422799
160,6.305850184,0.001444838
165,6.281899845,0.001447967
170,6.264955435,0.001449353
175,6.251154575,0.001448414
180,6.240279111,0.001448012
185,6.229789885,0.001448906
190,6.221435697,0.001448549
195,6.214490564,0.001448146
200,6.207695634,0.001449219
205,6.202127367,0.001447923
210,6.196673542,0.001448504
215,6.191191107,0.001448146
220,6.185794502,0.001449085
225,6.181921392,0.001448012
230,6.177544026,0.001448549
235,6.174450545,0.001448638
240,6.169808535,0.001448593
245,6.166729359,0.001448549
250,6.163782505,0.001448549
255,6.160470871,0.001447967
260,6.157191423,0.001448951
265,6.154026416,0.001448861
270,6.150968698,0.001447073
275,6.14830437,0.00144761
280,6.145640042,0.001448325
285,6.143179562,0.00144913
290,6.141069558,0.001448727
295,6.138959553,0.00144828
300,6.136538412,0.001448727
305,6.133870508,0.00144837
310,6.131259825,0.001448057
315,6.129253532,0.001448191
320,6.127941038,0.001448414
325,6.12558427,0.001448146
330,6.123088027,0.001447789
335,6.121632482,0.001447297
340,6.428033753,0.001536346
345,6.534989526,0.001740775
350,6.5874893,0.001980699
355,6.629578527,0.002226032
360,6.66616386,0.002470917
365,6.69825381,0.002713255
370,6.724843444,0.002955458
375,6.748815241,0.003191627
380,6.770569746,0.0034286
385,6.790553992,0.003661729
390,6.809540457,0.003884129
395,6.827707954,0.004109613
400,6.844977805,0.004318646
405,6.862244079,0.004524774
410,6.878770064,0.004727236
415,6.894384098,0.004923172
420,6.910359336,0.005102388
425,6.925669386,0.005275301
430,6.939788535,0.005448438
435,6.954533533,0.005615986
440,6.969564633,0.005785949
445,6.983980613,0.005956225
450,7.000131089,0.006126455
455,7.016009767,0.006294675
460,7.030497273,0.006463877
465,7.046683511,0.006633527
470,7.062787495,0.006804741
475,7.077332221,0.006976403
480,7.093175137,0.007148645
485,7.108764136,0.007320664
490,7.123662914,0.007491566
495,7.139251914,0.007662959
500,7.15401837,0.007839538
505,7.169550149,0.008017905
510,7.184577673,0.008195601
515,7.199733943,0.008374013
520,7.215176315,0.008548267
525,7.229999991,0.008721493
530,7.245631906,0.008893467
535,7.260555718,0.009064905
540,7.275905107,0.009240769
545,7.290503477,0.009422354
550,7.306246257,0.00960005
555,7.322461106,0.009777613
560,7.336583831,0.009951554
565,7.352083424,0.010121383
570,7.366821269,0.010296575
575,7.381598454,0.010470338
580,7.396486503,0.010650761
585,7.412003977,0.010830961
590,7.425987227,0.011006824
595,7.440499767,0.011180006
600,7.455348477,0.011350684
605,7.469621406,0.011521585
610,7.48357247,0.011696376
615,7.497580755,0.011873804
620,7.51145314,0.012053154
625,7.524724711,0.012231968
630,7.538547029,0.012406669
635,7.552483788,0.012579895
640,7.565952055,0.012752406
645,7.579373829,0.012931399
650,7.592995876,0.013113655
655,7.606732363,0.013295822
660,7.620272155,0.013469674
665,7.634144541,0.013640799
670,7.647763011,0.013816752
675,7.661184785,0.013996683
680,7.674449204,0.014177598
685,7.687352418,0.014355116
690,7.699679852,0.014526643
695,7.713291169,0.014698125
700,7.725743772,0.014872961
705,7.737981799,0.015052535
710,7.751153234,0.015234433
715,7.762643818,0.015413381
720,7.775783066,0.015583254
725,7.787227159,0.015757062
730,7.79957605,0.015929617
735,7.811653144,0.016111024
740,7.82291127,0.0162948
745,7.834873923,0.016472094
750,7.847219238,0.016644113
755,7.858573923,0.016815595
760,7.869113217,0.017003797
765,7.880653869,0.017189451
770,7.892924082,0.017361425
775,7.904550565,0.017542742
780,7.915654911,0.017731615
785,7.926655544,0.01790721
790,7.937516703,0.018079765
795,7.949246898,0.018263541
800,7.960508601,0.018447183
805,7.970518605,0.01862564
810,7.981562154,0.018797972
815,7.992505568,0.018978261
820,8.003137845,0.019165971
825,8.01394536,0.019342415
830,8.024817248,0.0195143
835,8.035377999,0.01969754
840,8.0452378,0.019880332
845,8.055312178,0.020058297
850,8.066001675,0.020231434
855,8.090499186,0.020649813
860,8.100748801,0.020838373
865,8.109778905,0.021015175
870,8.120400454,0.021187373
875,8.130224492,0.021372088
880,8.139562156,0.02155801
885,8.148488548,0.021731414
890,8.158638028,0.021910944
895,8.167789726,0.022100844
900,8.177413492,0.022278987
905,8.186275511,0.022455968
910,8.196110278,0.022642114
915,8.205283434,0.022825577
920,8.214574606,0.022998356
925,8.224434407,0.023184099
930,8.233511003,0.023370781
935,8.242687735,0.023542755
940,8.251660618,0.023727336
945,8.260168586,0.023913213
950,8.269452606,0.024087735
955,8.277996336,0.024270617
960,8.286869084,0.024458461
965,8.295276916,0.024635532
970,8.303423679,0.024813004
975,8.311702765,0.025005989
980,8.320124902,0.025181272
985,8.328196563,0.02536326
990,8.336518564,0.025553652
995,8.344683209,0.025727593
1000,8.35278348,0.025911146
1005,8.360865871,0.026100867
1010,8.369162838,0.026275568
1015,8.377434771,0.026463055
1020,8.385363381,0.026649513
1025,8.393803399,0.026823812
1030,8.401785654,0.027014383
1035,8.409574789,0.027195834
1040,8.416895432,0.027370446
1045,8.424226804,0.027564102
1050,8.432362839,0.02774296
1055,8.44046311,0.027921864
1060,8.447619244,0.028115251
1065,8.455290363,0.028289952
1070,8.462349937,0.028474265
1075,8.470267819,0.028662243
1080,8.477094935,0.028837212
1085,8.484204577,0.029029303
1090,8.491972255,0.029210352
1095,8.498763609,0.029392608
1100,8.505472708,0.029584923
1105,8.511931468,0.029759356
1110,8.519470264,0.029949524
1115,8.525775243,0.03013263
1120,8.533306887,0.030315467
1125,8.540777733,0.030506664
1130,8.547089866,0.030682975
1135,8.554768136,0.030876809
1140,8.561162523,0.031055086
1145,8.56881576,0.031245568
1150,8.574577145,0.031431132
1155,8.582083755,0.031611332
1160,8.588288599,0.031804272
1165,8.595523411,0.031980314
1170,8.601506525,0.032176563
1175,8.607525403,0.032353633
1180,8.614080722,0.032544025
1185,8.620539482,0.032728338
1190,8.62633663,0.032912069
1195,8.632373389,0.033102595
1200,8.638778504,0.033278548
1205,8.645265874,0.033473724
1210,8.650734004,0.033650928
1215,8.656448898,0.033842528
1220,8.662832556,0.034025678
1225,8.669137536,0.034208515
1230,8.675438939,0.034401321
1235,8.681486427,0.03457781
1240,8.688660442,0.034773254
1245,8.694443285,0.034949654
1250,8.699943602,0.035147914
1255,8.705644191,0.035326549
1260,8.711552203,0.035519087
1265,8.716748537,0.035701969
1270,8.723969044,0.035887176
1275,8.728997292,0.036076674
1280,8.734315219,0.036256829
1285,8.740366282,0.036451065
1290,8.745544734,0.036627644
1295,8.750923458,0.036823937
1300,8.755658451,0.036999532
1305,8.761806074,0.03719596
1310,8.767406527,0.03737455
1315,8.772188012,0.03756901
1320,8.77816755,0.037749702
1325,8.784157818,0.03794291
1330,8.789754694,0.038125256
1335,8.794807976,0.038314128
1340,8.800311869,0.038500586
1345,8.80547244,0.038688028
1350,8.809974975,0.038875917
1355,8.815983124,0.039064565
1360,8.820696659,0.039250442
1365,8.825875111,0.039436945
1370,8.831175156,0.039628366
1375,8.836228438,0.039811784
1380,8.841267415,0.040004143
1385,8.845820018,0.040182644
1390,8.850447723,0.040379652
1395,8.855844328,0.040558198
1400,8.861029933,0.040753597
1405,8.866322825,0.040932769
1410,8.869891952,0.04113
1415,8.874862979,0.04130716
1420,8.879966329,0.041504929
1425,8.884161304,0.041683519
1430,8.889214587,0.041878873
1435,8.894182038,0.042060191
1440,8.89954288,0.042255455
1445,8.904027534,0.04243418
1450,8.908269001,0.042631099
1455,8.91318996,0.042813444
1460,8.918493582,0.043007636
1465,8.922456099,0.04319025
1470,8.926915719,0.043384084
1475,8.932154967,0.043567235
1480,8.93588145,0.04375946
1485,8.940455511,0.043946007
1490,8.945784166,0.044135371
1495,8.948756054,0.044323662
1500,8.953405217,0.04451164
1505,8.957800463,0.044704983
1510,8.961948947,0.044888267
1515,8.965539531,0.045086795
1520,8.970388965,0.045264045
1525,8.974426584,0.045462528
1530,8.978757458,0.045641208
1535,8.98396452,0.045841837
1540,8.98832758,0.046021992
1545,8.992429572,0.046216989
1550,8.997035819,0.046402419
1555,9.000511962,0.046593839
1560,9.005543787,0.046779716
1565,9.008837539,0.046968768
1570,9.013679821,0.047161842
1575,9.017095167,0.0473445
1580,9.02085026,0.04754048
1585,9.025170405,0.047721082
1590,9.028725226,0.047920192
1595,9.033184846,0.048099721
1600,9.03649648,0.048300306
1605,9.041306576,0.048482204
1610,9.044432243,0.04867586
1615,9.048784575,0.048862407
1620,9.052453837,0.049053559
1625,9.055744014,0.049245874
1630,9.059674344,0.049429471
1635,9.063483081,0.04962554
1640,9.068243108,0.049805964
1645,9.071676336,0.050003106
1650,9.075989328,0.050184021
1655,9.079812371,0.050382415
1660,9.082794987,0.050562973
1665,9.08734759,0.050758595
1670,9.090798699,0.050946305
1675,9.094339215,0.051135222
1680,9.098373258,0.051327581
1685,9.101788604,0.051512206
1690,9.105668867,0.051709349
1695,9.109638537,0.051890532
1700,9.112885798,0.052088971
1705,9.116941298,0.052274848
1710,9.119587744,0.052467475
1715,9.123357142,0.052660997
1720,9.126439895,0.052844102
1725,9.129626359,0.05304111
1730,9.133056011,0.05322283
1735,9.137243833,0.053421895
1740,9.140344467,0.053601156
1745,9.143184033,0.053799371
1750,9.148255196,0.053980599
1755,9.151191321,0.054176266
1760,9.15522894,0.05436411
1765,9.158887473,0.05455182
1770,9.161948768,0.054747353
1775,9.165081588,0.054927374
1780,9.168479053,0.055127511
1785,9.172237722,0.055310215
1790,9.175563662,0.055506597
1795,9.178188651,0.055691178
1800,9.181042521,0.055881391
1805,9.184164613,0.056074689
1810,9.187390416,0.056259359
1815,9.190866559,0.056457351
1820,9.19415316,0.056637148
1825,9.19710359,0.056838001
1830,9.20013985,0.057019899
1835,9.20303306,0.057214002
1840,9.20700273,0.0574035
1845,9.210410923,0.057592104
1850,9.213829846,0.057787905
1855,9.216637225,0.057969625
1860,9.219648452,0.058170791
1865,9.223614545,0.058355327
1870,9.227269502,0.058545942
1875,9.229930254,0.058739687
1880,9.232755514,0.058924089
1885,9.235637995,0.059124539
1890,9.238452526,0.059306572
1895,9.241152617,0.059502642
1900,9.243938538,0.059693615
1905,9.246770951,0.059876765
1910,9.249388787,0.060078288
1915,9.25231776,0.060259427
1920,9.255085799,0.060456793
1925,9.257796619,0.060647677
1930,9.260793541,0.060834135
1935,9.263246868,0.061032618
1940,9.267234419,0.061212908
1945,9.2703279,0.061414476
1950,9.273632382,0.061603616
1955,9.276657914,0.061791818
1960,9.279418801,0.061991911
1965,9.282165383,0.062174256
1970,9.284861898,0.062371398
1975,9.287565564,0.062561299
1980,9.29043374,0.062747399
1985,9.293166017,0.062946777
1990,9.296134329,0.063129704
1995,9.298816538,0.063326578
2000,9.301455832,0.063520233
2005,9.30408082,0.063703652
2010,9.306881047,0.063904549
2015,9.309656239,0.064088415
2020,9.312227584,0.064282204
2025,9.314827538,0.064480285
2030,9.317534782,0.064661469
2035,9.320206262,0.064863037
2040,9.322917081,0.065050389
2045,9.325613596,0.065238501
2050,9.328553297,0.06544074
2055,9.331332066,0.06562313
2060,9.333992817,0.065820317
2065,9.336771586,0.06601518
2070,9.339471676,0.066200297
2075,9.342193225,0.066399853
2080,9.344861129,0.066587071
2085,9.347654202,0.06677791
2090,9.350175479,0.066975366
2095,9.352925638,0.067158427
2100,9.355343202,0.067357044
2105,9.357592682,0.0675469
2110,9.359463075,0.067733313
2115,9.361759046,0.067933764
2120,9.36427317,0.06811745
2125,9.366819481,0.068311464
2130,9.369541029,0.068507175
2135,9.372040848,0.068690951
2140,9.374533515,0.068892385
2145,9.377405267,0.069082822
2150,9.380223374,0.06926928
2155,9.383102279,0.069469507
2160,9.385512691,0.069653283
2165,9.388130527,0.069849666
2170,9.390369278,0.070043008
2175,9.393030029,0.07022741
2180,9.394907576,0.070428665
2185,9.397589785,0.070616107
2190,9.39957462,0.070805248
2195,9.402314049,0.07100543
2200,9.404999835,0.071192648
2205,9.406541211,0.071384292
2210,9.408400876,0.071582328
2215,9.411183221,0.07176606
2220,9.41325031,0.071965348
2225,9.415939672,0.072159406
2230,9.418271406,0.072345283
2235,9.420034511,0.072543677
2240,9.421647413,0.072733667
2245,9.42425452,0.072922271
2250,9.426983221,0.073124688
2255,9.429583176,0.073308643
2260,9.432261809,0.07349984
2265,9.434790238,0.073699128
2270,9.436664208,0.073882591
2275,9.438198432,0.07408094
2280,9.440955743,0.074272092
2285,9.443323239,0.074460383
2290,9.446026906,0.074661147
2295,9.448555335,0.074849661
2300,9.450096712,0.07503983
2305,9.451534376,0.07523952
2310,9.454241619,0.075423252
2315,9.456745014,0.075620394
2320,9.458171949,0.075815927
2325,9.459935055,0.075999748
2330,9.462431297,0.076199975
2335,9.464770184,0.076388534
2340,9.46585022,0.076576244
2345,9.46806036,0.076778259
2350,9.470731841,0.076966103
2355,9.472934829,0.077156585
2360,9.475645648,0.077355739
2365,9.478435146,0.077541929
2370,9.479186164,0.077734735
2375,9.481639491,0.07793523
2380,9.484375345,0.078120526
2385,9.485923874,0.078316238
2390,9.487286436,0.078515839
2395,9.489875662,0.078702968
2400,9.492293226,0.078897383
2405,9.492883312,0.079097655
2410,9.495340216,0.079281788
2415,9.497925866,0.079478394
2420,9.49862324,0.079676699
2425,9.500872719,0.079862129
2430,9.503515589,0.080059003
2435,9.505103457,0.08025695
2440,9.50634085,0.080442559
2445,9.50895511,0.080638897
2450,9.511229623,0.080837962
2455,9.512263168,0.081022498
2460,9.514623512,0.081219193
2465,9.517062534,0.081420314
2470,9.519741167,0.081605163
2475,9.521647323,0.081798684
2480,9.522698749,0.08200137
2485,9.525402416,0.082190242
2490,9.527659048,0.082382109
2495,9.528724779,0.082584348
2500,9.530877699,0.082776618
2505,9.532901873,0.082963478
2510,9.533795943,0.08316603
2515,9.536349406,0.083359238
2520,9.53806602,0.083546278
2525,9.539553752,0.083747577
2530,9.541627994,0.083942663
2535,9.543462625,0.084129256
2540,9.544531932,0.084327963
2545,9.547206989,0.084526491
2550,9.549023738,0.084715318
2555,9.550164571,0.084907722
2560,9.552735916,0.085112241
2565,9.554892412,0.085302543
2570,9.556043974,0.085491192
2575,9.558246962,0.085691598
2580,9.560875527,0.085891467
2585,9.56253492,0.086079579
2590,9.563758008,0.086273324
2595,9.566264979,0.086476368
2600,9.567026726,0.086667341
2605,9.569100968,0.086856437
2610,9.571579329,0.087057602
2615,9.572151534,0.087254387
2620,9.574157827,0.087445405
2625,9.575359456,0.087639955
2630,9.577337138,0.087841836
2635,9.578696124,0.088029501
2640,9.580030077,0.088221279
2645,9.581868284,0.088425305
2650,9.583030575,0.088616323
2655,9.585387342,0.088803542
2660,9.587207668,0.089006048
2665,9.588902824,0.089206901
2670,9.590919846,0.089394388
2675,9.592725867,0.089587417
2680,9.594099158,0.08978979
2685,9.596373671,0.089979512
2690,9.59782564,0.090168697
2695,9.599216813,0.090371963
2700,9.601319665,0.090570179
2705,9.602839583,0.09075771
2710,9.604581231,0.090952125
2715,9.606047506,0.091154677
2720,9.607406491,0.091348869
2725,9.609266157,0.091536221
2730,9.610106582,0.09173618
2735,9.611858959,0.091939089
2740,9.613064165,0.092129794
2745,9.615463848,0.092322153
2750,9.616053934,0.09252314
2755,9.618196125,0.092722249
2760,9.620041485,0.09291367
2765,9.621328945,0.093106744
2770,9.623664255,0.093308357
2775,9.625144835,0.093507421
2780,9.626528855,0.093694192
2785,9.627658959,0.093889278
2790,9.62943637,0.094093931
2795,9.631743069,0.094288659
2800,9.632150765,0.094476191
2805,9.634757873,0.09467454
2810,9.635516044,0.094875571
2815,9.637397166,0.095068691
2820,9.639117356,0.095260468
2825,9.640100833,0.095459041
2830,9.642207261,0.095661056
2835,9.642854568,0.095853371
2840,9.644932386,0.096043092
2845,9.645719167,0.09624551
2850,9.647500154,0.096447525
2855,9.64834058,0.096640063
2860,9.649552938,0.096829829
2865,9.651058552,0.097030592
2870,9.653429625,0.097231222
2875,9.654563305,0.097422329
2880,9.656512377,0.097615314
2885,9.657538769,0.097816927
2890,9.659280417,0.098018495
2895,9.661855338,0.098209736
2900,9.662159321,0.098399324
2905,9.664584039,0.09860192
2910,9.665617583,0.098801968
2915,9.667230485,0.098995668
2920,9.667999385,0.099186105
2925,9.670084355,0.099386645
2930,9.67047417,0.099590091
2935,9.672140716,0.099784864
2940,9.673016904,0.099978519
2945,9.674830078,0.100172756
2950,9.675559638,0.100375978
2955,9.677015184,0.100576786
2960,9.678359865,0.100767312
2965,9.679157375,0.100960431
2970,9.681224464,0.101163832
2975,9.68335235,0.101364551
2980,9.684375166,0.101558921
2985,9.686517357,0.101749716
2990,9.687082409,0.101948959
2995,9.689271092,0.102153567
3000,9.689768195,0.10235071
3005,9.692003369,0.102543471
3010,9.692350268,0.102739362
3015,9.694081187,0.102938829
3020,9.6948179,0.103141917
3025,9.695626139,0.103338523
3030,9.697385669,0.103529496
3035,9.698186755,0.103724135
3040,9.699906945,0.10392834
3045,9.701087117,0.104128701
3050,9.702331662,0.104323698
3055,9.703057647,0.104516102
3060,9.705074668,0.104714406
3065,9.705589652,0.104921652
3070,9.707924963,0.105122192
3075,9.708793998,0.105319111
3080,9.710728765,0.10551071
3085,9.711190105,0.105709506
3090,9.71381867,0.105911923
3095,9.714090467,0.106115682
3100,9.715803505,0.106315059
3105,9.716658236,0.106508894
3110,9.718371273,0.106704293
3115,9.719276072,0.10690139
3120,9.72073877,0.107088922
3125,9.722061993,0.107284008
3130,9.722326638,0.107482983
3135,9.724365117,0.107686473
3140,9.724876525,0.10788889
3145,9.726310612,0.108087195
3150,9.727598073,0.108282415
3155,9.728438498,0.108478976
3160,9.729969146,0.108678488
3165,9.730369689,0.108880905
3170,9.732025506,0.109084128
3175,9.733177068,0.109288378
3180,9.734439494,0.109486906
3185,9.735809209,0.109683467
3190,9.737711789,0.109877614
3195,9.738491418,0.110078646
3200,9.740458372,0.110282673
3205,9.741195085,0.110486744
3210,9.742192867,0.110685764
3215,9.743791464,0.110880716
3220,9.744474533,0.111078216
3225,9.746098163,0.111275627
3230,9.746613148,0.111477105
3235,9.747646692,0.111682115
3240,9.749352577,0.111884667
3245,9.749377611,0.112085564
3250,9.751312378,0.112280203
3255,9.752177838,0.112478106
3260,9.753222111,0.112677304
3265,9.754291418,0.112876414
3270,9.754942301,0.113081334
3275,9.756887797,0.113286076
3280,9.757599476,0.113488851
3285,9.759359006,0.113690464
3290,9.760403279,0.113889126
3295,9.761100653,0.114086269
3300,9.763089065,0.114285959
3305,9.764830712,0.114486723
3310,9.765653257,0.114687754
3315,9.765896443,0.114891915
3320,9.767859821,0.115095629
3325,9.768442754,0.115298806
3330,9.768628721,0.115497513
3335,9.770853166,0.115695728
3340,9.771257286,0.115894838
3345,9.771300201,0.116094618
3350,9.773342256,0.116294219
3355,9.773932342,0.116497262
3360,9.77459753,0.116700573
3365,9.776510839,0.116905852
3370,9.776671772,0.117107152
3375,9.778159504,0.117309703
3380,9.779379015,0.117509259
3385,9.780355339,0.11770524
3390,9.782014732,0.117904885
3395,9.782780056,0.118105649
3400,9.784053211,0.118307932
3405,9.784915095,0.118511601
3410,9.785394316,0.118716522
3415,9.78760088,0.118920191
3420,9.78769744,0.119121044
3425,9.788906222,0.119320779
3430,9.790322428,0.119521587
3435,9.790408259,0.119722484
3440,9.792103415,0.119920878
3445,9.792929536,0.120123206
3450,9.793247825,0.120324551
3455,9.794860726,0.120524688
3460,9.795561677,0.120730503
3465,9.79596222,0.120934083
3470,9.797224647,0.121139898
3475,9.797864801,0.121343388
3480,9.798873311,0.121548041
3485,9.800797349,0.121751799
3490,9.801287299,0.121952697
3495,9.802231437,0.122151895
3500,9.804001695,0.122355922
3505,9.804470188,0.122559189
3510,9.805632478,0.122760042
3515,9.806773311,0.122961923
3520,9.808007128,0.123164027
3525,9.80924452,0.12336631
3530,9.809459097,0.123570292
3535,9.810177929,0.123772397
3540,9.811486847,0.123976289
3545,9.812177069,0.124181165
3550,9.812295086,0.124385371
3555,9.813003189,0.124589174
3560,9.81444443,0.124793827
3565,9.814916498,0.12499678
3570,9.815066702,0.125201791
3575,9.8163184,0.125404253
3580,9.817766793,0.12560743
3585,9.818167336,0.125811099
3590,9.820359595,0.126012667
3595,9.820727952,0.126217186
3600,9.822437413,0.126420587
3605,9.823156245,0.126624256
3610,9.823342211,0.126829758
3615,9.825276978,0.127034589
3620,9.825892098,0.127238616
3625,9.826138862,0.127442508
3630,9.827901967,0.127647027
3635,9.828617223,0.12785235
3640,9.828660138,0.128055885
3645,9.829046376,0.128261208
3650,9.831260093,0.128465637
3655,9.83140672,0.128670737
3660,9.831635602,0.12887673
3665,9.833609708,0.129082053
3670,9.83393515,0.129287555
3675,9.834056743,0.129490867
3680,9.834739812,0.129698514
3685,9.836367019,0.12990272
3690,9.836746105,0.130107819
3695,9.838033565,0.130316272
3700,9.839363941,0.130520656
3705,9.839571365,0.130728125
3710,9.840583452,0.130933851
3715,9.842114099,0.131141051
3720,9.842235693,0.131346061
3725,9.842514643,0.131553798
3730,9.844556698,0.131758004
3735,9.845000156,0.13196212
3740,9.845039496,0.132167667
3745,9.846065888,0.132373929
3750,9.84702433,0.132577642
3755,9.847657332,0.132785022
3760,9.847685942,0.132990121
3765,9.848883995,0.133194774
3770,9.849981913,0.133400231
3775,9.85025371,0.133604437
3780,9.850518355,0.13380976
3785,9.851634154,0.134015664
3790,9.852814326,0.134220719
3795,9.853536734,0.1344302
3800,9.854974398,0.134637043
3805,9.855843434,0.134846791
3810,9.856122384,0.135054081
3815,9.857989201,0.135263875
3820,9.858647237,0.13547416
3825,9.858686576,0.135683954
3830,9.859319577,0.13589026
3835,9.860717902,0.136096746
3840,9.861168513,0.136303499
3845,9.861379514,0.136507705
3850,9.861973176,0.136713877
3855,9.862463126,0.1369192
3860,9.863679061,0.137129888
3865,9.86412252,0.137337357
3870,9.864240537,0.13754724
3875,9.864683996,0.137758016
3880,9.86633266,0.137969106
3885,9.866776119,0.138176218
3890,9.867158781,0.138384223
3895,9.868539224,0.138589501
3900,9.86946548,0.138795137
3905,9.869647871,0.139001176
3910,9.870373855,0.139209628
3915,9.87153257,0.139419153
3920,9.872315775,0.139629662
3925,9.872408758,0.139840975
3930,9.873467337,0.14004907
3935,9.874783407,0.140259847
3940,9.875033747,0.140467182
3945,9.875305544,0.140672058
3950,9.875981461,0.140875995
3955,9.876224648,0.141084358
3960,9.877633701,0.141296208
3965,9.877737414,0.141508371
3970,9.878095041,0.141720489
3975,9.878881823,0.141932294
3980,9.880072724,0.142139942
3985,9.880326639,0.142343521
3990,9.880476843,0.142551124
3995,9.881499659,0.142761454
4000,9.88290156,0.142976836
4005,9.883234154,0.143191591
4010,9.883541714,0.143401474
4015,9.884700429,0.143606395
4020,9.885784041,0.143812746
4025,9.885962855,0.144025892
4030,9.887132298,0.144240737
4035,9.888044249,0.14445661
4040,9.888469826,0.144666225
4045,9.88862003,0.144872621
4050,9.888888251,0.145079598
4055,9.889027726,0.145291224
4060,9.890132796,0.145508528
4065,9.890865933,0.145721004
4070,9.891355884,0.145930306
4075,9.891380918,0.146135092
4080,9.891509664,0.14634265
4085,9.8918208,0.146557585
4090,9.892693412,0.146773458
4095,9.89369477,0.14698647
4100,9.894216907,0.147192821
4105,9.894739043,0.147400111
4110,9.896480691,0.147615627
4115,9.89679898,0.147830472
4120,9.896902692,0.148043752
4125,9.898050678,0.148251623
4130,9.899509799,0.148458556
4135,9.899667156,0.148675681
4140,9.899713647,0.14889294
4145,9.900031936,0.149104342
4150,9.900457513,0.149310962
4155,9.900847328,0.149521873
4160,9.902174127,0.149739087
4165,9.902284992,0.149955273
4170,9.902352941,0.15016386
4175,9.902374399,0.150371463
4180,9.90346874,0.150587291
4185,9.903890741,0.150805221
4190,9.904845608,0.151019172
4195,9.90513171,0.151222975
4200,9.905532253,0.151440055
4205,9.906172407,0.151659773
4210,9.907652987,0.151870192
4215,9.907892597,0.152077929
4220,9.907889021,0.152295903
4225,9.908886803,0.152515978
4230,9.909884585,0.152723671
4235,9.909859551,0.15293418
4240,9.910521162,0.153155417
4245,9.910567654,0.153371424
4250,9.910742891,0.153579296
4255,9.910639179,0.153791771
4260,9.911390198,0.154009477
4265,9.91272415,0.154227094
4270,9.91331066,0.154433892
4275,9.913257016,0.154648826
4280,9.913364304,0.154869617
4285,9.913271321,0.155081377
4290,9.913582457,0.155290903
4295,9.914476527,0.155511291
4300,9.915195359,0.15572855
4305,9.915849818,0.155936957
4310,9.916028632,0.156159134
4315,9.916389836,0.15637751
4320,9.917595042,0.156584934
4325,9.918428315,0.156805591
4330,9.918710841,0.157026381
4335,9.918843163,0.157234163
4340,9.918911112,0.157458977
4345,9.920066251,0.157676281
4350,9.920041217,0.157884599
4355,9.921232117,0.15810986
4360,9.921507491,0.158326403
4365,9.921493186,0.158539058
4370,9.921539677,0.158765347
4375,9.92175783,0.158975811
4380,9.921883,0.159198077
4385,9.921872271,0.159417481
4390,9.922569646,0.159628616
4395,9.92339219,0.159857185
4400,9.923635377,0.1600668
4405,9.924232615,0.160289602
4410,9.924397124,0.160509901
4415,9.924951448,0.160723538
4420,9.926067247,0.160947592
4425,9.926528587,0.161160247
4430,9.926839723,0.161383585
4435,9.926972045,0.161602901
4440,9.927547826,0.161820204
4445,9.928059234,0.162046762
4450,9.928681506,0.162256466
4455,9.929253711,0.162482308
4460,9.929457559,0.162697287
4465,9.929597034,0.162922324
4470,9.929679288,0.163140254
4475,9.929800882,0.16335787
4480,9.930019035,0.163584785
4485,9.929943933,0.16379896
4490,9.931031122,0.164025785
4495,9.931331529,0.164237009
4500,9.930998935,0.164466293
4505,9.932286396,0.164678858
4510,9.932390108,0.164909126
4515,9.932590379,0.165122183
4520,9.933148279,0.165347131
4525,9.93408884,0.165565105
4530,9.934904232,0.165789695
4535,9.93498291,0.166009368
4540,9.935222521,0.16622399
4545,9.935258283,0.166452603
4550,9.868532072,0.166624846
4555,9.783938771,0.166657926
4560,9.742836597,0.166658686
4565,9.714884401,0.16665967
4570,9.694352984,0.166670086
4575,9.677651762,0.166689353
4580,9.663557646,0.166692348
4585,9.65119445,0.166693466
4590,9.640733835,0.166692795
4595,9.631914731,0.16669351
4600,9.62359273,0.166692303
4605,9.615606899,0.166692706
4610,9.609287614,0.166693376
4615,9.602210158,0.16669351
4620,9.596380824,0.166693823
4625,9.59084832,0.166696908
4630,9.585798614,0.166703122
4635,9.581435554,0.16670339
4640,9.577165477,0.166710453
4645,9.571990602,0.166715683
4650,9.568875663,0.166720601
4655,9.563911788,0.166723104
4660,9.560832611,0.166723417
4665,9.557807079,0.166726189
4670,9.553901783,0.166727261
4675,9.550275436,0.166727664
4680,9.547235599,0.166727217
4685,9.544449678,0.166728424
4690,9.541674485,0.166727798
4695,9.538888564,0.166726814
4700,9.536217084,0.166728468
4705,9.533491959,0.166726948
4710,9.530799021,0.166727396
4715,9.528052439,0.166727664
4720,9.525416721,0.166726457
4725,9.523170818,0.166727306
4730,9.521332611,0.166726948
4735,9.547793499,0.166735621
4740,9.838863262,0.166880952
4745,9.915588749,0.167068349
4750,9.934825554,0.167276846
4755,9.940565481,0.167500051
4760,9.943047419,0.167716997
4765,9.943222656,0.167942123
4770,9.943365708,0.168161841
4775,9.943376436,0.168392064
4780,9.943304911,0.168606954
4785,9.943294182,0.168842094
4790,9.943236962,0.16906275
4795,9.94337286,0.169287475
4800,9.94303669,0.169514345
4805,9.942464485,0.169733884
4810,9.94223918,0.169966744
4815,9.941438093,0.170189546
4820,9.941649094,0.170413511
4825,9.942106857,0.17064512
4830,9.941348686,0.170865776
4835,9.941713467,0.171098055
4840,9.942110434,0.171325507
4845,9.942135468,0.17154585
4850,9.941627636,0.171780499
4855,9.94245018,0.172004016
4860,9.942564621,0.172226103
4865,9.942907944,0.172460886
4870,9.943283453,0.172682436
4875,9.943362131,0.172906848
4880,9.943405047,0.173139753
4885,9.943483725,0.173363673
4890,9.943905726,0.173590185
4895,9.943902149,0.173825326
4900,9.943995133,0.174047502
4905,9.945397034,0.17427388
4910,9.944535151,0.174509155
4915,9.944803372,0.174734639
4920,9.945683136,0.174962135
4925,9.945636645,0.175197276
4930,9.945940628,0.175424101
4935,9.94611229,0.175650614
4940,9.946065798,0.175882088
4945,9.946080103,0.176114949
4950,9.94598712,0.17634097
4955,9.946105137,0.176566141
4960,9.946115866,0.176801505
4965,9.946498528,0.177030521
4970,9.947238818,0.177257033
4975,9.947971955,0.17748453
4980,9.947392598,0.177721547
4985,9.948537007,0.17794949
4990,9.948687211,0.178173902
4995,9.948840991,0.178406271
5000,9.948926821,0.178639221
5005,9.948898211,0.178868326
5010,9.949112788,0.179094347
5015,9.948923245,0.179329576
5020,9.949849501,0.179565343
5025,9.950067654,0.17979409
5030,9.949667111,0.180021765
5035,9.949792281,0.180251094
5040,9.950339451,0.180488827
5045,9.950403824,0.180720615
5050,9.950743571,0.180949586
5055,9.95072569,0.181178066
5060,9.950532571,0.181411731
5065,9.951154843,0.18164705
5070,9.95164837,0.181877988
5075,9.951619759,0.182108032
5080,9.951601878,0.182338345
5085,9.952571049,0.182573083
5090,9.952638999,0.182809877
5095,9.953153983,0.183048012
5100,9.953722611,0.183280828
5105,9.954187528,0.183511945
5110,9.954123155,0.183743465
5115,9.954198256,0.18397856
5120,9.954244748,0.184212628
5125,9.954208985,0.184450629
5130,9.954162494,0.184689167
5135,9.954287663,0.184925291
5140,9.954251901,0.185158911
5145,9.954280511,0.185392129
5150,9.954248324,0.185623649
5155,9.954280511,0.185856375
5160,9.954276935,0.186091783
5165,9.95434846,0.18632983
5170,9.954777614,0.18656877
5175,9.954870597,0.186806592
5180,9.955757514,0.187044102
5185,9.956286803,0.18728188
5190,9.956640855,0.187517735
5195,9.956422702,0.187752429
5200,9.956612245,0.187991324
5205,9.956984178,0.18822718
5210,9.956801787,0.188463303
5215,9.956901923,0.188702422
5220,9.956898347,0.188937652
5225,9.956876889,0.189176995
5230,9.9569055,0.189412448
5235,9.956973449,0.189651299
5240,9.957070008,0.189890641
5245,9.956984178,0.190130967
5250,9.957091466,0.190367493
5255,9.957052127,0.190606836
5260,9.956926957,0.190845597
5265,9.957062856,0.191089499
5270,9.957134381,0.191330719
5275,9.957148686,0.191570509
5280,9.957334653,0.191815975
5285,9.957853213,0.192056614
5290,9.957985536,0.192299265
5295,9.957584993,0.192543301
5300,9.958804504,0.192784253
5305,9.958597079,0.193023238
5310,9.95852913,0.193263787
5315,9.959416047,0.193505097
5320,9.959319488,0.193747747
5325,9.958046332,0.193992678
5330,9.958532706,0.194237072
5335,9.958911792,0.19448236
5340,9.958897487,0.194727379
5345,9.958872453,0.194967795
5350,9.958353892,0.195207852
5355,9.958479062,0.195451934
5360,9.957978383,0.195699591
5365,9.957849637,0.195945594
5370,9.957624332,0.196195308
5375,9.958167926,0.196436483
5380,9.958854572,0.196677882
5385,9.959233657,0.196928087
5390,9.95945181,0.19717722
5395,9.959694997,0.197426397
5400,9.959587709,0.197667617
5405,9.959737912,0.197913218
5410,9.959562675,0.198164362
5415,9.959737912,0.198416177
5420,9.959712878,0.198656771
5425,9.959162131,0.198904294
5430,9.95954837,0.199155796
5435,9.959376708,0.19940627
5440,9.95911564,0.199650798
5445,9.958908216,0.199906144
5450,9.959348098,0.200158898
5455,9.958650724,0.200400878
5460,9.958142892,0.200655732
5465,9.958307401,0.200909603
5470,9.957717315,0.201156054
5475,9.957449094,0.201410372
5480,9.958607808,0.201662946
5485,9.958446876,0.201915208
5490,9.957971231,0.202171717
5495,9.958228723,0.202418972
5500,9.958564893,0.202674318
5505,9.958200112,0.202926446
5510,9.957846061,0.203182239
5515,9.957778112,0.203436334
5520,9.958132163,0.203687478
5525,9.957477704,0.203948189
5530,9.957323924,0.204199735
5535,9.957109347,0.204459731
5540,9.957073585,0.204709623
5545,9.9571165,0.204971496
5550,9.957062856,0.205222864
5555,9.957030669,0.205485229
5560,9.957002059,0.205741424
5565,9.956755296,0.205998425
5570,9.955736056,0.206259404
5575,9.955821887,0.206513811
5580,9.956791059,0.206779484
5585,9.956429854,0.207033579
5590,9.955185309,0.207296122
5595,9.956358329,0.207557101
5600,9.956408397,0.207811911
5605,9.95514597,0.208079372
5610,9.955603734,0.208338652
5615,9.955932752,0.20859981
5620,9.954605952,0.208864723
5625,9.954251901,0.209128518
5630,9.954309121,0.209391866
5635,9.954305545,0.209652711
5640,9.95336856,0.209922899
5645,9.953815595,0.210185085
5650,9.953075305,0.210447539
5655,9.95191659,0.210712586
5660,9.951834336,0.210982461
5665,9.951666251,0.211248536
5670,9.951537505,0.211516534
5675,9.951330081,0.211781312
5680,9.951054707,0.212049042
5685,9.951126233,0.212316815
5690,9.950868741,0.212587272
5695,9.950983182,0.212859158
5700,9.95032157,0.213131805
5705,9.94911994,0.213400294
5710,9.949481145,0.213672002
5715,9.948998347,0.213943754
5720,9.94878377,0.214217429
5725,9.94875516,0.214489092
5730,9.948086396,0.214764957
5735,9.947714463,0.215036576
5740,9.946201697,0.21530958
5745,9.946087256,0.215587144
5750,9.946123019,0.21585903
5755,9.944327727,0.216131945
5760,9.943716183,0.216407631
5765,9.943383589,0.216683407
5770,9.943297758,0.216957976
5775,9.942525282,0.217238267
5780,9.942042484,0.217517396
5785,9.941030397,0.217799832
5790,9.940822973,0.218082403
5795,9.940669193,0.218360503
5800,9.940608397,0.218643029
5805,9.938809528,0.218930786
5810,9.938738003,0.219211524
5815,9.938022747,0.219491323
5820,9.937854662,0.219780062
5825,9.937185898,0.220063661
5830,9.936052217,0.220348512
5835,9.935150995,0.220635285
5840,9.934739723,0.220919465
5845,9.933294906,0.22120664
5850,9.932404413,0.221497168
5855,9.931188478,0.221783986
5860,9.929901018,0.222076972
5865,9.929707898,0.222361644
5870,9.927748098,0.22265472
5875,9.927086486,0.222945561
5880,9.926124467,0.223239621
5885,9.924693955,0.22353444
5890,9.924175395,0.223823538
5895,9.923828496,0.224124258
5900,9.921915187,0.224416485
5905,9.921432389,0.22471117
5910,9.920184268,0.225010326
5915,9.91877879,0.225306799
5920,9.91724099,0.225602155
5925,9.916143073,0.225903948
5930,9.915574444,0.226204177
5935,9.913342846,0.226503243
5940,9.91134013,0.226804411
5945,9.910546196,0.227104908
5950,9.90787114,0.227409651
5955,9.906819714,0.227715959
5960,9.905163896,0.228020927
5965,9.902495992,0.228327324
5970,9.900972498,0.228633588
5975,9.899660003,0.228943607
5980,9.896909845,0.229249289
5985,9.895000112,0.229558637
5990,9.894070279,0.229869818
5995,9.891445291,0.23017711
6000,9.88910998,0.230489185
6005,9.887146603,0.230804389
6010,9.885841261,0.231117716
6015,9.883219849,0.231429299
6020,9.880176436,0.231745442
6025,9.877744566,0.232056981
6030,9.875062357,0.232375136
6035,9.872179876,0.232691547
6040,9.86956204,0.233010327
6045,9.866779695,0.233327543
6050,9.863314281,0.233646726
6055,9.859923968,0.233964479
6060,9.856365571,0.234284243
6065,9.853247056,0.234608432
6070,9.850360999,0.234925425
6075,9.846137413,0.235248586
6080,9.842285761,0.23556996
6085,9.838401922,0.235894775
6090,9.834675439,0.236218339
6095,9.83116711,0.236542395
6100,9.826746829,0.236867925
6105,9.823159821,0.237195155
6110,9.818449862,0.237518138
6115,9.814791329,0.237843043
6120,9.809491283,0.238171211
6125,9.804713375,0.238498217
6130,9.80047906,0.238824105
6135,9.795118218,0.239153212
6140,9.79024375,0.239479727
6145,9.784872179,0.239811784
6150,9.779328947,0.240141696
6155,9.773918037,0.240474916
6160,9.768453483,0.240804872
6165,9.761948232,0.241136259
6170,9.755160454,0.241468004
6175,9.749374035,0.241801402
6180,9.742976072,0.242128945
6185,9.735633971,0.242464847
6190,9.730155112,0.242794714
6195,9.72297752,0.243128559
6200,9.716264845,0.243460036
6205,9.710067154,0.243794999
6210,9.70281446,0.244124285
6215,9.694935918,0.244458175
6220,9.688530802,0.244793004
6225,9.681013464,0.245128459
6230,9.672902463,0.245461724
6235,9.664637683,0.245797581
6240,9.656476614,0.24612937
6245,9.648233291,0.246463708
6250,9.640047189,0.246799565
6255,9.631861087,0.247133276
6260,9.622491236,0.247465781
6265,9.612695808,0.247799716
6270,9.60456335,0.248134143
6275,9.595543974,0.24846781
6280,9.585494631,0.248802594
6285,9.576371543,0.249138854
6290,9.566368691,0.24933233
6295,9.556659094,0.24933166
6300,9.546899429,0.249331883
6305,9.537182679,0.249332241
6310,9.526861538,0.249332464
6315,9.516189922,0.249331973
6320,9.505679238,0.249332241
6325,9.495071995,0.249332554
6330,9.483813869,0.249331704
6335,9.472477065,0.249330989
6340,9.460532293,0.249331749
6345,9.448737726,0.24933242
6350,9.436932429,0.249332107
6355,9.424122198,0.249332196
6360,9.412459952,0.249332196
6365,9.399503094,0.249332241
6370,9.386031251,0.249332375
6375,9.37396131,0.24933318
6380,9.360321382,0.249332777
6385,9.347153523,0.249331794
6390,9.333481409,0.249331704
6395,9.319140531,0.249333045
6400,9.305303908,0.249331481
6405,9.291206216,0.249332554
6410,9.276629303,0.249333045
6415,9.261179779,0.249332867
6420,9.246538493,0.24933242
6425,9.230470272,0.249332509
6430,9.2152389,0.249332375
6435,9.199560493,0.249332464
6440,9.183524459,0.249332643
6445,9.167377559,0.249332196
6450,9.150572625,0.249332196
6455,9.133635368,0.249332062
6460,9.115825499,0.249332643
6465,9.098344648,0.249332688
6470,9.079930388,0.24933233
6475,9.061569772,0.249332911
6480,9.042690596,0.249331928
6485,9.02441581,0.249332151
6490,9.004492361,0.249331615
6495,8.985101776,0.249332241
6500,8.964738444,0.249331302
6505,8.944907978,0.249332464
6510,8.923979594,0.249332509
6515,8.902468276,0.249332733
6520,8.881625723,0.24933242
6525,8.859810421,0.249332107
6530,8.836907931,0.249332509
6535,8.814595527,0.249332554
6540,8.791600054,0.24933157
6545,8.767306391,0.249331749
6550,8.743134322,0.249332554
6555,8.718461574,0.249332688
6560,8.692748129,0.24933166
6565,8.667016802,0.249332956
6570,8.640727576,0.249333269
6575,8.614184434,0.249332062
6580,8.586428934,0.249332509
6585,8.558297924,0.249332733
6590,8.529727032,0.249333269
6595,8.500394392,0.249331928
6600,8.470249937,0.249332598
6605,8.439497515,0.249332464
6610,8.408634228,0.249332464
6615,8.376605074,0.24933309
6620,8.343585291,0.249332062
6625,8.310175694,0.249332733
6630,8.275453602,0.24933242
6635,8.24001983,0.249332777
6640,8.203938753,0.249332867
6645,8.165729789,0.249332956
6650,8.127585198,0.249332733
6655,8.086368584,0.249332688
6660,8.044225713,0.24933242
6665,7.999515074,0.249332911
6670,7.952504888,0.249332151
6675,7.895760071,0.249332464
6680,7.785549884,0.249333671
6685,3.980542915,0.249332464
6690,3.287080979,0.249333537
6695,2.830154129,0.249332554
6700,2.494044709,0.249332509
6705,2.130916502,0.24933309
6710,1.727176072,0.249333045
6715,1.258418891,0.249332286
6720,0.847407886,0.249333358
6725,0.60069471,0.249332464
6730,0.278046404,0.249333269
6735,0.118944908,0.249333671
6740,0.056066773,0.249333493
6745,0.012257356,0.249332464
6750,0.012142915,0.249332464
6755,0.012178678,0.24933242
6757.5,0.012250204,0.249332643