File: Coupon(GU)/S3.csv
Time*,C-3DKA-5 Instron Force (kN),C-3DKA-5 Extensometer (mm/mm)
0,0.01505043,3.43985E-05
1.5,0.015089769,3.48008E-05
3,0.015082617,3.32362E-05
4.5,0.014961023,3.39514E-05
6,0.014914531,3.44432E-05
7.5,0.014835853,3.42197E-05
9,0.014814396,3.68572E-05
10.5,0.014903803,3.5829E-05
12,0.014875192,3.54267E-05
13.5,0.014961023,3.69019E-05
15,0.014914531,3.68125E-05
16.5,0.01584794,3.50243E-05
18,0.015980263,3.51584E-05
19.5,0.018916387,3.63207E-05
21,0.033779403,3.69466E-05
22.5,0.032223721,3.23868E-05
24,0.017425079,5.72867E-05
25.5,0.030238886,-0.000498691
27,0.039254686,-0.001055025
28.5,0.026326437,-0.001368665
30,0.037341376,-0.001786598
31.5,0.047505161,-0.001944133
33,0.10324862,-0.002034971
34.5,0.074484609,-0.001980566
36,0.113247896,-0.001984366
37.5,0.498334455,-0.001874083
39,0.568361573,-0.001872071
40.5,0.51639824,-0.00178472
42,0.512568045,-0.001792991
43.5,0.511523772,-0.001792186
45,0.509907294,-0.001794019
46.5,0.509789277,-0.001793482
48,0.509714175,-0.001793527
49.5,0.509152699,-0.001792946
51,0.508644867,-0.001794019
52.5,0.507847357,-0.001793885
54,0.507486153,-0.001794108
55.5,0.507246542,-0.001794332
57,0.507110644,-0.001792901
58.5,0.50729661,-0.001793482
60,0.507103491,-0.001794511
61.5,0.507192898,-0.00179384
63,0.507096339,-0.001794958
64.5,0.50711422,-0.00179384
66,0.507014084,-0.001794689
67.5,0.608051116,-0.001735457
69,0.741417708,-0.001663619
70.5,0.86948068,-0.001593837
72,0.990097838,-0.001529598
73.5,1.108619297,-0.001470813
75,1.22480187,-0.00141243
76.5,1.338466742,-0.001348727
78,1.452042207,-0.001282969
79.5,1.563754431,-0.00122539
81,1.672827361,-0.001172104
82.5,1.78237236,-0.001111039
84,1.89043678,-0.001047649
85.5,1.996637958,-0.000995749
87,2.103203917,-0.000939243
88.5,2.209326417,-0.000873753
90,2.312355436,-0.000825831
91.5,2.41493742,-0.000769996
93,2.517265488,-0.000710183
94.5,2.617390568,-0.000664049
96,2.717111529,-0.000602492
97.5,2.817486949,-0.000551575
99,2.91616006,-0.000496142
100.5,3.014017779,-0.00044156
102,3.111610854,-0.000392565
103.5,3.208352775,-0.000334673
105,3.303378082,-0.000288629
106.5,3.399197322,-0.00023114
108,3.494025933,-0.000185051
109.5,3.587574237,-0.000125372
111,3.682095288,-8.33058E-05
112.5,3.775493388,-2.34478E-05
114,3.868029604,1.42372E-05
115.5,3.960361973,6.33216E-05
117,4.051793119,0.000116608
118.5,4.142576959,0.000163457
120,4.233507427,0.000217191
121.5,4.323511638,0.000263146
123,4.412636084,0.000317953
124.5,4.502232599,0.00036279
126,4.59097796,0.000418983
127.5,4.678890048,0.000462613
129,4.765071217,0.000518224
130.5,4.851753065,0.000561453
132,4.937916353,0.00061237
133.5,5.023053248,0.000662572
135,5.108208025,0.000704951
136.5,5.193573802,0.000763468
138,5.278163527,0.000805087
139.5,5.361312012,0.000862843
141,5.443777427,0.000903971
142.5,5.525409569,0.000960655
144,5.606608981,0.001004598
145.5,5.686689018,0.001059718
147,5.766021613,0.001106477
148.5,5.844638952,0.001157082
150,5.922126187,0.001209161
151.5,5.998672861,0.001264549
153,6.073467158,0.001312248
154.5,6.146398213,0.001373804
156,6.218063266,0.001420117
157.5,6.287485992,0.001481182
159,6.355864445,0.001539833
160.5,6.421936197,0.001594461
162,6.485236334,0.0016549
163.5,6.546276262,0.001722179
165,6.604480201,0.001788921
166.5,6.659190116,0.001858301
168,6.711618365,0.001925937
169.5,6.761264268,0.001996747
171,6.808199353,0.002070419
172.5,6.853095958,0.002151779
174,6.895685863,0.002231754
175.5,6.935761645,0.002311862
177,6.973666625,0.002398766
178.5,7.008982379,0.002480752
180,7.04241701,0.002572439
181.5,7.073823892,0.002658761
183,7.103632176,0.00274866
184.5,7.132292475,0.002843834
186,7.159904925,0.002936728
187.5,7.186551779,0.003031275
189,7.211203069,0.003127343
190.5,7.234266492,0.003226406
192,7.257090304,0.003328375
193.5,7.278319095,0.003428153
195,7.298246121,0.003532849
196.5,7.318477131,0.003634728
198,7.337667444,0.00374452
199.5,7.356278399,0.003850199
201,7.374098997,0.003958247
202.5,7.390485507,0.004068218
204,7.406210405,0.004178859
205.5,7.377936344,0.004246227
207,7.35008786,0.004246719
208.5,7.335446574,0.004246987
210,7.325686909,0.004247076
211.5,7.31820891,0.004246763
213,7.311771608,0.004246808
214.5,7.307018733,0.004247166
216,7.303138471,0.00424873
217.5,7.298857665,0.004249401
219,7.295302844,0.004248283
220.5,7.292381024,0.00425025
222,7.289627289,0.004249401
223.5,7.287077402,0.004251368
225,7.284588312,0.004250116
226.5,7.282839512,0.004251859
228,7.281276678,0.004250474
229.5,7.278716062,0.004251278
231,7.277035211,0.004251457
232.5,7.275958751,0.004251994
234,7.273523305,0.004250876
235.5,7.272818778,0.004251994
237,7.270647977,0.004249848
238.5,7.269993518,0.004251144
240,7.267869208,0.004249624
241.5,7.267504428,0.00424721
243,7.265305016,0.004251457
244.5,7.264983151,0.004249848
246,7.26314852,0.004250116
247.5,7.262232993,0.004251591
249,7.26137111,0.0042511
250.5,7.259786818,0.004251815
252,7.259557936,0.004252083
253.5,7.258313391,0.004249848
255,7.256915066,0.004249535
256.5,7.256832812,0.004249311
258,7.255713436,0.00424949
259.5,7.254189942,0.00424806
261,7.254093382,0.004249133
262.5,7.253488991,0.00424806
264,7.251826021,0.004248149
265.5,7.251328918,0.004249624
267,7.251218054,0.004247702
268.5,7.249830458,0.004247344
270,7.24876115,0.004249177
271.5,7.248657438,0.004247881
273,7.248335573,0.004247389
274.5,7.247144672,0.004248864
276,7.246010992,0.004246808
277.5,7.245950195,0.004247255
279,7.245714161,0.004247791
280.5,7.244655582,0.004247255
282,7.243521902,0.004247791
283.5,7.243124935,0.004248015
285,7.243124935,0.004247389
286.5,7.242527696,0.004247881
288,7.241486999,0.004247255
289.5,7.240546438,0.004246227
291,7.240482065,0.004246584
292.5,7.240356895,0.004247434
294,7.239949199,0.004246361
295.5,7.238704654,0.004247076
297,7.237996551,0.004247166
298.5,7.237674686,0.0042473
300,7.237753364,0.00424721
301.5,7.237438651,0.004246137
303,7.236734124,0.004247344
304.5,7.235722037,0.004246093
306,7.235092612,0.004247479
307.5,7.234942408,0.004247032
309,7.234974595,0.004247434
310.5,7.234802934,0.004246495
312,7.233926745,0.00424654
313.5,7.233050557,0.004247523
315,7.232421132,0.00424721
316.5,7.232303115,0.004246361
318,7.232281657,0.004246182
319.5,7.232188674,0.00424645
321,7.231709452,0.004246987
322.5,7.230743857,0.004247702
324,7.230160924,0.00424654
325.5,7.22957799,0.004246629
327,7.229524346,0.004246137
328.5,7.229506465,0.004246361
330,7.229409905,0.004247166
331.5,7.228955718,0.004246182
333,7.228304835,0.004246361
334.5,7.22739646,0.004246093
336,7.227013798,0.004247076
337.5,7.226967307,0.004246942
339,7.226763459,0.00424721
340.5,7.22662756,0.004246584
342,7.226659747,0.004246137
343.5,7.226223441,0.004246853
345,7.225658388,0.004246897
346.5,7.224971743,0.004246853
348,7.224227877,0.004245959
349.5,7.224117012,0.00424721
351,7.224059792,0.0042473
352.5,7.224106283,0.004245869
354,7.223916741,0.004247568
355.5,7.223712893,0.004246316
357,7.223337383,0.004245959
358.5,7.222339602,0.004246853
360,7.221892567,0.004245735
361.5,7.221449108,0.004246629
363,7.221320362,0.004245959
364.5,7.22134182,0.004246406
366,7.221295328,0.004247121
367.5,7.221298904,0.004246674
369,7.221137972,0.004246495
370.5,7.22069809,0.004247747
372,7.220125885,0.004246853
373.5,7.219374866,0.004247389
375,7.21903512,0.00424654
376.5,7.218774052,0.004246495
378,7.218702526,0.004246763
379.5,7.218631,0.004246048
381,7.218595238,0.004246137
382.5,7.218530865,0.00424569
384,7.218462915,0.004245467
385.5,7.281491255,0.004276804
387,7.398972017,0.004351682
388.5,7.485618102,0.004433713
390,7.499436843,0.004547484
391.5,7.500191438,0.004673682
393,7.50555228,0.004799432
394.5,7.513173331,0.004921697
396,7.522421588,0.005047
397.5,7.531398048,0.005169175
399,7.539848795,0.005290903
400.5,7.549508324,0.00541491
402,7.558917514,0.005536638
403.5,7.568380348,0.005663417
405,7.577303164,0.005782864
406.5,7.585778945,0.005907408
408,7.592995876,0.006033025
409.5,7.600574011,0.00615368
411,7.607891077,0.006280772
412.5,7.614972109,0.006408222
414,7.622535939,0.00653138
415.5,7.629609819,0.006659276
417,7.636662241,0.006786681
418.5,7.642638203,0.006910465
420,7.649121997,0.007037736
421.5,7.654811856,0.007166527
423,7.660226343,0.007294558
424.5,7.665948389,0.007420666
426,7.671981571,0.007549412
427.5,7.677446126,0.007680393
429,7.683014392,0.007810972
430.5,7.688146352,0.007941417
432,7.692309141,0.00806757
433.5,7.6968081,0.008198462
435,7.700827837,0.00832913
436.5,7.705190897,0.008463688
438,7.709611178,0.008594982
439.5,7.713652373,0.008728198
441,7.71881652,0.008861415
442.5,7.722625257,0.008990965
444,7.726805927,0.009121589
445.5,7.730046036,0.009256191
447,7.733253958,0.009388379
448.5,7.73713422,0.00952401
450,7.740606787,0.009657271
451.5,7.743449929,0.009791158
453,7.748281482,0.009925134
454.5,7.751385692,0.010060273
456,7.754314664,0.010193757
457.5,7.757004026,0.010326169
459,7.759757761,0.010461755
460.5,7.762522224,0.010595731
462,7.765233044,0.010732747
463.5,7.768330101,0.010867663
465,7.771788363,0.011001102
466.5,7.773855452,0.011138253
468,7.777306561,0.011273436
469.5,7.779355769,0.011406652
471,7.781605249,0.011543624
472.5,7.784308915,0.011680327
474,7.786833768,0.011816718
475.5,7.789344316,0.011955879
477,7.792602306,0.012091689
478.5,7.794926887,0.012230448
480,7.796060568,0.012363531
481.5,7.798256403,0.012500413
483,7.80080629,0.012638412
484.5,7.803123719,0.012774624
486,7.804293162,0.012909897
487.5,7.806946761,0.013049506
489,7.809099681,0.013186745
490.5,7.811735398,0.013324566
492,7.814392573,0.013462923
493.5,7.816177137,0.013601236
495,7.817235715,0.01373928
496.5,7.819252737,0.013876386
498,7.820468671,0.014013983
499.5,7.822671659,0.014152251
501,7.825085647,0.014290832
502.5,7.827835806,0.014430396
504,7.828425892,0.014568977
505.5,7.830789812,0.014704742
507,7.832574375,0.014843904
508.5,7.833625801,0.014982797
510,7.835589179,0.015120126
511.5,7.837012538,0.015259244
513,7.839040288,0.015395098
514.5,7.841751107,0.015534036
516,7.843524941,0.015671186
517.5,7.844436893,0.015809856
519,7.845245132,0.015946515
520.5,7.847265729,0.016083755
522,7.848145494,0.01622399
523.5,7.849719056,0.016362436
525,7.852100858,0.016503208
526.5,7.852694521,0.016643979
528,7.85420371,0.016783051
529.5,7.855423221,0.016921319
531,7.857390175,0.017060302
532.5,7.858244905,0.017200627
534,7.859725485,0.017337643
535.5,7.860780487,0.017479129
537,7.862497101,0.017616727
538.5,7.863877545,0.017754726
540,7.863477001,0.017893799
541.5,7.863115797,0.018032737
543,7.863777409,0.01817248
544.5,7.865647803,0.018312447
546,7.866427431,0.018454291
547.5,7.867435942,0.018596001
549,7.869152556,0.018736415
550.5,7.871738206,0.018877052
552,7.872961293,0.019016169
553.5,7.874584924,0.019156047
555,7.875861655,0.019291856
556.5,7.877074014,0.019432627
558,7.877867948,0.019569598
559.5,7.879523765,0.019711666
561,7.880575191,0.019851677
562.5,7.882756721,0.019992449
564,7.883346807,0.020135098
565.5,7.885463964,0.020274751
567,7.885850202,0.020413779
568.5,7.88820697,0.020551734
570,7.88833214,0.020691164
571.5,7.889973652,0.020828896
573,7.890953552,0.020968683
574.5,7.893478405,0.021109142
576,7.894165051,0.021250539
577.5,7.896321547,0.021389477
579,7.897108328,0.02153007
580.5,7.898349297,0.021670975
582,7.89918257,0.021811299
583.5,7.899561655,0.021952339
585,7.901274693,0.022091412
586.5,7.901997101,0.02222807
588,7.904471886,0.022368126
589.5,7.904947532,0.02250769
591,7.906270755,0.022646539
592.5,7.907268537,0.022788518
594,7.907558215,0.022927322
595.5,7.908616794,0.023068004
597,7.909918559,0.023208283
598.5,7.911184562,0.023347267
600,7.912815345,0.023485892
601.5,7.914803756,0.023624562
603,7.915479673,0.023763367
604.5,7.915669216,0.02389998
606,7.917114032,0.024038159
607.5,7.918215526,0.024177544
609,7.918290628,0.024315186
610.5,7.920379175,0.024452963
612,7.92162372,0.02459436
613.5,7.923551334,0.024733164
615,7.923780216,0.024871566
616.5,7.925668491,0.025011622
618,7.926011814,0.025152796
619.5,7.926290764,0.025291242
621,7.926752104,0.025430315
622.5,7.928758396,0.025569879
624,7.929148211,0.025707611
625.5,7.931411995,0.025844806
627,7.931912674,0.025982671
628.5,7.932173743,0.026120939
630,7.933779492,0.026260012
631.5,7.934680714,0.026399889
633,7.934730782,0.026536592
634.5,7.936579718,0.026677006
636,7.938117518,0.026817196
637.5,7.939977183,0.026957788
639,7.940206065,0.027096593
640.5,7.941869035,0.02723562
642,7.942620053,0.027374693
643.5,7.942823901,0.027515107
645,7.943557039,0.027651274
646.5,7.944894567,0.0277882
648,7.945552602,0.027926781
649.5,7.948073879,0.028066703
651,7.948270574,0.028203943
652.5,7.948982254,0.028341629
654,7.950434223,0.028478556
655.5,7.950974241,0.028617316
657,7.951178089,0.028756567
658.5,7.953141466,0.028893583
660,7.953788772,0.029031762
661.5,7.955673471,0.029173204
663,7.956499592,0.029311963
664.5,7.957286373,0.029450723
666,7.958505884,0.029588231
667.5,7.958727614,0.029728823
669,7.95934631,0.029864811
670.5,7.959850565,0.030005001
672,7.960876957,0.030142644
673.5,7.962307469,0.030281358
675,7.964531914,0.030419805
676.5,7.964674965,0.030557447
678,7.966194884,0.030695134
679.5,7.966877953,0.030834162
681,7.967328564,0.030969837
682.5,7.967489497,0.031107121
684,7.96850516,0.031245523
685.5,7.970153825,0.031385982
687,7.971466319,0.031520763
688.5,7.972846763,0.031661355
690,7.972939746,0.031797701
691.5,7.973061339,0.031935879
693,7.974180715,0.032075533
694.5,7.975178497,0.03221322
696,7.97563626,0.032352247
697.5,7.977295654,0.032493913
699,7.978350656,0.032632851
700.5,7.978493707,0.032770359
702,7.980503576,0.032908761
703.5,7.981036441,0.033046224
705,7.981140153,0.033183196
706.5,7.981748121,0.033320659
708,7.983175056,0.03345991
709.5,7.983675735,0.033597552
711,7.984559076,0.033734971
712.5,7.986529606,0.033873731
714,7.986551063,0.034010881
715.5,7.987019556,0.034147227
717,7.988804119,0.034287283
718.5,7.988904255,0.034424925
720,7.989218968,0.034562835
721.5,7.98978402,0.034700834
723,7.991822499,0.034839996
724.5,7.992155092,0.03498193
726,7.993664282,0.035121003
727.5,7.994572657,0.03526164
729,7.994504708,0.035399014
730.5,7.994676369,0.035537594
732,7.995520371,0.035675952
733.5,7.996460932,0.035813415
735,7.997440833,0.0359528
736.5,7.999765414,0.03608928
738,8.000037211,0.03622947
739.5,8.000223178,0.036366173
741,8.000734586,0.036503458
742.5,8.00158574,0.036642843
744,8.00192191,0.036780217
745.5,8.002926845,0.036920631
747,8.004192847,0.037061536
748.5,8.005330104,0.037199089
750,8.005548257,0.037337938
751.5,8.006145496,0.037478128
753,8.006027478,0.037615144
754.5,8.007175464,0.037757212
756,8.008133907,0.037895748
757.5,8.008133907,0.038033345
759,8.008970756,0.038172328
760.5,8.01105215,0.038311893
762,8.011238117,0.038449803
763.5,8.011377592,0.038586104
765,8.013348121,0.038727143
766.5,8.013712902,0.038865322
768,8.013755817,0.039003992
769.5,8.01400258,0.039145792
771,8.015025396,0.039286742
772.5,8.01649167,0.039426082
774,8.016860027,0.039565915
775.5,8.017392893,0.039705658
777,8.017113943,0.039844731
778.5,8.018852014,0.039983177
780,8.019195337,0.040121266
781.5,8.019248981,0.040259668
783,8.019742508,0.040398428
784.5,8.021852512,0.040536696
786,8.022099276,0.040676126
787.5,8.022675057,0.040815154
789,8.023089905,0.040954942
790.5,8.023762245,0.041095132
792,8.024073382,0.041234473
793.5,8.024473925,0.041374618
795,8.024860163,0.041513825
796.5,8.025267859,0.041653836
798,8.027474423,0.041792238
799.5,8.02743866,0.041931445
801,8.027560254,0.042067924
802.5,8.027989407,0.042206595
804,8.029105206,0.042346919
805.5,8.028844138,0.042483667
807,8.030228158,0.042625824
808.5,8.030507107,0.042765567
810,8.031783839,0.042905712
811.5,8.032981892,0.043047065
813,8.033017655,0.043186808
814.5,8.033067723,0.043326864
816,8.033107062,0.043466115
817.5,8.033400317,0.043604473
819,8.034294387,0.043743456
820.5,8.03543522,0.043882886
822,8.035853644,0.04402245
823.5,8.036114713,0.044163266
825,8.036325713,0.044305155
826.5,8.037724038,0.044445524
828,8.037938615,0.044585938
829.5,8.037995835,0.044726262
831,8.038435718,0.04486681
832.5,8.039358398,0.045005525
834,8.040302535,0.045144508
835.5,8.041164419,0.045283223
837,8.041178724,0.0454231
838.5,8.041225215,0.045562128
840,8.041321775,0.045704151
841.5,8.041811725,0.045844207
843,8.041761657,0.045986721
844.5,8.042805931,0.046126509
846,8.043943187,0.046265313
847.5,8.044100544,0.046403313
849,8.044636985,0.046543682
850.5,8.046110412,0.046682263
852,8.046271345,0.046823615
853.5,8.045434496,0.046962643
855,8.04616048,0.047105471
856.5,8.046800634,0.047245795
858,8.046904346,0.047388623
859.5,8.048535129,0.047531495
861,8.049311182,0.047669808
862.5,8.04902508,0.047808791
864,8.04911091,0.047949383
865.5,8.049329063,0.0480923
867,8.049318334,0.04823705
868.5,8.049489996,0.048377598
870,8.051485559,0.048519844
871.5,8.051968357,0.04865914
873,8.051954052,0.048799599
874.5,8.052075645,0.048939878
876,8.052136442,0.049081097
877.5,8.052175781,0.049223701
879,8.052182934,0.04936702
880.5,8.052479765,0.049509043
882,8.052919647,0.049649501
883.5,8.054149887,0.049788932
885,8.054832956,0.049930731
886.5,8.054825804,0.05007186
888,8.054861567,0.050215224
889.5,8.054918787,0.050358946
891,8.054929516,0.050499404
892.5,8.054965279,0.050638521
894,8.056513808,0.050779069
895.5,8.057182572,0.050922389
897,8.057146809,0.051063741
898.5,8.057672522,0.051206166
900,8.05756881,0.051349352
901.5,8.057629607,0.05149057
903,8.057522318,0.051629151
904.5,8.057543776,0.051769967
906,8.057690403,0.051912571
907.5,8.059092305,0.052054147
909,8.0598469,0.052198003
910.5,8.059972069,0.052342171
912,8.060000679,0.052483077
913.5,8.060193799,0.052622999
915,8.059947035,0.052763233
916.5,8.059843323,0.052907
918,8.060361884,0.053052599
919.5,8.060608647,0.053196947
921,8.060762427,0.053336556
922.5,8.061270259,0.053477014
924,8.061348937,0.053619082
925.5,8.060969851,0.053762356
927,8.06128814,0.053906883
928.5,8.060994885,0.054049397
930,8.061509869,0.054191376
931.5,8.062793753,0.054333175
933,8.063147805,0.054475645
934.5,8.063176415,0.054622094
936,8.063154957,0.054765011
937.5,8.063140652,0.054907436
939,8.063222907,0.055047313
940.5,8.062997601,0.055189381
942,8.062954686,0.055333818
943.5,8.063222907,0.05547982
945,8.063423178,0.055622781
946.5,8.064184926,0.055762837
948,8.06402757,0.055905799
949.5,8.063351653,0.056047196
951,8.063394568,0.056192661
952.5,8.063265822,0.056336919
954,8.063201449,0.056478674
955.5,8.064406655,0.056620608
957,8.065139792,0.056764553
958.5,8.065347216,0.056912164
960,8.065683387,0.057056109
961.5,8.065561793,0.057197462
963,8.064885876,0.057339395
964.5,8.064310096,0.057484234
966,8.064667723,0.057631622
967.5,8.064513943,0.057774941
969,8.065332911,0.057916741
970.5,8.065783522,0.058058764
972,8.065797828,0.058204721
973.5,8.0656512,0.058349962
975,8.065801404,0.058494757
976.5,8.065547488,0.058636199
978,8.06433513,0.058779652
979.5,8.065175555,0.058929141
981,8.065815709,0.059072192
982.5,8.065758489,0.059214975
984,8.065794251,0.059358294
985.5,8.065794251,0.059506531
987,8.065157674,0.059651281
988.5,8.064231417,0.059794466
990,8.064631961,0.059935774
991.5,8.064149163,0.06008486
993,8.064724944,0.060230906
994.5,8.065644048,0.060373063
996,8.06513264,0.060516874
997.5,8.064810775,0.060663055
999,8.064639113,0.060810934
1000.5,8.063787959,0.060953538
1002,8.063276551,0.061096723
1003.5,8.06328728,0.06124791
1005,8.063387416,0.061393912
1006.5,8.063290856,0.061535622
1008,8.063326619,0.061678718
1009.5,8.063269398,0.061827849
1011,8.063222907,0.061975549
1012.5,8.063058398,0.062115069
1014,8.062457583,0.062260802
1015.5,8.061738751,0.062408234
1017,8.062049887,0.062555487
1018.5,8.062614939,0.0626976
1020,8.062818787,0.062843378
1021.5,8.061449072,0.062992643
1023,8.060894749,0.063136677
1024.5,8.060522816,0.063278611
1026,8.060451291,0.063424389
1027.5,8.060383341,0.06357352
1029,8.0602689,0.063718627
1030.5,8.060315392,0.063862394
1032,8.060361884,0.064010854
1033.5,8.060065053,0.064158912
1035,8.059052966,0.064302231
1036.5,8.057951472,0.064446713
1038,8.057654641,0.064598258
1039.5,8.057364962,0.06474198
1041,8.056985876,0.064884763
1042.5,8.003853101,0.064964022
1044,7.963180081,0.064980249
1045.5,7.936619057,0.064999785
1047,7.916752828,0.06499965
1048.5,7.900663149,0.065015297
1050,7.887062561,0.065032373
1051.5,7.875554095,0.065033536
1053,7.865247259,0.065033491
1054.5,7.856045494,0.065033715
1056,7.847523221,0.06503823
1057.5,7.840009459,0.06504878
1059,7.832881935,0.065062504
1060.5,7.826144226,0.065066795
1062,7.820060976,0.065066929
1063.5,7.814517743,0.065067779
1065,7.808999545,0.065067287
1066.5,7.803624398,0.065067108
1068,7.798735624,0.065067063
1069.5,7.794705158,0.065067868
1071,7.789816385,0.065071712
1072.5,7.785567766,0.065074708
1074,7.781669622,0.065078418
1075.5,7.777893071,0.065089773
1077,7.773655181,0.065093349
1078.5,7.770733361,0.065098088
1080,7.76723576,0.065100859
1081.5,7.763226751,0.065101619
1083,7.759990219,0.065102692
1084.5,7.757150653,0.065101977
1086,7.754332546,0.065102692
1087.5,7.751457217,0.06510153
1089,7.748800042,0.065101709
1090.5,7.74587107,0.065101798
1092,7.743027928,0.065102424
1093.5,7.740506651,0.065102156
1095,7.737838747,0.065102066
1096.5,7.735177996,0.06510296
1098,7.732506516,0.065103765
1099.5,7.729788544,0.065103899
1101,7.727342369,0.06510533
1102.5,7.725371839,0.065109576
1104,7.723637344,0.065115298
1105.5,7.721477271,0.065116505
1107,7.718784333,0.065122138
1108.5,7.716216565,0.065125357
1110,7.714721681,0.065128397
1111.5,7.713205338,0.065131928
1113,7.710641146,0.065133224
1114.5,7.708295107,0.065134029
1116,7.707097054,0.065134834
1117.5,7.704958439,0.065135594
1119,7.702465773,0.065136264
1120.5,7.701503754,0.065135996
1122,7.699561834,0.065135415
1123.5,7.697255134,0.065135683
1125,7.696271658,0.065135862
1126.5,7.694133043,0.06513546
1128,7.69255948,0.065135996
1129.5,7.691372156,0.065135951
1131,7.688883066,0.065135013
1132.5,7.688328742,0.065136264
1134,7.685939788,0.065136041
1135.5,7.685024261,0.06513622
1137,7.683207511,0.065136711
1138.5,7.681616067,0.065135504
1140,7.680385827,0.065135683
1141.5,7.678493975,0.065135549
1143,7.677667855,0.065136264
1144.5,7.6758368,0.065137337
1146,7.674949883,0.065137203
1147.5,7.672721861,0.065138634
1149,7.672221182,0.06513841
1150.5,7.670293568,0.065139349
1152,7.669517515,0.065139528
1153.5,7.667479036,0.06514221
1155,7.66680312,0.065144624
1156.5,7.665261743,0.065146054
1158,7.664027927,0.065148021
1159.5,7.663033722,0.065150435
1161,7.661363599,0.065153654
1162.5,7.661116836,0.065154459
1164,7.65874934,0.065156873
1165.5,7.658588407,0.065159912
1167,7.656492708,0.065162148
1168.5,7.655859706,0.065164472
1170,7.654919145,0.065163712
1171.5,7.653220412,0.065164517
1173,7.652902124,0.065167601
1174.5,7.650799272,0.065167736
1176,7.650302169,0.065168183
1177.5,7.648846623,0.065168674
1179,7.647687909,0.06516939
1180.5,7.647459027,0.065169658
1182,7.645302531,0.065168719
1183.5,7.64493775,0.065169479
1185,7.64432263,0.065169166
1186.5,7.642480847,0.065169613
1188,7.642148253,0.065169747
1189.5,7.640892979,0.065169434
1191,7.63946962,0.065169658
1192.5,7.639380213,0.065170462
1194,7.637463327,0.065169613
1195.5,7.636683699,0.065169881
1197,7.636283155,0.065169524
1198.5,7.634330507,0.065170507
1200,7.634044405,0.065169613
1201.5,7.633418556,0.065170194
1203,7.631523128,0.065169881
1204.5,7.631226297,0.065169568
1206,7.630786415,0.065170373
1207.5,7.628865953,0.065170373
1209,7.628526207,0.065169568
1210.5,7.627868171,0.065169837
1212,7.626151557,0.065169255
1213.5,7.625865455,0.065170373
1215,7.625557895,0.065169971
1216.5,7.623744722,0.065169747
1218,7.623086686,0.065170462
1219.5,7.62290072,0.065170194
1221,7.621566768,0.065170194
1222.5,7.620504613,0.065170239
1224,7.61874866,0.065171178
1225.5,7.730568172,0.065254639
1227,7.840889224,0.065339933
1228.5,7.939433589,0.065432291
1230,8.018759031,0.065533365
1231.5,8.072796605,0.065643738
1233,8.101642871,0.06576855
1234.5,8.113086963,0.065903734
1236,8.113659168,0.066043745
1237.5,8.108241106,0.066191892
1239,8.100866818,0.066345404
1240.5,8.093016886,0.066490914
1242,8.084523224,0.066647913
1243.5,8.076741241,0.066794406
1245,8.069288276,0.066947828
1246.5,8.063194297,0.067099239
1248,8.057683251,0.067248549
1249.5,8.052798054,0.067401926
1251,8.049804708,0.067547257
1252.5,8.047605297,0.067699652
1254,8.046178362,0.067850124
1255.5,8.043846628,0.067993935
1257,8.041289588,0.06814843
1258.5,8.038832685,0.068294566
1260,8.038020869,0.068440612
1261.5,8.035710593,0.068593006
1263,8.034491082,0.068739276
1264.5,8.033289452,0.06888787
1266,8.032574197,0.069042902
1267.5,8.0309756,0.069184746
1269,8.030181666,0.0693379
1270.5,8.027481575,0.069487121
1272,8.026319285,0.069630708
1273.5,8.024924536,0.069785248
1275,8.023064871,0.069932457
1276.5,8.022102852,0.07008047
1278,8.021698732,0.070234339
1279.5,8.019366999,0.070379939
1281,8.017421503,0.070531483
1282.5,8.016623993,0.070681911
1284,8.013884563,0.070828672
1285.5,8.011180896,0.070983346
1287,8.010916252,0.071131002
1288.5,8.008670348,0.071280714
1290,8.007286329,0.07143275
1291.5,8.005591172,0.071577992
1293,8.00340249,0.07173356
1294.5,8.000337619,0.071880098
1296,7.9997976,0.07202762
1297.5,7.997490901,0.072183322
1299,7.99466564,0.072328385
1300.5,7.992566365,0.072482209
1302,7.991289633,0.07263219
1303.5,7.988732594,0.072783332
1305,7.986497419,0.072933312
1306.5,7.983718651,0.073079582
1308,7.981072204,0.073235955
1309.5,7.978175418,0.073383253
1311,7.975554006,0.073535289
1312.5,7.972821729,0.073687147
1314,7.97062947,0.07383297
1315.5,7.968172566,0.073990505
1317,7.965415255,0.074137088
1318.5,7.961928383,0.07428984
1320,7.959199682,0.074441161
1321.5,7.956377998,0.074590292
1323,7.952125803,0.074743982
1324.5,7.949468628,0.074890029
1326,7.94732286,0.075046625
1327.5,7.943782344,0.075194146
1329,7.94047071,0.075345691
1330.5,7.937284245,0.075497951
1332,7.933733,0.075647127
1333.5,7.929570212,0.075800504
1335,7.926523222,0.075948026
1336.5,7.923057808,0.076105293
1338,7.919617428,0.076252099
1339.5,7.916584743,0.076407935
1341,7.912783159,0.076556753
1342.5,7.908573878,0.076706376
1344,7.904600632,0.076860514
1345.5,7.900809777,0.077008214
1347,7.896375191,0.077166241
1348.5,7.892155182,0.077311974
1350,7.88857175,0.077467274
1351.5,7.885263692,0.077616941
1353,7.881025802,0.077771168
1354.5,7.877217065,0.07792164
1356,7.871895562,0.078074034
1357.5,7.867772112,0.078227144
1359,7.863416205,0.078375694
1360.5,7.858212719,0.078533452
1362,7.854346761,0.078681063
1363.5,7.850323448,0.078838553
1365,7.845899591,0.078987461
1366.5,7.840599545,0.079141688
1368,7.836325892,0.079290863
1369.5,7.830911406,0.07944366
1371,7.825396784,0.079596277
1372.5,7.820482976,0.079747956
1374,7.815908916,0.079902854
1375.5,7.811302669,0.080051314
1377,7.806546218,0.080209431
1378.5,7.801328427,0.08035646
1380,7.795681482,0.080514308
1381.5,7.790427929,0.080660265
1383,7.78539968,0.08081941
1384.5,7.778915887,0.080968496
1386,7.774116521,0.081124198
1387.5,7.769778494,0.081273865
1389,7.763738159,0.0814314
1390.5,7.758016113,0.081578698
1392,7.752469304,0.081736367
1393.5,7.746171477,0.081887823
1395,7.740109684,0.082041961
1396.5,7.734391215,0.082193416
1398,7.727732183,0.082352158
1399.5,7.722092391,0.082501781
1401,7.71702838,0.082659047
1402.5,7.711209775,0.082809653
1404,7.704568625,0.082967233
1405.5,7.697927475,0.083116901
1407,7.691676139,0.08327828
1408.5,7.683797597,0.083425176
1410,7.677789448,0.083585125
1411.5,7.672138928,0.083736357
1413,7.665208099,0.083895054
1414.5,7.658731458,0.084043336
1416,7.652812717,0.084203866
1417.5,7.644901988,0.084354204
1419,7.637184378,0.084511694
1420.5,7.630947347,0.084662166
1422,7.623283382,0.084819522
1423.5,7.615833993,0.084970128
1425,7.609661335,0.085128021
1426.5,7.602616066,0.085283768
1428,7.595166677,0.085435715
1429.5,7.58754205,0.085591194
1431,7.579595559,0.085744706
1432.5,7.571234219,0.085901883
1434,7.563405744,0.086052355
1435.5,7.556056491,0.086213153
1437,7.548077813,0.086363089
1438.5,7.540885916,0.086522055
1440,7.532953729,0.086672169
1441.5,7.524667491,0.086832207
1443,7.515930642,0.086982947
1444.5,7.507855404,0.087141153
1446,7.498710859,0.087295022
1447.5,7.490159976,0.087452558
1449,7.482395874,0.087611702
1450.5,7.473698364,0.087763962
1452,7.464832769,0.087924537
1453.5,7.456138835,0.08807559
1455,7.44631122,0.088234243
1456.5,7.436805471,0.088388157
1458,7.427010043,0.088545155
1459.5,7.417697413,0.088703898
1461,7.408670885,0.088855621
1462.5,7.399672967,0.089019147
1464,7.390067082,0.089172122
1465.5,7.380175095,0.089330283
1467,7.369431953,0.089487281
1468.5,7.359386185,0.089640391
1470,7.348929146,0.089801905
1471.5,7.337524392,0.08995412
1473,7.32813666,0.090114918
1474.5,7.317633129,0.090274778
1476,7.307254768,0.090426189
1477.5,7.296364999,0.090587032
1479,7.284817194,0.090742153
1480.5,7.273394559,0.090900001
1482,7.261896823,0.091060531
1483.5,7.249794695,0.091213998
1485,7.238357755,0.09137587
1486.5,7.227174731,0.091534791
1488,7.215487451,0.091689643
1489.5,7.202923984,0.091854778
1491,7.190067261,0.092010212
1492.5,7.177392928,0.092166987
1494,7.163524119,0.092331273
1495.5,7.149855581,0.092487109
1497,7.136934485,0.09264527
1498.5,7.122958387,0.092809153
1500,7.108867848,0.092967761
1501.5,7.094323122,0.093127308
1503,7.078136884,0.093289849
1504.5,7.060208998,0.093453822
1506,7.040096005,0.093613056
1507.5,7.006689984,0.093787757
1509,6.850481698,0.094038409
1510.5,1.51134764,0.097372395
1512,1.51839291,0.097371546
1513.5,1.521758188,0.097371948
1515,1.523696531,0.097371769
1516.5,1.523914684,0.097371501