File: Coupon(GU)/S5.csv
Time,Instron Force (kN),Extensometer (mm/mm)
0,0.010520371,1.18392E-06
5,0.01077071,-4.35931E-06
10,0.010877999,-1.15119E-05
15,0.010645541,-1.07072E-05
20,0.010985287,-1.96479E-05
25,0.035464916,-0.000227161
30,1.321155062,-9.72532E-05
35,0.516277733,-0.000150987
40,0.516563835,-0.000151076
45,0.516402903,-0.000150629
50,0.516510191,-0.000149467
55,0.516152563,-0.000150808
60,0.516134682,-0.000150719
65,0.524717751,-0.000150271
70,0.530457679,-0.000181385
75,0.700330926,-0.00015045
80,0.983876199,-9.26934E-05
85,1.268190372,-7.93718E-05
90,1.543885712,-1.26742E-05
95,1.678353799,-3.91227E-06
100,1.899940039,5.01789E-05
105,2.078914917,5.16095E-05
110,2.272266435,0.000113747
115,2.446431218,0.000118844
120,2.650404285,0.000183217
125,2.818399986,0.000185809
130,3.021854493,0.000255457
135,3.121847251,0.000251792
140,3.331041685,0.000290326
145,3.540969257,0.000323138
150,3.706801309,0.000386081
155,3.870255136,0.000391088
160,4.018956813,0.000423364
165,4.196376009,0.000457964
170,4.387724812,0.000516079
175,4.534566823,0.000529937
180,4.666746091,0.000529579
185,4.823816261,0.000596277
190,4.939365832,0.00060182
195,5.158037405,0.00066521
200,5.31274723,0.000665657
205,5.414313551,0.000729135
210,5.619270095,0.000732444
215,5.717117086,0.000793419
220,5.920732525,0.00080227
225,5.990183861,0.000856898
230,6.19662456,0.000869326
235,6.310064127,0.000933073
240,6.480080426,0.000937901
245,6.65708835,0.001008801
250,6.715292289,0.001007549
255,6.900793876,0.001073531
260,7.060957526,0.001141838
265,7.21961914,0.001144341
270,7.277590621,0.001209698
275,7.436037657,0.001281313
280,7.572740918,0.001332901
285,7.68265785,0.001353554
290,7.79806437,0.001415423
295,7.886040831,0.001485966
300,7.955313354,0.00155463
305,8.080179131,0.001622937
310,8.137792984,0.00169026
315,8.197355909,0.001824639
320,8.234531329,0.001957051
325,8.240110324,0.002042077
330,8.139795701,0.002098046
335,8.098400272,0.002099834
340,8.082861341,0.002099744
345,8.057773744,0.002099297
350,8.043629561,0.002098224
355,8.04259244,0.002100817
360,8.030093345,0.002099029
365,8.016664418,0.002098135
370,8.016789588,0.002099655
375,8.002985151,0.002099297
380,8.003020914,0.002100191
385,7.989645631,0.002099029
390,8.080590403,0.002100281
395,8.251482891,0.002235285
400,8.276016164,0.00237333
405,8.275765824,0.002576015
410,8.275783706,0.002714596
415,8.275926757,0.002919428
420,8.276051927,0.003085724
425,8.276105571,0.003260605
430,8.276123452,0.00346776
435,8.275855231,0.003671519
440,8.283454824,0.003871612
445,8.289731193,0.004080109
450,8.289802719,0.004285387
455,8.303338935,0.004489414
460,8.303267409,0.004692189
465,8.316946676,0.004897557
470,8.32776492,0.005102567
475,8.331019333,0.005305789
480,8.344519786,0.005507134
485,8.344287328,0.005657337
490,8.357948713,0.005853675
495,8.37187832,0.006056539
500,8.371556455,0.006227843
505,8.385164196,0.006399057
510,8.387917931,0.006603978
515,8.398914988,0.006746851
520,8.412862476,0.006946049
525,8.413023409,0.007129065
530,8.426201996,0.007285438
535,8.440364061,0.007492505
540,8.439899144,0.007631801
545,8.45356053,0.007834844
550,8.467096745,0.007983707
555,8.46754378,0.008174054
560,8.480722368,0.008358501
565,8.494651974,0.00851845
570,8.4947235,0.008717738
575,8.508402767,0.00886061
580,8.521581355,0.009063564
585,8.522207203,0.009203039
590,8.535868589,0.009406797
595,8.535618249,0.009542875
600,8.549243872,0.009747885
605,8.524656954,0.009888612
610,8.535940114,0.009962194
615,8.569056457,0.010156922
620,8.576960033,0.010296397
625,8.590049214,0.010499708
630,8.590245909,0.010649912
635,8.603925176,0.010841779
640,8.567786878,0.010909907
645,8.617765376,0.011091135
650,8.617532917,0.011249833
655,8.631301591,0.011443846
660,8.63180227,0.011592083
665,8.644766281,0.011797003
670,8.658678006,0.01193469
675,8.658642243,0.012138538
680,8.67219634,0.012284718
685,8.672232103,0.012480609
690,8.685857726,0.012666665
695,8.685732556,0.012820266
700,8.699751569,0.013023488
705,8.699429704,0.013161443
710,8.712751343,0.013367795
715,8.719599917,0.013509594
720,8.726663068,0.013706289
725,8.735889868,0.013888501
730,8.740378098,0.014048003
735,8.753753381,0.014254265
740,8.754575925,0.014391147
745,8.762926536,0.01459723
750,8.768416124,0.014751189
755,8.777178007,0.014935546
760,8.782113272,0.015134119
765,8.795434911,0.015276365
770,8.7955422,0.015483432
775,8.806789597,0.015621118
780,8.809346636,0.015824251
785,8.819646319,0.016002171
790,8.823097429,0.01616507
795,8.824814042,0.016370796
800,8.836901865,0.016508751
805,8.836615763,0.016714208
810,8.85029503,0.016880326
815,8.850384437,0.017052166
820,8.864206755,0.017258428
825,8.863992178,0.017397009
830,8.877957547,0.017601572
835,8.878046954,0.01774972
840,8.878172124,0.017942481
845,8.891064609,0.018131666
850,8.891386474,0.018284642
855,8.905137267,0.018490278
860,8.905065741,0.018627964
865,8.91838738,0.018831544
870,8.91851255,0.019006961
875,8.923233238,0.019171827
880,8.932084528,0.019378536
885,8.932120291,0.019515954
890,8.945799558,0.019718908
895,8.945728032,0.019900404
900,8.956152885,0.020060622
905,8.959657638,0.020264917
910,8.95942518,0.02040305
915,8.973551482,0.020605557
920,8.973068684,0.02078911
925,8.977038354,0.020949685
930,8.987266511,0.021153801
935,8.987212867,0.021299176
940,8.998424502,0.021494888
945,9.000784846,0.021696769
950,9.000570269,0.021836512
955,9.014410468,0.022041433
960,9.014374706,0.022196554
965,9.01430318,0.02238118
970,9.028125498,0.022584312
975,9.02789304,0.022723251
980,9.038335774,0.022927009
985,9.041983579,0.023099922
990,9.041608069,0.023267829
995,8.986050577,0.02335205
1000,9.055180048,0.023540699
1005,9.055036997,0.023678475
1010,9.060043787,0.02388268
1015,9.069109654,0.024055772
1020,9.069109654,0.024224662
1025,9.072453475,0.024430387
1030,9.082627988,0.024568253
1035,9.08239553,0.024770223
1040,9.082484937,0.024974608
1045,9.095949627,0.025113636
1050,9.096271492,0.025317662
1055,9.096182085,0.025504076
1060,9.109879234,0.025658571
1065,9.109914996,0.025861882
1070,9.109771945,0.026013427
1075,9.123773077,0.026204758
1080,9.12303994,0.026413792
1085,9.12316511,0.026555144
1090,9.136826495,0.026754522
1095,9.137291411,0.026944601
1100,9.136737088,0.027092301
1105,9.138614634,0.027300083
1110,9.150541525,0.027454847
1115,9.150309066,0.027641439
1120,9.150756101,0.027846717
1125,9.164417487,0.027982884
1130,9.164703589,0.028189235
1135,9.16432808,0.02838003
1140,9.169048768,0.028530681
1145,9.178364974,0.028734171
1150,9.178168279,0.028914415
1155,9.17791794,0.029073828
1160,9.191597206,0.029276514
1165,9.191793902,0.02944737
1170,9.19190119,0.029622429
1175,9.198714001,0.029826456
1180,9.205651982,0.029970669
1185,9.205830796,0.030167901
1190,9.205437406,0.030372285
1195,9.219045147,0.030509346
1200,9.219277605,0.030711764
1205,9.219134554,0.030908906
1210,9.219188198,0.03105455
1215,9.233242974,0.031258845
1220,9.232813821,0.03144204
1225,9.233278737,0.031600201
1230,9.233171449,0.031803423
1235,9.246475206,0.031977141
1240,9.246421562,0.03214764
1245,9.246403681,0.032349878
1250,9.246403681,0.032511526
1255,9.259975659,0.032693559
1260,9.259939896,0.032897496
1265,9.260565745,0.033044034
1270,9.260512101,0.03323912
1275,9.273923147,0.033442789
1280,9.27383374,0.033583784
1285,9.274173486,0.033785307
1290,9.273422468,0.033986383
1295,9.010208341,0.034058803
1300,9.260279643,0.034196222
1305,9.287566651,0.034331584
1310,9.287566651,0.03453722
1315,9.299368371,0.034698689
1320,9.30115651,0.034878754
1325,9.301549901,0.035087162
1330,9.300602187,0.035237545
1335,9.300852527,0.035429144
1340,9.314424505,0.035633081
1345,9.314603319,0.035773003
1350,9.314853659,0.035975778
1355,9.314424505,0.036176228
1360,9.315103998,0.036352718
1365,9.32858657,0.036522144
1370,9.328354112,0.036725366
1375,9.3284614,0.036888444
1380,9.328318349,0.037066901
1385,9.341979734,0.037271732
1390,9.342104904,0.0374484
1395,9.342158548,0.037613982
1400,9.341979734,0.037817651
1405,9.344554655,0.037994766
1410,9.355712645,0.038160259
1415,9.35590934,0.038366789
1420,9.355426543,0.038542831
1425,9.355855696,0.03870734
1430,9.361130708,0.038912261
1435,9.369552844,0.039100105
1440,9.369445556,0.039253169
1445,9.369284624,0.039455766
1450,9.369463437,0.039652461
1455,9.378332609,0.039797658
1460,9.383249993,0.040001953
1465,9.383178467,0.040195698
1470,9.383178467,0.040345097
1475,9.383142704,0.040549123
1480,9.393782134,0.040744478
1485,9.39667892,0.040892446
1490,9.39667892,0.04109397
1495,9.397125955,0.041298443
1500,9.396535869,0.041439617
1505,9.409732338,0.041641856
1510,9.410590645,0.041845256
1515,9.410572763,0.042000467
1520,9.410572763,0.042185986
1525,9.410608526,0.042390818
1530,9.415347096,0.042552555
1535,9.424144742,0.042732799
1540,9.424055335,0.042939419
1545,9.42385864,0.043105895
1550,9.424180505,0.043280149
1555,9.423912284,0.043483013
1560,9.43771672,0.043661827
1565,9.437609432,0.043828303
1570,9.437752483,0.044032777
1575,9.43784189,0.044228131
1580,9.437573669,0.044375653
1585,9.450627087,0.044579411
1590,9.451127766,0.044783617
1595,9.451270817,0.044922823
1600,9.450984715,0.045125777
1605,9.451342343,0.045330161
1610,9.453380822,0.04547509
1615,9.465146779,0.045669908
1620,9.465093135,0.045875812
1625,9.464950084,0.046037102
1630,9.465307712,0.046218509
1635,9.464985847,0.046424056
1640,9.470457554,0.046604211
1645,9.478790283,0.046763623
1650,9.478754521,0.046970243
1655,9.478700876,0.04717266
1660,9.478808165,0.047314191
1665,9.478826046,0.047517414
1670,9.486962081,0.047720546
1675,9.492648364,0.047879869
1680,9.492290736,0.048061634
1685,9.492576839,0.048266644
1690,9.492916585,0.048454399
1695,9.492451669,0.048608715
1700,9.504342796,0.048812026
1705,9.506023647,0.049016858
1710,9.50618458,0.049165989
1715,9.505862715,0.04935884
1720,9.506113054,0.049561704
1725,9.505826952,0.049742753
1730,9.515196803,0.049903417
1735,9.519756558,0.050107891
1740,9.519828084,0.050312186
1745,9.519327405,0.050455774
1750,9.519667151,0.050654883
1755,9.519595626,0.05085882
1760,9.520489695,0.051013852
1765,9.533221248,0.051200802
1770,9.533149723,0.051406706
1775,9.53323913,0.051594819
1780,9.533471588,0.051748151
1785,9.533400062,0.051953698
1790,9.533078197,0.052155221
1795,9.545720343,0.052297378
1800,9.547150855,0.052499706
1805,9.547204499,0.052705074
1810,9.546685938,0.052863682
1815,9.546989922,0.053047771
1820,9.546775345,0.053253139
1825,9.551156287,0.053446258
1830,9.560454612,0.053594674
1835,9.560526138,0.053798611
1840,9.560347324,0.054002816
1845,9.560651307,0.054173405
1850,9.56068707,0.054345603
1855,9.560436731,0.054549719
1860,9.565139537,0.054746593
1865,9.574723965,0.054893221
1870,9.574115998,0.05509537
1875,9.574169642,0.05530181
1880,9.574455744,0.055460061
1885,9.574384218,0.05564263
1890,9.574169642,0.055848266
1895,9.576118714,0.056029494
1900,9.587562806,0.05618989
1905,9.587848908,0.056394095
1910,9.588206536,0.05659848
1915,9.587491281,0.056803579
1920,9.587974078,0.056963797
1925,9.587580688,0.057143773
1930,9.595287569,0.057350214
1935,9.601903685,0.057539578
1940,9.601653345,0.057689334
1945,9.601546057,0.057896669
1950,9.601242073,0.058097924
1955,9.601438768,0.058244999
1960,9.601528175,0.05844232
1965,9.602136143,0.058646436
1970,9.609843024,0.058818991
1975,9.614867696,0.058986719
1980,9.580857283,0.059055562
1985,9.615404137,0.059260394
1990,9.615207442,0.059401835
1995,9.615386256,0.059600498
2000,9.615296849,0.059805329
2005,9.619391688,0.059967871
2010,9.629011879,0.060148652
2015,9.628815183,0.060353126
2020,9.629047641,0.060553576
2025,9.628618488,0.060695375
2030,9.628743658,0.060900117
2035,9.628725776,0.061105396
2040,9.628707895,0.061275805
2045,9.63056756,0.061447556
2050,9.641958008,0.061654533
2055,9.642512331,0.061855073
2060,9.642261992,0.062002595
2065,9.64274479,0.062198754
2070,9.642458687,0.062404211
2075,9.642798434,0.062601264
2080,9.642226229,0.06274816
2085,9.642941485,0.062950666
2090,9.650845061,0.063154425
2095,9.655887615,0.063325192
2100,9.65608431,0.063497479
2105,9.656155835,0.063702758
2110,9.656263124,0.063908483
2115,9.65620948,0.064062084
2120,9.655673038,0.064247336
2125,9.656799566,0.064452256
2130,9.669692051,0.064654942
2135,9.669799339,0.06479701
2140,9.669709932,0.064998533
2145,9.669692051,0.06520399
2150,9.669709932,0.065382536
2155,9.669405949,0.065547134
2160,9.669924509,0.065749015
2165,9.670049679,0.06595331
2170,9.675253165,0.066111918
2175,9.683156741,0.066296365
2180,9.683496488,0.066499408
2185,9.683514369,0.066702093
2190,9.683424962,0.066851582
2195,9.683389199,0.067046579
2200,9.683746827,0.067248907
2205,9.68313886,0.067443814
2210,9.684766067,0.067592766
2215,9.696836008,0.067799117
2220,9.697032703,0.068004038
2225,9.69712211,0.068175431
2230,9.696979059,0.068344231
2235,9.69724728,0.068547632
2240,9.697175754,0.068754162
2245,9.697265161,0.068912055
2250,9.697104229,0.069096144
2255,9.699232115,0.069298204
2260,9.709871545,0.069502677
2265,9.710676207,0.069657262
2270,9.710801377,0.069847073
2275,9.710568919,0.070054676
2280,9.710568919,0.070252444
2285,9.710318579,0.070402916
2290,9.710890784,0.070602651
2295,9.7105868,0.070808466
2300,9.710658326,0.07099184
2305,9.720904365,0.071148839
2310,9.724283948,0.071355995
2315,9.72405149,0.0715602
2320,9.724319711,0.071722116
2325,9.724677339,0.071898963
2330,9.724552169,0.072105225
2335,9.724605814,0.072312113
2340,9.724498525,0.072471347
2345,9.724462762,0.072652753
2350,9.732920662,0.072855797
2355,9.738070504,0.073055353
2360,9.738016859,0.073206004
2365,9.737963215,0.073403682
2370,9.738034741,0.073608961
2375,9.737605587,0.073790636
2380,9.737855927,0.073947635
2385,9.737945334,0.074152466
2390,9.737748639,0.074358281
2395,9.737981097,0.074536111
2400,9.743470685,0.074699994
2405,9.751177566,0.074903663
2410,9.751302736,0.075107064
2415,9.751123922,0.075265046
2420,9.751821296,0.075449046
2425,9.75123121,0.075654145
2430,9.751570957,0.075858619
2435,9.751410024,0.076009359
2440,9.751517312,0.076200064
2445,9.755129354,0.076406416
2450,9.763980644,0.07660785
2455,9.764660137,0.076752689
2460,9.765375393,0.076950278
2465,9.76533963,0.077155735
2470,9.765071409,0.077349212
2475,9.765107172,0.077500936
2480,9.765107172,0.077701118
2485,9.764910477,0.077905502
2490,9.765142935,0.078094777
2495,9.765321749,0.078250256
2500,9.766019123,0.078454014
2505,9.77572872,0.078660276
2510,9.779001016,0.078853484
2515,9.778482455,0.079005119
2520,9.778947371,0.079208877
2525,9.778965253,0.07941344
2530,9.77892949,0.07958832
2535,9.778518218,0.079754796
2540,9.778679151,0.079958465
2545,9.779269237,0.080164548
2550,9.780914325,0.080325481
2555,9.784597892,0.08050358
2560,9.792340536,0.080709573
2565,9.79251935,0.080915478
2570,9.792680282,0.081089732
2575,9.792054434,0.08125737
2580,9.792286892,0.081461844
2585,9.79264452,0.081665155
2590,9.792412062,0.081835922
2595,9.792197485,0.082006243
2600,9.792537231,0.082211879
2605,9.79226901,0.082415279
2610,9.799886484,0.08259606
2615,9.806234379,0.082756904
2620,9.806019803,0.082963702
2625,9.806001921,0.083166209
2630,9.806198617,0.083351728
2635,9.806019803,0.083510873
2640,9.806288024,0.083712217
2645,9.806162854,0.083918032
2650,9.806216498,0.084103551
2655,9.805912514,0.084258494
2660,9.806431075,0.084463057
2665,9.806377431,0.084668156
2670,9.812832614,0.084852067
2675,9.819627544,0.085010674
2680,9.819395086,0.085214701
2685,9.820253393,0.085419711
2690,9.819716951,0.085596558
2695,9.819430849,0.085762855
2700,9.819931528,0.085964826
2705,9.819752714,0.08616921
2710,9.81969907,0.086349723
2715,9.819627544,0.086513695
2720,9.8195739,0.086717632
2725,9.820360681,0.086921659
2730,9.829229853,0.087112543
2735,9.833646557,0.087264982
2740,9.833181641,0.087470529
2745,9.833342574,0.087676075
2750,9.833217404,0.087868211
2755,9.83368232,0.088020113
2760,9.833378336,0.088221815
2765,9.833575032,0.088426557
2770,9.833020708,0.088624683
2775,9.833485625,0.088779357
2780,9.833431981,0.088972297
2785,9.833288929,0.089178917
2790,9.833199522,0.089378205
2795,9.839672587,0.089531717
2800,9.845501922,0.089724925
2805,9.847164891,0.089928773
2810,9.846986078,0.0901328
2815,9.847200654,0.090290603
2820,9.846682094,0.090474424
2825,9.847164891,0.090680149
2830,9.846843026,0.090884981
2835,9.846878789,0.091058073
2840,9.847254298,0.091226784
2845,9.847468875,0.091430095
2850,9.847218536,0.091635195
2855,9.849721931,0.091812578
2860,9.855587028,0.091977176
2865,9.860701107,0.092180577
2870,9.860683226,0.092386034
2875,9.860915684,0.092578438
2880,9.861005091,0.092733291
2885,9.861040854,0.092931953
2890,9.860772633,0.093138484
2895,9.861005091,0.093338845
2900,9.860647463,0.093493161
2905,9.860844158,0.093683866
2910,9.860665344,0.093887356
2915,9.860665344,0.09409335
2920,9.860629582,0.09426367
2925,9.863776707,0.094434438
2930,9.870911383,0.094637302
2935,9.873414779,0.094841686
2940,9.874469781,0.095035431
2945,9.874380374,0.095190105
2950,9.874559188,0.095389662
2955,9.874308848,0.095595655
2960,9.874058509,0.095800755
2965,9.873986983,0.095966068
2970,9.874451899,0.096141396
2975,9.874666476,0.096349535
2980,9.874523425,0.096554277
2985,9.874773765,0.096733001
2990,9.874290967,0.096895901
2995,9.874577069,0.097101716
3000,9.874934697,0.097305117
3005,9.879798436,0.09750664
3010,9.887719894,0.097670434
3015,9.888095403,0.097851572
3020,9.888381506,0.098056135
3025,9.887988115,0.098258553
3030,9.888149048,0.098443714
3035,9.888041759,0.098602948
3040,9.888041759,0.09880778
3045,9.888166929,0.099012075
3050,9.888023878,0.099198578
3055,9.888041759,0.099352894
3060,9.888041759,0.099559603
3065,9.888524557,0.099762557
3070,9.888149048,0.099957553
3075,9.89086702,0.100108919
3080,9.894175078,0.100308923
3085,9.90113094,0.100515095
3090,9.901399161,0.100718585
3095,9.901506449,0.100876568
3100,9.901649501,0.101058421
3105,9.901881959,0.101263342
3110,9.901434924,0.101468174
3115,9.901828314,0.1016511
3120,9.901721026,0.101812212
3125,9.901059415,0.102014808
3130,9.901452805,0.102219639
3135,9.901631619,0.102423129
3140,9.901846196,0.102574406
3145,9.901953484,0.10276529
3150,9.901667382,0.102970479
3155,9.905082728,0.103176294
3160,9.908766296,0.103360919
3165,9.913898256,0.103518812
3170,9.915382412,0.103720782
3175,9.915561225,0.103927849
3180,9.915418174,0.104127942
3185,9.915400293,0.104281811
3190,9.915310886,0.104473142
3195,9.915471818,0.10467851
3200,9.915221479,0.104882358
3205,9.915453937,0.10504937
3210,9.915596988,0.105228363
3215,9.915650632,0.105434088
3220,9.915704277,0.105636595
3225,9.915310886,0.105820594
3230,9.915507581,0.105980454
3235,9.915561225,0.106185375
3240,9.915543344,0.106389133
3245,9.918279197,0.106588958
3250,9.927273539,0.106744973
3255,9.929276255,0.10693532
3260,9.928918627,0.107140152
3265,9.928811339,0.107345609
3270,9.928847102,0.107516645
3275,9.929222611,0.107685981
3280,9.92947295,0.107890276
3285,9.929061678,0.108095823
3290,9.928990153,0.10829073
3295,9.929240492,0.108442275
3300,9.928900746,0.108643798
3305,9.929186848,0.108846752
3310,9.929025916,0.1090506
3315,9.929222611,0.109205811
3320,9.929347781,0.10939428
3325,9.929294136,0.109598486
3330,9.928793457,0.109802692
3335,9.928650406,0.10998383
3340,9.930438546,0.110144584
3345,9.936160592,0.110348432
3350,9.942615775,0.110555409
3355,9.942705182,0.110753266
3360,9.942383317,0.110918401
3365,9.942615775,0.111099808
3370,9.942365436,0.111303298
3375,9.942758826,0.111507951
3380,9.942580013,0.111696242
3385,9.942794589,0.111851363
3390,9.942454843,0.112054585
3395,9.942580013,0.1122604
3400,9.942508487,0.112463801
3405,9.942615775,0.112620799
3410,9.942901878,0.112806676
3415,9.942740945,0.113010882
3420,9.942705182,0.113215624
3425,9.942526368,0.113405435
3430,9.94254425,0.113562612
3435,9.942687301,0.113763957
3440,9.943223743,0.113968788
3445,9.945923833,0.114174961
3450,9.954560547,0.114346354
3455,9.956116228,0.114514707
3460,9.95640233,0.114721774
3465,9.95600894,0.114928125
3470,9.956384449,0.115124105
3475,9.956455975,0.11528924
3480,9.956259279,0.115471809
3485,9.956205635,0.115677355
3490,9.955830126,0.115881293
3495,9.956348686,0.116071372
3500,9.956277161,0.116227298
3505,9.956366568,0.116428821
3510,9.956098347,0.116632043
3515,9.956384449,0.1168375
3520,9.956169872,0.117020248
3525,9.956080465,0.117182164
3530,9.95588377,0.117385654
3535,9.956330805,0.117589771
3540,9.955794363,0.117792724
3545,9.956330805,0.117960452
3550,9.956455975,0.118134885
3555,9.958333521,0.118338822
3560,9.961176663,0.118544101
3565,9.969974309,0.118739276
3570,9.969938546,0.118896364
3575,9.969688207,0.119089304
3580,9.970296174,0.119294851
3585,9.969938546,0.119500308
3590,9.969813376,0.119677066
3595,9.969884902,0.119841843
3600,9.969920665,0.120046048
3605,9.970081597,0.120250969
3610,9.969884902,0.120457052
3615,9.970010072,0.120624422
3620,9.970063716,0.120797961
3625,9.969902783,0.121000915
3630,9.969920665,0.121206819
3635,9.969652444,0.121408789
3640,9.969884902,0.121572672
3645,9.970260411,0.121753453
3650,9.969723969,0.121958911
3655,9.969884902,0.122164725
3660,9.969563037,0.122364371
3665,9.97011736,0.12252441
3670,9.971637279,0.12271136
3675,9.971994906,0.122917085
3680,9.978771955,0.123121469
3685,9.983081371,0.123315214
3690,9.983295948,0.123471766
3695,9.983510525,0.123667478
3700,9.983564169,0.123872488
3705,9.983671457,0.124078571
3710,9.983492643,0.124266504
3715,9.983385355,0.124425112
3720,9.983528406,0.124621718
3725,9.98370722,0.124830215
3730,9.983778745,0.125035226
3735,9.983635694,0.12522459
3740,9.983474762,0.125382751
3745,9.983689338,0.12557882
3750,9.983796627,0.125786334
3755,9.983796627,0.125990003
3760,9.983438999,0.126185089
3765,9.983617813,0.126342892
3770,9.983546287,0.126535832
3775,9.983492643,0.126739591
3780,9.98358205,0.12694621
3785,9.983260185,0.127135664
3790,9.983653576,0.127293646
3795,9.983725101,0.127490252
3800,9.983564169,0.127693563
3805,9.984207899,0.127900987
3810,9.98447612,0.128090351
3815,9.988928587,0.128251999
3820,9.988499434,0.128446191
3825,9.990877659,0.128652185
3830,9.996706994,0.128857553
3835,9.997225554,0.129056483
3840,9.99704674,0.12922278
3845,9.996903689,0.129404544
3850,9.997368605,0.129605352
3855,9.997422249,0.12981233
3860,9.997601063,0.130016714
3865,9.997100384,0.130183726
3870,9.997279198,0.130359768
3875,9.997440131,0.130563169
3880,9.997493775,0.130768984
3885,9.997386487,0.130972653
3890,9.997368605,0.131144404
3895,9.997243436,0.131319552
3900,9.997261317,0.131521791
3905,9.997332842,0.131726622
3910,9.997243436,0.13193056
3915,9.997118266,0.132126629
3920,9.997225554,0.132287204
3925,9.997529538,0.132477015
3930,9.997279198,0.132683456
3935,9.997547419,0.132889002
3940,9.997654708,0.133088469
3945,9.997314961,0.133264243
3950,9.997404368,0.133432239
3955,9.997440131,0.133638859
3960,9.997797759,0.133843154
3965,10.00457481,0.1340487
3970,10.00686363,0.134220362
3975,10.01024321,0.134392112
3980,10.01115516,0.134595871
3985,10.0108333,0.134798556
3990,10.01102999,0.135004192
3995,10.01081541,0.135165036
4000,10.01124457,0.135343403
4005,10.01058296,0.135550201
4010,10.01097635,0.135755658
4015,10.01076177,0.135959774
4020,10.01086906,0.136130184
4025,10.01085118,0.136300951
4030,10.01128033,0.136503905
4035,10.01113728,0.136709273
4040,10.01119092,0.136915267
4045,10.01077965,0.137102038
4050,10.01079753,0.137264222
4055,10.0116022,0.13746056
4060,10.0111194,0.137667447
4065,10.01085118,0.137870669
4070,10.01129821,0.138067454
4075,10.01117304,0.138222396
4080,10.01102999,0.138417661
4085,10.01085118,0.138621777
4090,10.01108363,0.138829738
4095,10.01088694,0.139025807
4100,10.01095847,0.139179587
4105,10.01081541,0.139374316
4110,10.01085118,0.139579863
4115,10.01095847,0.139783442
4120,10.01074389,0.139984518
4125,10.01095847,0.140149564
4130,10.01101211,0.140331418
4135,10.01128033,0.140533745
4140,10.01094058,0.140739024
4145,10.01122669,0.140943229
4150,10.01213864,0.141107738
4155,10.01519636,0.141287446
4160,10.02276019,0.141492099
4165,10.02374366,0.141696483
4170,10.02458409,0.141899437
4175,10.02451256,0.142080128
4180,10.02456621,0.14224571
4185,10.02456621,0.142449737
4190,10.02470926,0.142650009
4195,10.02420858,0.142857522
4200,10.02470926,0.14305538
4205,10.02465561,0.14322418
4210,10.02438739,0.143402636
4215,10.02487019,0.143609882
4220,10.02456621,0.143812567
4225,10.02481655,0.144016415
4230,10.0247629,0.144201667
4235,10.0241907,0.14436251
4240,10.02485231,0.144561887
4245,10.02438739,0.144768775
4250,10.02449468,0.144972176
4255,10.02465561,0.145170212
4260,10.02460197,0.145328373
4265,10.02442316,0.145518452
4270,10.0247629,0.145723105
4275,10.02463773,0.145927042
4280,10.02453044,0.146132321
4285,10.02431587,0.14630282
4290,10.02436951,0.146475286
4295,10.02461985,0.146677435
4300,10.02479866,0.146883697
4305,10.02444104,0.147088618
4310,10.02461985,0.147282631
4315,10.02451256,0.147441328
4320,10.02456621,0.147635878
4325,10.02461985,0.147840441
4330,10.02463773,0.148043037
4335,10.02444104,0.148248852
4340,10.02470926,0.148426235
4345,10.02463773,0.148596019
4350,10.02472714,0.148798705
4355,10.02465561,0.149004699
4360,10.02774909,0.149209083
4365,10.02801732,0.149411143
4370,10.0275524,0.149591029
4375,10.03692225,0.149756969
4380,10.03449038,0.149961443
4385,10.03729776,0.150164396
4390,10.03797725,0.150368602
4395,10.03846005,0.150566996
4400,10.03815607,0.150731237
4405,10.03847793,0.150916309
4410,10.03810242,0.15112123
4415,10.03844217,0.15132472
4420,10.03829912,0.151527942
4425,10.03853158,0.151707292
4430,10.03810242,0.151882709
4435,10.03853158,0.152077795
4440,10.03828124,0.152280034
4445,10.03838852,0.152485401
4450,10.03840641,0.152685405
4455,10.03813818,0.152857156
4460,10.03822759,0.153031231
4465,10.03810242,0.153237225
4470,10.03835276,0.153442056
4475,10.03833488,0.153645367
4480,10.03817395,0.153849752
4485,10.03801301,0.154020161
4490,10.03826335,0.154193611
4495,10.03842429,0.15439585
4500,10.03851369,0.154602111
4505,10.03837064,0.154804618
4510,10.03833488,0.154979498
4515,10.03842429,0.155147941
4520,10.03824547,0.155351699
4525,10.03826335,0.155556531
4530,10.03838852,0.155762167
4535,10.03828124,0.155949743
4540,10.03869251,0.156109245
4545,10.03792361,0.156307996
4550,10.0387998,0.156514169
4555,10.03862098,0.156718374
4560,10.03815607,0.156921597
4565,10.03835276,0.157105507
4570,10.03847793,0.157272429
4575,10.03835276,0.157470377
4580,10.03858522,0.157676817
4585,10.03837064,0.157881827
4590,10.03840641,0.158082814
4595,10.03851369,0.158247591
4600,10.03851369,0.158429356
4605,10.03847793,0.158634098
4610,10.03847793,0.158835889
4615,10.03867463,0.159042151
4620,10.03847793,0.159232856
4625,10.03883556,0.159397454
4630,10.03838852,0.159588517
4635,10.03849581,0.159793796
4640,10.03835276,0.159999432
4645,10.03851369,0.160204352
4650,10.03815607,0.160386027
4655,10.03856734,0.160549463
4660,10.03854946,0.160749288
4665,10.03826335,0.160954209
4670,10.03890708,0.161160202
4675,10.03967598,0.161351623
4680,10.03949717,0.161514343
4685,10.0413926,0.161705853
4690,10.04550532,0.161910684
4695,10.04386023,0.162114085
4700,10.04593447,0.162319185
4705,10.05044058,0.162493528
4710,10.04815177,0.162662239
4715,10.04741863,0.162864567
4720,10.05052999,0.163069935
4725,10.0513883,0.163276018
4730,10.05147771,0.163475753
4735,10.05158499,0.163647236
4740,10.05192474,0.163824262
4745,10.05115584,0.1640265
4750,10.05067304,0.16423008
4755,10.05194262,0.164437683
4760,10.05208567,0.164627136
4765,10.05197838,0.164790751
4770,10.05203203,0.164981099
4775,10.05192474,0.165188165
4780,10.05206779,0.165391119
4785,10.05169228,0.165596934
4790,10.05174593,0.165773334
4795,10.05201415,0.165939363
4800,10.0518711,0.166145803
4805,10.05203203,0.166350098
4810,10.05199627,0.166555824
4815,10.05197838,0.166754218
4820,10.05221084,0.166920515
4825,9.929508713,0.16696495
4830,9.874434018,0.166964414
4835,9.847594045,0.167009028
4840,9.819466611,0.167031648
4845,9.805948277,0.167033257
4850,9.792465706,0.16703424
4855,9.779090423,0.167033167
4860,9.765214461,0.167032452
4865,9.751338498,0.167033972
4870,9.751410024,0.167030396
4875,9.737802283,0.167033078
4880,9.737855927,0.167033346
4885,9.724570051,0.167033525
4890,9.961123019,0.167169513
4895,10.03849581,0.167306932
4900,10.05219296,0.167511942
4905,10.05240754,0.167716326
4910,10.05213932,0.167888435
4915,10.05219296,0.168062063
4920,10.05197838,0.168262782
4925,10.05194262,0.168467613
4930,10.05199627,0.16867164
4935,10.05145982,0.168868871
4940,10.05201415,0.169029893
4945,10.0519605,0.169218363
4950,10.05197838,0.169423999
4955,10.05210355,0.169628205
4960,10.05201415,0.169832321
4965,10.05188898,0.170016321
4970,10.05212144,0.170176985
4975,10.05171016,0.170377167
4980,10.05188898,0.1705803
4985,10.05219296,0.170785668
4990,10.05181745,0.170988711
4995,10.05178169,0.171148749
5000,10.05197838,0.17133409
5005,10.05190686,0.171539189
5010,10.05231813,0.171742143
5015,10.05206779,0.17194921
5020,10.05219296,0.172130259
5025,10.05179957,0.172295125
5030,10.05226449,0.17249352
5035,10.05210355,0.172699245
5040,10.05171016,0.172905239
5045,10.05201415,0.173108282
5050,10.05192474,0.173273327
5055,10.05197838,0.173452588
5060,10.05203203,0.173655363
5065,10.05203203,0.173862519
5070,10.05206779,0.174065831
5075,10.05203203,0.174262168
5080,10.05217508,0.174417289
5085,10.05183533,0.174610587
5090,10.0518711,0.174817833
5095,10.05210355,0.175026598
5100,10.05179957,0.175227495
5105,10.05226449,0.175399872
5110,10.05172804,0.175574216
5115,10.05185321,0.175775113
5120,10.05204991,0.175982716
5125,10.0518711,0.176188352
5130,10.05179957,0.1763787
5135,10.05228237,0.176539364
5140,10.05213932,0.176733645
5145,10.05203203,0.176937672
5150,10.05212144,0.177142682
5155,10.05190686,0.177345636
5160,10.05206779,0.177520874
5165,10.05201415,0.177689585
5170,10.05183533,0.177891465
5175,10.05204991,0.178098621
5180,10.05172804,0.178303721
5185,10.05188898,0.178493443
5190,10.05194262,0.178656163
5195,10.05185321,0.178849819
5200,10.05206779,0.179051521
5205,10.05190686,0.179259035
5210,10.05201415,0.179460111
5215,10.05206779,0.179625424
5220,10.05178169,0.179801824
5225,10.05188898,0.180009159
5230,10.05204991,0.180214706
5235,10.05210355,0.180419537
5240,10.05188898,0.180588516
5245,10.05210355,0.18076125
5250,10.05204991,0.180961433
5255,10.05204991,0.181168589
5260,10.05194262,0.181374672
5265,10.05210355,0.181542399
5270,10.05237177,0.181715849
5275,10.05235389,0.181920412
5280,10.05213932,0.182126406
5285,10.05228237,0.182328286
5290,10.05204991,0.182504239
5295,10.05194262,0.182672414
5300,10.05213932,0.182876888
5305,10.05228237,0.183078232
5310,10.05208567,0.183286729
5315,10.05201415,0.18346456
5320,10.05230025,0.183629694
5325,10.05217508,0.183834883
5330,10.05190686,0.184039804
5335,10.05192474,0.184245083
5340,10.05201415,0.184427115
5345,10.05178169,0.184587154
5350,10.05249694,0.184792968
5355,10.0518711,0.184997174
5360,10.05169228,0.185200664
5365,10.05171016,0.185387525
5370,10.05222872,0.185544255
5375,10.0521572,0.185747299
5380,10.05194262,0.18595213
5385,10.05210355,0.186156514
5390,10.05219296,0.186345163
5395,10.05212144,0.186507347
5400,10.05171016,0.18670145
5405,10.05194262,0.186907801
5410,10.05160287,0.187112007
5415,10.05190686,0.187295738
5420,10.05188898,0.187456223
5425,10.05217508,0.187658373
5430,10.05192474,0.187864366
5435,10.05206779,0.188067141
5440,10.05199627,0.188235852
5445,10.05199627,0.188406977
5450,10.05197838,0.188613507
5455,10.05203203,0.188819233
5460,10.0521572,0.189018074
5465,10.05213932,0.189179096
5470,10.05219296,0.189363811
5475,10.05231813,0.189571414
5480,10.05197838,0.189775887
5485,10.05199627,0.18996248
5490,10.05174593,0.19011769
5495,10.0522466,0.1903227
5500,10.05213932,0.190525744
5505,10.05201415,0.190727893
5510,10.05206779,0.190907333
5515,10.05253271,0.191072914
5520,10.05192474,0.191276852
5525,10.05194262,0.191480878
5530,10.05197838,0.191686783
5535,10.05219296,0.191842082
5540,10.05226449,0.192026887
5545,10.05230025,0.192234311
5550,10.05230025,0.192440662
5555,10.05197838,0.192629847
5560,10.05228237,0.192784521
5565,10.05204991,0.192986045
5570,10.0521572,0.193191412
5575,10.05212144,0.19339687
5580,10.05233601,0.193549845
5585,10.05179957,0.193737421
5590,10.05185321,0.193941716
5595,10.05235389,0.194146011
5600,10.05230025,0.194313917
5605,10.05201415,0.194487724
5610,10.0518711,0.194693807
5615,10.05237177,0.194898639
5620,10.05210355,0.195070389
5625,10.0521572,0.195238474
5630,10.05188898,0.195442769
5635,10.05212144,0.195652339
5640,10.05183533,0.195828829
5645,10.05226449,0.195990745
5650,10.05212144,0.196194414
5655,10.05194262,0.19639853
5660,10.05179957,0.19658843
5665,10.05197838,0.196744446
5670,10.05192474,0.196945879
5675,10.05213932,0.197151694
5680,10.05210355,0.197336767
5685,10.0521572,0.197490457
5690,10.05192474,0.19769654
5695,10.05185321,0.197903071
5700,10.05222872,0.198080365
5705,10.0522466,0.198243532
5710,10.05194262,0.198445413
5715,10.05203203,0.198651943
5720,10.05190686,0.198820744
5725,10.05199627,0.198995445
5730,10.0521572,0.199199472
5735,10.05206779,0.199403588
5740,10.05178169,0.199566577
5745,10.05249694,0.199744765
5750,10.05192474,0.199950848
5755,10.05194262,0.200153355
5760,10.05204991,0.200300608
5765,10.05153135,0.200499002
5770,10.05201415,0.200699542
5775,10.05204991,0.200888995
5780,10.05204991,0.201044832
5785,10.05208567,0.201251809
5790,10.0519605,0.201455478
5795,10.05094126,0.20160434
5800,10.05154923,0.201796744
5805,10.05103067,0.202000234
5810,10.05052999,0.202189241
5815,10.04934982,0.202344183
5820,10.04525498,0.202548657
5825,10.0427337,0.202750627
5830,10.04207209,0.202896897
5835,10.03933624,0.203093235
5840,10.03922895,0.203296725
5845,10.03892497,0.203471605
5850,10.03840641,0.203637991
5855,10.03863886,0.203844343
5860,10.0390859,0.204040502
5865,10.0386031,0.204185162
5870,10.03865675,0.204391782
5875,10.03851369,0.204594735
5880,10.03869251,0.204740826
5885,10.0381203,0.204936717
5890,10.03808454,0.205142711
5895,10.03838852,0.20529962
5900,10.03840641,0.2054821
5905,10.03863886,0.205688987
5910,10.03813818,0.205868427
5915,10.03820971,0.206027571
5920,10.03820971,0.206233833
5925,10.0381203,0.20642588
5930,10.03865675,0.206574116
5935,10.03826335,0.206780557
5940,10.038317,0.206973408
5945,10.03838852,0.207119499
5950,10.03835276,0.207327012
5955,10.03822759,0.207516645
5960,10.03837064,0.207666044
5965,10.03837064,0.207873825
5970,10.03804878,0.208045934
5975,10.03838852,0.208212767
5980,10.03874615,0.208418135
5985,10.03822759,0.208573524
5990,10.03829912,0.208760564
5995,10.03869251,0.208964322
6000,10.03837064,0.209104334
6005,10.03838852,0.209305768
6010,10.03838852,0.209500407
6015,10.03872827,0.209647123
6020,10.03881768,0.209858213
6025,10.03829912,0.210011725
6030,10.03829912,0.210198139
6035,10.03838852,0.210402612
6040,10.0386031,0.210540657
6045,10.03817395,0.210746024
6050,10.03837064,0.210907762
6055,10.03858522,0.211087917
6060,10.03851369,0.211291854
6065,10.03829912,0.211428915
6070,10.03853158,0.211633478
6075,10.03833488,0.211778854
6080,10.03824547,0.211975549
6085,10.03846005,0.212162857
6090,10.038317,0.21231619
6095,10.03829912,0.212522273
6100,10.03835276,0.212657188
6105,10.03863886,0.212862645
6110,10.03856734,0.213005517
6115,10.03846005,0.213204627
6120,10.03808454,0.213375394
6125,10.03820971,0.213546251
6130,10.03822759,0.213736956
6135,10.03846005,0.213886355
6140,10.03590301,0.214087699
6145,10.03461555,0.214228605
6150,10.02944783,0.214432721
6155,10.02917961,0.214568441
6160,10.0288041,0.214772915
6165,10.02615765,0.214912568
6170,10.02771333,0.215114539
6175,10.02562121,0.215253388
6180,10.02517417,0.215456788
6185,10.02454832,0.215594028
6190,10.0249596,0.215798055
6195,10.02499536,0.215934848
6200,10.02474502,0.216129308
6205,10.02458409,0.216274415
6210,10.02497748,0.216450189
6215,10.02485231,0.216616486
6220,10.02454832,0.216767673
6225,10.02478078,0.216956143
6230,10.02465561,0.217095171
6235,10.02483443,0.217298572
6240,10.02485231,0.217435722
6245,10.02463773,0.217630183
6250,10.02478078,0.217777972
6255,10.02487019,0.217928981
6260,10.02501324,0.218118434
6265,10.02453044,0.218256031
6270,10.02469138,0.218458449
6275,10.02494172,0.218602573
6280,10.02490595,0.218743389
6285,10.0244768,0.218943213
6290,10.02481655,0.219078039
6295,10.02453044,0.219234769
6300,10.02499536,0.219418233
6305,10.02503112,0.219556188
6310,10.02474502,0.219709252
6315,10.02487019,0.21989647
6320,10.02479866,0.220034157
6325,10.02497748,0.220174258
6330,10.02501324,0.220374351
6335,10.02463773,0.220510518
6340,10.02467349,0.220649814
6345,10.02454832,0.220811998
6350,10.02284959,0.220991706
6355,10.01866535,0.221125101
6360,10.01460627,0.221264487
6365,10.0121744,0.221427565
6370,10.01283601,0.221601998
6375,10.01179889,0.221740847
6380,10.01101211,0.221878534
6385,10.0109227,0.222016399
6390,10.01090482,0.222176974
6395,10.01101211,0.222353195
6400,10.01108363,0.222491508
6405,10.01102999,0.222627138
6410,10.01088694,0.222765272
6415,10.01131609,0.222901886
6420,10.01095847,0.223039662
6425,10.01090482,0.223202025
6430,10.01131609,0.223367249
6435,10.01119092,0.223513787
6440,10.01108363,0.223651832
6445,10.01085118,0.223788356
6450,10.01102999,0.223925059
6455,10.0111194,0.224059706
6460,10.01108363,0.224197661
6465,10.01097635,0.224333917
6470,10.0111194,0.224470442
6475,10.01081541,0.224607145
6480,10.01099423,0.224743222
6485,10.01124457,0.224880105
6490,10.00877693,0.225017612
6495,10.0000687,0.225152796
6500,9.99999717,0.225285297
6505,9.997350724,0.225383913
6510,9.997404368,0.225498622
6515,9.997672589,0.225630587
6520,9.997601063,0.22576729
6525,9.997422249,0.225904708
6530,9.997422249,0.226041054
6535,9.997064622,0.226126974
6540,9.997100384,0.226245528
6545,9.997797759,0.226383125
6550,9.997440131,0.22651813
6555,9.997154029,0.226601815
6560,9.997493775,0.226724839
6565,9.997458012,0.226858681
6570,9.99717191,0.226945048
6575,9.997618945,0.227066999
6580,9.996957333,0.227204328
6585,9.995312245,0.227269506
6590,9.985835106,0.227408444
6595,9.983778745,0.227486944
6600,9.983993322,0.227614885
6605,9.983903915,0.227703487
6610,9.983671457,0.227817571
6615,9.98358205,0.227892315
6620,9.983868152,0.228024011
6625,9.983903915,0.228093212
6630,9.983868152,0.228225713
6635,9.983742983,0.228296077
6640,9.983367473,0.228367334
6645,9.977287799,0.228501176
6650,9.970385581,0.228572702
6655,9.970027953,0.228641277
6660,9.970296174,0.228712177
6665,9.970027953,0.228835558
6670,9.970010072,0.228913611
6675,9.970439225,0.228979504
6680,9.96999219,0.229049062
6685,9.970349818,0.229116386
6690,9.969294816,0.229183977
6695,9.956992417,0.229252553
6700,9.955937414,0.229320502
6705,9.956295042,0.229391491
6710,9.956259279,0.229459708
6715,9.956420212,0.229525423
6720,9.956813603,0.229595965
6725,9.955615549,0.229664272
6730,9.942973403,0.229703968
6735,9.942723064,0.229732132
6740,9.942794589,0.22980169
6745,9.942955522,0.229869461
6750,9.942848233,0.229906833
6755,9.931886939,0.229937231
6760,9.928918627,0.230004733
6765,9.929365662,0.230007773
6770,9.929186848,0.23007304
6775,9.929133204,0.230112111
6780,9.916061904,0.230141437
6785,9.915507581,0.230191236
6790,9.915346649,0.23021028
6795,9.915561225,0.230219042
6800,9.904635693,0.230277603
6805,9.902007128,0.230277335
6810,9.901792552,0.230342871
6815,9.902096535,0.230346536
6820,9.888149048,0.230346894
6825,9.888077522,0.230396336
6830,9.888113285,0.230413502
6835,9.874559188,0.230414396
6840,9.874934697,0.23041529
6845,9.87432673,0.23045445
6850,9.860879921,0.23048315
6855,9.861040854,0.230481183
6860,9.856731438,0.230481988
6865,9.847325824,0.230482077
6870,9.847254298,0.230484044
6875,9.833861134,0.23048771
6880,9.833503506,0.23053599
6885,9.824169418,0.230549937
6890,9.81969907,0.230550384
6895,9.819252035,0.230551189
6900,9.806377431,0.230552083
6905,9.80598404,0.230551546
6910,9.792340536,0.230549669
6915,9.792537231,0.230551904
6920,9.778840083,0.230551368
6925,9.778446692,0.230551099
6930,9.764999884,0.230551815
6935,9.764642256,0.230551368
6940,9.75174977,0.230550563
6945,9.737426773,0.230551457
6950,9.737855927,0.230551993
6955,9.724570051,0.23055101
6960,9.724695221,0.230551099
6965,9.710855021,0.23055244
6970,9.697032703,0.230549669
6975,9.69699694,0.230551725
6980,9.683156741,0.230549848
6985,9.67249943,0.230550831
6990,9.669817221,0.230550384
6995,9.656281005,0.230552619
7000,9.642279873,0.230551546
7005,9.642154704,0.230552172
7010,9.628761539,0.230549669
7015,9.614849814,0.230551904
7020,9.605372675,0.230551278
7025,9.601671226,0.230552083
7030,9.588313825,0.230551099
7035,9.574008709,0.230550921
7040,9.560669189,0.230548149
7045,9.558094268,0.230542606
7050,9.546828989,0.230530268
7055,9.533274892,0.230501121
7060,9.519434693,0.230485653
7065,9.506005766,0.230483329
7070,9.492523194,0.230483239
7075,9.478933335,0.230483418
7080,9.46489644,0.230484581
7085,9.455526589,0.230481362
7090,9.446746824,0.230483418
7095,9.437663076,0.230481898
7100,9.424019572,0.230484312
7105,9.410340305,0.230482703
7110,9.396589513,0.23048172
7115,9.383178467,0.23048467
7120,9.369052165,0.23048315
7125,9.352404587,0.230482345
7130,9.332216493,0.23048163
7135,9.314710608,0.230474031
7140,9.301192273,0.230441755
7145,9.287548769,0.230423963
7150,9.274048316,0.230412608
7155,9.260208117,0.230413234
7160,9.241075025,0.230414486
7165,9.218812689,0.230415022
7170,9.205276473,0.230413502
7175,9.191954834,0.23041377
7180,9.17035411,0.230414039
7185,9.150648813,0.230414843
7190,9.137255649,0.230414575
7195,9.119749763,0.230412072
7200,9.09611056,0.230393654
7205,9.082413412,0.230352616
7210,9.05559132,0.230346179
7215,9.041590188,0.230345732
7220,9.01596615,0.230346894
7225,9.000927897,0.230346
7230,8.973175973,0.230345463
7235,8.959532469,0.230344122
7240,8.932388512,0.23034439
7245,8.918494668,0.230344569
7250,8.891225542,0.23032642
7255,8.863902771,0.230279928
7260,8.847827397,0.230278766
7265,8.823008022,0.230278408
7270,8.795971353,0.230278587
7275,8.768398243,0.230277693
7280,8.740467505,0.230277246
7285,8.714879229,0.230277782
7290,8.692008925,0.230267679
7295,8.667725992,0.230217343
7300,8.638776014,0.230209654
7305,8.606142469,0.230209654
7310,8.576620287,0.230208671
7315,8.549172346,0.230208671
7320,8.521938982,0.230208939
7325,8.49447316,0.230197584
7330,8.453417479,0.230147159
7335,8.42586225,0.230141079
7340,8.389205391,0.230140632
7345,8.358145409,0.230140632
7350,8.316946676,0.23013947
7355,8.286083389,0.230116224
7360,8.24826424,0.23007304
7365,8.207691356,0.230073398
7370,8.166045588,0.230073219
7375,8.111990132,0.230071789
7380,8.057094251,0.230004376
7385,7.93154898,0.230005806
7390,-0.0037311,0.224220102
7395,-0.00398144,0.224198108
7396.5,-0.004035084,0.224197929