File: Coupon(GU)/testdata.csv
Time (sec),Instron Force (kN),Extensometer (mm/mm)
0,0.015189905,-1.50E-05
5.5,0.015071888,-1.93E-05
11,0.015143413,-2.07E-05
16.5,0.015150566,-2.55E-05
22,0.015186329,-3.04E-05
27.5,0.015121956,-3.50E-05
33,0.015086193,-4.11E-05
38.5,0.023136397,-5.70E-05
44,0.018673201,-2.48E-05
49.5,0.273815666,-0.000107213
55,1.015800555,6.78993E-05
60.5,0.996442157,0.000187874
66,1.00702079,0.000135616
71.5,0.983095484,7.23428E-05
77,0.982562618,6.63972E-05
82.5,0.982516127,5.89496E-05
88,0.982508974,5.25034E-05
93.5,0.982605534,5.12517E-05
99,0.982544737,4.74966E-05
104.5,1.411462171,0.000142939
110,1.917680873,0.000237317
115.5,2.402420443,0.0003265
121,2.874417733,0.000386832
126.5,3.336401441,0.000477142
132,3.790313488,0.000573022
137.5,4.234598192,0.000638048
143,4.668504534,0.000716842
148.5,5.086728894,0.000809593
154,5.48595606,0.000860725
159.5,5.858078608,0.00095529
165,6.189145475,0.001009238
170.5,6.452917502,0.001098735
176,6.616120989,0.001195053
181.5,6.711711348,0.001290996
187,6.734048786,0.001385874
192.5,6.646508631,0.001384873
198,6.614618952,0.001385812
203.5,6.594134026,0.001384936
209,6.579203062,0.001384184
214.5,6.567276172,0.001386375
220,6.557298354,0.001386938
225.5,6.548840454,0.001385561
231,6.54091542,0.001385999
236.5,6.534184863,0.001387001
242,6.527475764,0.001385624
247.5,6.521928955,0.001385749
253,6.516675402,0.001385499
258.5,6.512591291,0.001383934
264,6.508081604,0.001383872
269.5,6.503371644,0.001383684
275,6.499974179,0.001384435
280.5,6.496691155,0.001383872
286,6.492292332,0.00138093
291.5,6.489152359,0.001377676
297,6.486334252,0.001372356
302.5,6.483537601,0.001368851
308,6.48072307,0.001362342
313.5,6.478040861,0.001362968
319,6.47528355,0.001359463
324.5,6.472583459,0.001356585
330,6.469915555,0.001349074
335.5,6.467186854,0.001345444
341,6.46470134,0.001343629
346.5,6.462548421,0.001341877
352,6.46082823,0.001340938
357.5,6.458922074,0.001342127
363,6.456314966,0.001342503
368.5,6.453997538,0.00133662
374,6.794763273,0.001466984
379.5,6.865412662,0.001606799
385,6.911020947,0.001731969
390.5,6.948178485,0.001864211
396,6.976581292,0.002007217
401.5,6.98876925,0.002150286
407,6.965487675,0.002354563
412.5,6.983812528,0.002580807
418,7.000266987,0.002771441
423.5,7.017787177,0.002962137
429,7.029746254,0.003153459
434.5,7.036187132,0.003346346
440,7.035675724,0.003582416
445.5,7.028887947,0.003821302
451,7.032775362,0.004076211
456.5,7.038315018,0.004347766
462,7.035607775,0.004638285
467.5,7.029095371,0.004967231
473,7.040907821,0.00527421
478.5,7.061060152,0.005564855
484,7.071238242,0.005829401
489.5,7.070787631,0.006084747
495,7.08459922,0.006310053
500.5,7.111696685,0.006510575
506,7.136519637,0.006723927
511.5,7.156064001,0.006931208
517,7.174528329,0.007123594
522.5,7.192148655,0.007322864
528,7.210044355,0.007539032
533.5,7.227407189,0.007743309
539,7.24485943,0.007935445
544.5,7.260931227,0.008126516
550,7.278580164,0.008317901
555.5,7.295370793,0.008515606
561,7.313284374,0.008717756
566.5,7.330218055,0.008919905
572,7.347498634,0.009119989
577.5,7.365526656,0.009313564
583,7.382252913,0.009508641
588.5,7.3975272,0.009701715
594,7.415261967,0.009894226
599.5,7.432460292,0.010085173
605,7.449336752,0.010277246
610.5,7.466041551,0.010468067
616,7.483636843,0.010659702
621.5,7.500130641,0.010851086
627,7.515458573,0.011041845
632.5,7.532524576,0.011232979
638,7.54902195,0.0114233
643.5,7.565601579,0.01161675
649,7.581648343,0.011806632
654.5,7.598303074,0.011998142
660,7.613842005,0.012192218
665.5,7.628526207,0.012384541
671,7.644894835,0.012576739
676.5,7.661320684,0.012768249
682,7.676362513,0.012959133
687.5,7.692191123,0.013150705
693,7.707805157,0.013345908
698.5,7.722793342,0.013531722
704,7.736919644,0.013729553
709.5,7.752383474,0.013918309
715,7.768086914,0.014112635
720.5,7.783561473,0.014306022
726,7.798006064,0.014496593
731.5,7.811842687,0.014694487
737,7.826387413,0.014885809
742.5,7.84114314,0.015081511
748,7.855469713,0.015272082
753.5,7.869435082,0.015468161
759,7.884684335,0.015659733
764.5,7.89838506,0.015851431
770,7.9123397,0.016045319
775.5,7.924863829,0.016237892
781,7.939093842,0.016431342
786.5,7.953077093,0.016625042
792,7.966473834,0.016819118
797.5,7.980650203,0.017011254
803,7.993521231,0.017204578
808.5,8.005970258,0.017399655
814,8.016691942,0.017590915
819.5,8.030339022,0.017781736
825,8.043800136,0.017971932
830.5,8.056782028,0.018168761
836,8.069656633,0.018362086
841.5,8.082241558,0.018558164
847,8.093210005,0.018755932
852.5,8.105980897,0.01895126
858,8.11855867,0.019150468
863.5,8.131283071,0.019350426
869,8.143159893,0.01954156
874.5,8.155827073,0.019741144
880,8.167213945,0.019934093
885.5,8.178457765,0.020125352
891,8.189662247,0.02031755
896.5,8.202150613,0.020507996
902,8.213458807,0.020699005
907.5,8.226011546,0.020891203
913,8.237344774,0.021080961
918.5,8.248356137,0.021276413
924,8.258398328,0.021469863
929.5,8.269116436,0.02167752
935,8.280703579,0.021870406
940.5,8.291790044,0.022072618
946,8.30264405,0.022273453
951.5,8.313387192,0.022465589
957,8.323837079,0.022658663
962.5,8.333550253,0.022849985
968,8.34313468,0.023040994
973.5,8.354045907,0.023234006
979,8.365146677,0.023429458
984.5,8.374741833,0.023629793
990,8.384472888,0.023838513
995.5,8.393817705,0.024043541
1001,8.403012318,0.024234738
1006.5,8.413115305,0.024428876
1012,8.423490091,0.024622138
1017.5,8.433714672,0.024818342
1023,8.443284794,0.025018801
1028.5,8.453445003,0.025229963
1034,8.462171123,0.025431361
1039.5,8.470460938,0.025624248
1045,8.480481671,0.025816571
1050.5,8.489629793,0.026006704
1056,8.49977212,0.026200529
1061.5,8.508537579,0.02639861
1067,8.516999055,0.026606392
1072.5,8.526930381,0.026811671
1078,8.534297516,0.027011504
1083.5,8.54391413,0.027202826
1089,8.552418521,0.027393272
1094.5,8.561480812,0.027586659
1100,8.571204714,0.027781361
1105.5,8.579612546,0.027988642
1111,8.586747222,0.028199678
1116.5,8.594808155,0.028395631
1122,8.603859717,0.02858808
1127.5,8.612464244,0.028779214
1133,8.620621736,0.028971475
1138.5,8.629004534,0.029177942
1144,8.63703328,0.029390042
1149.5,8.644979772,0.029589438
1155,8.651510057,0.029781699
1160.5,8.660872755,0.029975086
1166,8.668354331,0.030166032
1171.5,8.676540433,0.030366679
1177,8.68342477,0.030581095
1182.5,8.691736042,0.030788877
1188,8.698913634,0.030979323
1193.5,8.705998242,0.03117077
1199,8.713579954,0.03136397
1204.5,8.721680225,0.03156712
1210,8.729852023,0.031778031
1215.5,8.736607613,0.031981995
1221,8.74374229,0.032174256
1226.5,8.749782625,0.032365828
1232,8.757407251,0.032563158
1237.5,8.765507523,0.032778263
1243,8.772742335,0.032986107
1248.5,8.779358451,0.033179181
1254,8.786671942,0.033370754
1259.5,8.79342038,0.033566394
1265,8.798967189,0.033797082
1270.5,8.806559629,0.033990845
1276,8.813397474,0.034182793
1281.5,8.820453472,0.034375304
1287,8.828106709,0.034588155
1292.5,8.833825179,0.034798628
1298,8.83935053,0.034993079
1303.5,8.845605442,0.035185215
1309,8.853011915,0.035379541
1314.5,8.859399149,0.035595709
1320,8.866419385,0.035805243
1325.5,8.872341703,0.035997942
1331,8.878085207,0.036189139
1336.5,8.885302137,0.03639642
1342,8.890205216,0.036611336
1347.5,8.89674623,0.036811107
1353,8.902418208,0.037001929
1358.5,8.909080816,0.037197006
1364,8.915825678,0.037410921
1369.5,8.921218706,0.03762202
1375,8.926697566,0.037816408
1380.5,8.932151391,0.038006291
1386,8.937952115,0.038204998
1391.5,8.944257095,0.038423669
1397,8.950515583,0.038627884
1402.5,8.956781224,0.038818893
1408,8.962260083,0.03901372
1413.5,8.966605262,0.039228323
1419,8.972767191,0.039438295
1424.5,8.978557186,0.039632058
1430,8.984064656,0.039824006
1435.5,8.989575701,0.040039924
1441,8.995083171,0.040251586
1446.5,9.000465471,0.040443972
1452,9.005593855,0.040636858
1457.5,9.00997122,0.040849334
1463,9.015750487,0.041064689
1468.5,9.022019704,0.041256637
1474,9.027809699,0.041448334
1479.5,9.032680591,0.041664127
1485,9.036703905,0.04187679
1490.5,9.041456779,0.04206999
1496,9.046835503,0.042261312
1501.5,9.052425227,0.042481673
1507,9.057635865,0.04269127
1512.5,9.063282809,0.042881903
1518,9.067710243,0.043093002
1523.5,9.07160481,0.043311423
1529,9.076572262,0.043505499
1534.5,9.081632696,0.043697134
1540,9.086535775,0.043911425
1545.5,9.091263616,0.044125152
1551,9.096291864,0.044318039
1556.5,9.100919569,0.044511739
1562,9.105107391,0.044724214
1567.5,9.109935368,0.044937817
1573,9.115081633,0.045129952
1578.5,9.119591321,0.045324591
1584,9.124970044,0.045545891
1589.5,9.129182901,0.045750794
1595,9.133599605,0.045942742
1600.5,9.137211647,0.046150399
1606,9.141939488,0.046369446
1611.5,9.146670905,0.046562332
1617,9.151187745,0.046758286
1622.5,9.156094399,0.046982214
1628,9.159931747,0.047185052
1633.5,9.164566604,0.047374622
1639,9.168554155,0.047590164
1644.5,9.172405808,0.047804893
1650,9.176851122,0.047995464
1655.5,9.180963843,0.048201994
1661,9.186321109,0.048426611
1666.5,9.190204948,0.048618058
1672,9.194070905,0.048812697
1677.5,9.197271675,0.049045513
1683,9.202099651,0.049244407
1688.5,9.205908388,0.049435354
1694,9.210396618,0.049655402
1699.5,9.214087338,0.049865875
1705,9.219176383,0.050058011
1710.5,9.22193727,0.05026379
1716,9.224912734,0.05048509
1721.5,9.230166288,0.050678164
1727,9.234093042,0.050874869
1732.5,9.238366696,0.051096482
1738,9.242186161,0.051300321
1743.5,9.246177289,0.051491205
1749,9.249363753,0.051710377
1754.5,9.252332065,0.051920099
1760,9.25689182,0.052110732
1765.5,9.260410879,0.052323208
1771,9.265017126,0.052541754
1776.5,9.268393133,0.052731449
1782,9.272266243,0.052942047
1787.5,9.275642251,0.053160156
1793,9.278184985,0.053353606
1798.5,9.282097434,0.053555755
1804,9.287333106,0.0537825
1809.5,9.290276384,0.053975574
1815,9.293294763,0.054178599
1820.5,9.297675705,0.054402278
1826,9.301087475,0.054597605
1831.5,9.303916311,0.054799629
1837,9.306999064,0.055025874
1842.5,9.311555243,0.055220763
1848,9.315088607,0.055417029
1853.5,9.318579055,0.055646403
1859,9.321826316,0.055840729
1864.5,9.324605085,0.056040625
1870,9.328102686,0.056267683
1875.5,9.33144293,0.056461821
1881,9.334987023,0.056663657
1886.5,9.339121201,0.056891404
1892,9.342132428,0.057084666
1897.5,9.34490762,0.05728137
1903,9.347571948,0.057506488
1908.5,9.350726226,0.05770507
1914,9.355357507,0.057898332
1919.5,9.358450988,0.05812395
1925,9.361530165,0.058326475
1930.5,9.365456919,0.058518798
1936,9.367431025,0.058741475
1941.5,9.36965547,0.058947067
1947,9.37457643,0.05913939
1952.5,9.377637725,0.059359438
1958,9.380366426,0.05956916
1963.5,9.383549314,0.059759669
1969,9.38706122,0.059980656
1974.5,9.388827901,0.06018994
1980,9.391263347,0.060381575
1985.5,9.396055561,0.060600872
1991,9.399474484,0.06081147
1996.5,9.402306897,0.061003919
2002,9.405053479,0.061226408
2007.5,9.407742841,0.061434753
2013,9.410421473,0.061627515
2018.5,9.413146598,0.061851881
2024,9.415925367,0.062057911
2029.5,9.419630392,0.062248357
2035,9.423703773,0.062475164
2040.5,9.425356014,0.062677626
2046,9.429189785,0.062874518
2051.5,9.430695398,0.063105519
2057,9.43304859,0.063299344
2062.5,9.436875208,0.063497926
2068,9.440104588,0.063724734
2073.5,9.44313012,0.063920186
2079,9.445844516,0.064123337
2084.5,9.448591098,0.064348142
2090,9.450518712,0.064541091
2095.5,9.45300065,0.064747559
2101,9.45669137,0.064970298
2106.5,9.459663258,0.065162621
2112,9.462449179,0.065368714
2117.5,9.465174303,0.065592454
2123,9.467588292,0.065782212
2128.5,9.469759093,0.065998881
2134,9.472934829,0.066213109
2139.5,9.475262986,0.066405244
2145,9.477895127,0.066622977
2150.5,9.481618034,0.066835953
2156,9.484078514,0.067027463
2161.5,9.486481773,0.067252644
2167,9.487962353,0.067457797
2172.5,9.490455019,0.067651497
2178,9.494045603,0.067881496
2183.5,9.496273625,0.068080642
2189,9.499395716,0.068276344
2194.5,9.501148093,0.068507032
2200,9.503587115,0.068700858
2205.5,9.506104815,0.068900128
2211,9.508883584,0.069129564
2216.5,9.511540759,0.069323077
2222,9.514305223,0.069527228
2227.5,9.517055381,0.069752534
2233,9.519812692,0.06994467
2238.5,9.520316948,0.070180427
2244,9.522770275,0.070374565
2249.5,9.525792231,0.070604565
2255,9.528227677,0.070803459
2260.5,9.530988564,0.071018501
2266,9.533463349,0.071234294
2271.5,9.536174168,0.071429371
2277,9.538541665,0.071661748
2282.5,9.539764752,0.071855449
2288,9.542922607,0.072080254
2293.5,9.545282951,0.072285094
2299,9.547747007,0.072484114
2304.5,9.550035825,0.07271524
2310,9.552653662,0.072906812
2315.5,9.554434648,0.073128488
2321,9.556512466,0.073337584
2326.5,9.558708302,0.073541798
2332,9.561969868,0.073769294
2337.5,9.563994042,0.07396143
2343,9.566586844,0.074183106
2348.5,9.56902229,0.074391513
2354,9.570152394,0.074587654
2359.5,9.572115771,0.074820157
2365,9.574887387,0.075012918
2370.5,9.577512376,0.075228836
2376,9.579904907,0.075442689
2381.5,9.582079284,0.075635513
2387,9.584296577,0.075871583
2392.5,9.58553397,0.076064845
2398,9.588048094,0.076273065
2403.5,9.590379828,0.076493864
2409,9.593255156,0.076685937
2414.5,9.595640534,0.076911118
2420,9.596527451,0.077113768
2425.5,9.598869914,0.077312975
2431,9.600582951,0.077544852
2436.5,9.603097075,0.077736612
2442,9.604634875,0.077950841
2447.5,9.607345695,0.078166007
2453,9.610027904,0.078358769
2458.5,9.612273807,0.078589269
2464,9.612949724,0.078787976
2469.5,9.615227813,0.078993067
2475,9.616983766,0.079217371
2480.5,9.619322653,0.079409068
2486,9.621876116,0.079633873
2491.5,9.623807307,0.079841217
2497,9.626224871,0.080039861
2502.5,9.626671906,0.080270549
2508,9.629153843,0.08046256
2513.5,9.631753798,0.080678853
2519,9.633745786,0.080893269
2524.5,9.635551806,0.081086343
2530,9.637719031,0.081320098
2535.5,9.639989969,0.081514549
2541,9.640465614,0.081725272
2546.5,9.642607805,0.081944945
2552,9.645443794,0.082138645
2557.5,9.648193952,0.082371211
2563,9.649814007,0.082567352
2568.5,9.651001331,0.082775384
2574,9.653712151,0.082994806
2579.5,9.654169914,0.083186754
2585,9.656376478,0.083416003
2590.5,9.658711789,0.083616525
2596,9.660657284,0.083818173
2601.5,9.662828086,0.084046358
2607,9.664591191,0.084239557
2612.5,9.66660106,0.084461984
2618,9.66730201,0.084667825
2623.5,9.669472812,0.084867283
2629,9.671246646,0.085096344
2634.5,9.673381685,0.085288918
2640,9.67548096,0.085507902
2645.5,9.677501558,0.085721817
2651,9.678227543,0.085916143
2656.5,9.68024814,0.086147332
2662,9.681485533,0.086343285
2667.5,9.683692097,0.086552381
2673,9.686338543,0.086773431
2678.5,9.688788294,0.086968759
2684,9.689210295,0.087198132
2689.5,9.691105723,0.087395275
2695,9.691917538,0.087606186
2700.5,9.694628358,0.087825295
2706,9.696384311,0.088018182
2711.5,9.697861314,0.088249746
2717,9.700128675,0.088446701
2722.5,9.702320933,0.088659176
2728,9.702649951,0.088876408
2733.5,9.703819394,0.089068669
2739,9.706204772,0.089301673
2744.5,9.708268285,0.089496937
2750,9.710120798,0.089711291
2755.5,9.711379648,0.089925894
2761,9.713732839,0.090121722
2766.5,9.713911653,0.090355226
2772,9.715946556,0.090548176
2777.5,9.717112423,0.09076691
2783,9.71925819,0.09097901
2788.5,9.721754433,0.091178656
2794,9.722190739,0.091408655
2799.5,9.724604727,0.091601542
2805,9.724744202,0.091835922
2810.5,9.727229716,0.09203175
2816,9.728774669,0.09225474
2821.5,9.730298163,0.092461646
2827,9.73248327,0.092671681
2832.5,9.733495357,0.092893231
2838,9.735515954,0.093090499
2843.5,9.735887887,0.093319622
2849,9.73810518,0.093514198
2854.5,9.740097167,0.093744761
2860,9.741212967,0.09394303
2865.5,9.743777158,0.094159824
2871,9.744184854,0.094374991
2876.5,9.745908621,0.094579017
2882,9.746484402,0.094803635
2887.5,9.749048594,0.095000464
2893,9.749663714,0.095232091
2898.5,9.75197399,0.095425666
2904,9.754205588,0.095658544
2909.5,9.754809979,0.095855374
2915,9.75535715,0.096079615
2920.5,9.757266882,0.096285645
2926,9.758325461,0.096500123
2931.5,9.760406855,0.096715665
2937,9.762817267,0.096918941
2942.5,9.763525371,0.097144998
2948,9.765195493,0.09733876
2953.5,9.765710477,0.097571952
2959,9.767541532,0.09776778
2964.5,9.769143705,0.097993899
2970,9.770964031,0.098197613
2975.5,9.772973899,0.098411716
2981,9.773928766,0.098628197
2986.5,9.774851446,0.098830346
2992,9.77613533,0.099058217
2997.5,9.776782636,0.099250103
3003,9.77926815,0.099483419
3008.5,9.780884628,0.099679059
3014,9.782039766,0.099906868
3019.5,9.783709889,0.100108705
3025,9.784818535,0.100327188
3030.5,9.784882908,0.100539664
3036,9.787393456,0.100744191
3041.5,9.787826186,0.100967995
3047,9.790329581,0.101167265
3052.5,9.792900925,0.101397077
3058,9.793076163,0.101591591
3063.5,9.793902284,0.101827911
3069,9.795404321,0.102022112
3074.5,9.796505815,0.102255303
3080,9.798444158,0.102451257
3085.5,9.799524194,0.102679191
3091,9.801215774,0.102881215
3096.5,9.802363759,0.103099949
3102,9.803844339,0.103311423
3107.5,9.803865797,0.1035152
3113,9.805775529,0.103740568
3118.5,9.807005769,0.103941528
3124,9.809101469,0.104172967
3129.5,9.809809572,0.10436698
3135,9.811980373,0.104600985
3140.5,9.812277205,0.104795937
3146,9.812534697,0.105029629
3151.5,9.814841397,0.105224205
3157,9.815531618,0.105447758
3162.5,9.817709572,0.105655665
3168,9.818803914,0.105870895
3173.5,9.820234425,0.106085123
3179,9.820391781,0.106286771
3184.5,9.821407445,0.106515456
3190,9.823156245,0.106710283
3195.5,9.825334199,0.106944538
3201,9.826031573,0.107138489
3206.5,9.826964982,0.107370303
3212,9.828624375,0.10756538
3217.5,9.829089292,0.107795943
3223,9.830659278,0.10799634
3228.5,9.831363805,0.108216701
3234,9.833452352,0.108458905
3239.5,9.835061677,0.108666749
3245,9.836088069,0.108904071
3250.5,9.836767562,0.10910403
3256,9.836849817,0.109333904
3261.5,9.839260229,0.109539245
3267,9.83968223,0.109765364
3272.5,9.841531166,0.109977151
3278,9.842321524,0.110197763
3283.5,9.844399342,0.110414807
3289,9.84481419,0.110626469
3294.5,9.845046648,0.110848896
3300,9.84702433,0.111057679
3305.5,9.847818264,0.111282421
3311,9.850003371,0.111486761
3316.5,9.850604185,0.1117182
3322,9.851812968,0.111917908
3327.5,9.852832207,0.112149598
3333,9.853225598,0.112347616
3338.5,9.855471501,0.112583749
3344,9.855936417,0.112778388
3349.5,9.85692347,0.113012142
3355,9.858650813,0.113210286
3360.5,9.85963429,0.113446732
3366,9.859602103,0.113641809
3371.5,9.860703597,0.113875751
3377,9.861729989,0.114073081
3382.5,9.864118943,0.114308839
3388,9.864344249,0.114507295
3393.5,9.866243253,0.114736481
3399,9.866858373,0.114939694
3404.5,9.867512832,0.115165187
3410,9.868628631,0.115372281
3415.5,9.869583498,0.115597899
3421,9.871257196,0.115810813
3426.5,9.872365843,0.116027482
3432,9.87361754,0.116248031
3437.5,9.874915729,0.116460069
3443,9.874550949,0.116688879
3448.5,9.875148188,0.116889839
3454,9.877680193,0.11712109
3459.5,9.877887617,0.117321049
3465,9.878906857,0.11755762
3470.5,9.880387436,0.117752321
3476,9.88059486,0.117987015
3481.5,9.881964575,0.118183343
3487,9.882754933,0.118417223
3492.5,9.883187663,0.118617495
3498,9.885633837,0.118849685
3503.5,9.88613094,0.119051771
3509,9.887700927,0.119279518
3514.5,9.888441216,0.119486298
3520,9.888645064,0.119708599
3525.5,9.889399659,0.119920136
3531,9.891087663,0.120139371
3536.5,9.891427409,0.120356165
3542,9.893669736,0.120569267
3547.5,9.894070279,0.120793195
3553,9.894170415,0.121000727
3558.5,9.894202602,0.121225469
3564,9.896777522,0.121428933
3569.5,9.897249591,0.121663626
3575,9.898851764,0.121863147
3580.5,9.899620664,0.122097402
3586,9.900207174,0.122297611
3591.5,9.90107621,0.122531553
3597,9.902141941,0.122737583
3602.5,9.902403009,0.122961136
3608,9.903947962,0.12318181
3613.5,9.905078066,0.123393347
3619,9.905714643,0.123619404
3624.5,9.906569374,0.123823618
3630,9.906108034,0.124057748
3635.5,9.907796038,0.12425658
3641,9.908922566,0.124489959
3646.5,9.91041745,0.124691983
3652,9.910621298,0.124921294
3657.5,9.912312878,0.125131079
3663,9.913210524,0.125350752
3668.5,9.913228405,0.125569298
3674,9.913267744,0.12578121
3679.5,9.915499342,0.126009145
3685,9.916014327,0.126211794
3690.5,9.916740311,0.126449054
3696,9.918306721,0.12664701
3701.5,9.918757332,0.126879951
3707,9.918710841,0.127084541
3712.5,9.91921152,0.127311911
3718,9.921396626,0.127523135
3723.5,9.921482457,0.127741369
3729,9.922737731,0.12796899
3734.5,9.924128903,0.128170513
3740,9.924139632,0.128407522
3745.5,9.924204005,0.128604915
3751,9.92520894,0.128842738
3756.5,9.926914825,0.129047953
3762,9.928066386,0.129272195
3767.5,9.929332389,0.129490241
3773,9.92954339,0.129703217
3778.5,9.929625644,0.129937097
3784,9.930315866,0.130136993
3789.5,9.931624784,0.130372813
3795,9.932068243,0.130574524
3800.5,9.932661905,0.130802145
3806,9.934847011,0.131022569
3811.5,9.9351653,0.131231853
3817,9.935172453,0.131466296
3822.5,9.935168876,0.131664878
3828,9.937264576,0.131900009
3833.5,9.937858238,0.132105162
3839,9.938097849,0.13233053
3844.5,9.940279379,0.132557025
3850,9.940583363,0.132761365
3855.5,9.940411701,0.132996747
3861,9.940633431,0.133196643
3866.5,9.941770687,0.133429709
3872,9.943122521,0.133642435
3877.5,9.943312063,0.133861044
3883,9.94472827,0.134091231
3888.5,9.94500722,0.134291064
3894,9.94531478,0.134528199
3899.5,9.94598712,0.134733352
3905,9.946616545,0.134962725
3910.5,9.948250905,0.135180834
3916,9.948733702,0.135392558
3921.5,9.949434653,0.13562938
3927,9.950925961,0.135831967
3932.5,9.950035468,0.136060026
3938,9.951136962,0.136281264
3943.5,9.951691285,0.136490735
3949,9.953726188,0.136727181
3954.5,9.954112426,0.136927703
3960,9.954262629,0.137161019
3965.5,9.954573766,0.137385574
3971,9.954956428,0.137590539
3976.5,9.955685988,0.137828049
3982,9.956944839,0.138031888
3987.5,9.957334653,0.138259008
3993,9.959265844,0.138486755
3998.5,9.959684268,0.138691094
4004,9.959569827,0.138927352
4009.5,9.959712878,0.139137074
4015,9.960478202,0.139357561
4020.5,9.96185507,0.13959313
4026,9.962484495,0.139791587
4031.5,9.962588207,0.140026969
4037,9.963285581,0.140251586
4042.5,9.963446514,0.140457928
4048,9.964619533,0.140696627
4053.5,9.965102331,0.14090372
4059,9.96535267,0.141129401
4064.5,9.967126505,0.14136034
4070,9.967959778,0.141560736
4075.5,9.96778454,0.141798622
4081,9.967956201,0.142012787
4086.5,9.968521253,0.142228142
4092,9.969890968,0.142467028
4097.5,9.970516817,0.142669615
4103,9.970777885,0.142897737
4108.5,9.972501652,0.143131617
4114,9.973091738,0.143334517
4119.5,9.97181143,0.143565518
4125,9.973342077,0.143794579
4130.5,9.973599569,0.143998856
4136,9.975466387,0.144236929
4141.5,9.975859778,0.144457853
4147,9.97611727,0.144667763
4152.5,9.976224558,0.144904271
4158,9.976081507,0.145120189
4163.5,9.977168696,0.145334041
4169,9.978588478,0.14557224
4174.5,9.97878875,0.145785591
4180,9.979811566,0.146005202
4185.5,9.98078789,0.146241647
4191,9.980176346,0.146449617
4196.5,9.979761498,0.146672982
4202,9.981295722,0.146913997
4207.5,9.981875079,0.147121028
4213,9.982425826,0.147346208
4218.5,9.982708352,0.147581715
4224,9.984131711,0.147783363
4229.5,9.984242575,0.148014927
4235,9.984210389,0.148245991
4240.5,9.984285491,0.148448015
4246,9.985701697,0.148684586
4251.5,9.98702492,0.148913709
4257,9.987074988,0.149116859
4262.5,9.987164395,0.14935343
4268,9.987232345,0.149576921
4273.5,9.987339633,0.149784327
4279,9.98878445,0.150021274
4284.5,9.98963918,0.150248832
4290,9.989803689,0.150454549
4295.5,9.990329402,0.150690744
4301,9.991652625,0.15092187
4306.5,9.99089803,0.151123894
4312,9.991570371,0.151359964
4317.5,9.992489475,0.151592342
4323,9.992614644,0.151796118
4328.5,9.994424241,0.152027933
4334,9.994878429,0.152264879
4339.5,9.994967836,0.152468217
4345,9.994599479,0.152698154
4350.5,9.99505009,0.15293485
4356,9.995228904,0.153147138
4361.5,9.996137279,0.153369252
4367,9.997839588,0.15360914
4372.5,9.99791469,0.153825558
4378,9.997886079,0.154039348
4383.5,9.997775215,0.154277296
4389,9.998354572,0.154501224
4394.5,9.999345201,0.154710321
4400,10.000461,0.154947142
4405.5,10.00050034,0.15517833
4411,10.00071134,0.155383984
4416.5,10.00067558,0.155615924
4422,10.00065412,0.15585312
4427.5,10.00164832,0.15606109
4433,10.00287141,0.156283141
4438.5,10.00342574,0.156522153
4444,10.00339355,0.156741137
4449.5,10.00355091,0.156956054
4455,10.00356521,0.15719106
4460.5,10.00375118,0.157426504
4466,10.00546421,0.157638229
4471.5,10.00607933,0.157861594
4477,10.00606503,0.158100231
4482.5,10.00619378,0.158323471
4488,10.00746693,0.158534945
4493.5,10.00707354,0.158768136
4499,10.0066122,0.159008838
4504.5,10.0083002,0.159224255
4510,10.00874724,0.15943986
4515.5,10.00905837,0.159679623
4521,10.00918712,0.159914003
4526.5,10.0091299,0.160128169
4532,10.00978794,0.160348405
4537.5,10.01036014,0.160587667
4543,10.01126494,0.160819919
4548.5,10.01130428,0.161028577
4554,10.01177277,0.161256073
4559.5,10.01194801,0.161496587
4565,10.01218762,0.16172765
4570.5,10.01160111,0.161933742
4576,10.01280274,0.162165244
4581.5,10.01372184,0.162402566
4587,10.01424756,0.162628747
4592.5,10.01446213,0.162842788
4598,10.01434411,0.163072474
4603.5,10.01444425,0.163310547
4609,10.01454796,0.163536854
4614.5,10.01586761,0.163748829
4620,10.01660432,0.163980331
4625.5,10.01686539,0.164217778
4631,10.0171658,0.164445837
4636.5,10.0171658,0.16466019
4642,10.01710143,0.164888875
4647.5,10.0171801,0.165127136
4653,10.01847114,0.165363018
4658.5,10.01959409,0.165574868
4664,10.01969065,0.165798046
4669.5,10.01976575,0.166036932
4675,10.02045955,0.166275318
4680.5,10.01992311,0.166493864
4686,9.904731167,0.1666119
4691.5,9.843165525,0.166610961
4697,9.807166702,0.166611211
4702.5,9.781943207,0.166615342
4708,9.762813691,0.16663612
4713.5,9.746584537,0.166654395
4719,9.733212831,0.166659026
4724.5,9.721933247,0.166660465
4730,9.711776615,0.166659714
4735.5,9.702907443,0.166659339
4741,9.694860816,0.1666584
4746.5,9.688187479,0.166659151
4752,9.680970548,0.166657712
4757.5,9.675359367,0.166660153
4763,9.66983044,0.166659777
4768.5,9.664523242,0.166658963
4774,9.65906584,0.166658963
4779.5,9.653858778,0.166657774
4785,9.650461313,0.166658713
4790.5,9.645368692,0.166659026
4796,9.642307397,0.166659089
4801.5,9.637390014,0.166659402
4807,9.634436007,0.16665815
4812.5,9.631632205,0.166658525
4818,9.627598162,0.166659652
4823.5,9.624050493,0.166659714
4829,9.620999928,0.166659214
4834.5,9.618249769,0.16665984
4840,9.615345831,0.16666009
4845.5,9.612760181,0.166660027
4851,9.610113735,0.16666178
4856.5,9.607517356,0.166662406
4862,9.605257148,0.16666591
4867.5,9.885955702,0.166802345
4873,9.998383182,0.166993104
4878.5,10.02239074,0.167201199
4884,10.02801265,0.167424251
4889.5,10.02885665,0.16766295
4895,10.02813782,0.167896955
4900.5,10.02827014,0.168113686
4906,10.02861347,0.168333109
4911.5,10.0292572,0.168569555
4917,10.02802696,0.168808817
4922.5,10.02790894,0.16904545
4928,10.02791252,0.169265749
4933.5,10.02740469,0.169486486
4939,10.02773728,0.169717799
4944.5,10.0277194,0.169957562
4950,10.02804484,0.170192756
4955.5,10.02789464,0.170420377
4961,10.02783742,0.170637735
4966.5,10.02696123,0.170864793
4972,10.0278088,0.17110418
4977.5,10.02787675,0.171345257
4983,10.02802338,0.171579449
4988.5,10.02823796,0.171799623
4994,10.02829518,0.172023114
4999.5,10.02810206,0.17225305
5005,10.02787318,0.172491874
5010.5,10.02810921,0.172729446
5016,10.02802696,0.172963264
5021.5,10.02979364,0.173187568
5027,10.03055896,0.173407804
5032.5,10.03053751,0.173638492
5038,10.03002252,0.173878693
5043.5,10.02951827,0.174117704
5049,10.03062691,0.174353649
5054.5,10.03056969,0.174577515
5060,10.03079857,0.174801632
5065.5,10.03107395,0.175028627
5071,10.03176417,0.17526257
5076.5,10.03102388,0.175503459
5082,10.03084149,0.175741719
5087.5,10.03201809,0.175975474
5093,10.03295865,0.176202657
5098.5,10.033116,0.176422768
5104,10.03331627,0.176650514
5109.5,10.03311958,0.176888024
5115,10.03309812,0.177126535
5120.5,10.03324117,0.17736586
5126,10.03340211,0.177595484
5131.5,10.03345933,0.177816971
5137,10.03457155,0.178038021
5142.5,10.03510799,0.178276657
5148,10.03474679,0.178573435
5153.5,10.03392424,0.178809255
5159,10.03446784,0.179042822
5164.5,10.03586259,0.179281395
5170,10.03601994,0.179517841
5175.5,10.0360414,0.179757416
5181,10.03614153,0.179996114
5186.5,10.03603067,0.180236002
5192,10.03619876,0.180474013
5197.5,10.03603425,0.18070589
5203,10.03613796,0.18093445
5208.5,10.03722515,0.181164762
5214,10.03843393,0.181390818
5219.5,10.03804412,0.1816257
5225,10.0381371,0.181860894
5230.5,10.03794398,0.182099342
5236,10.03831949,0.182337102
5241.5,10.03880586,0.182577553
5247,10.0388452,0.182815563
5252.5,10.03899541,0.183052885
5258,10.03909196,0.183289393
5263.5,10.03905263,0.183517578
5269,10.03885235,0.183749893
5274.5,10.03887739,0.183981833
5280,10.03972497,0.18421008
5285.5,10.04061546,0.184445899
5291,10.0412878,0.184682032
5296.5,10.04013981,0.184920794
5302,10.04090156,0.185159993
5307.5,10.04037585,0.18539938
5313,10.04134502,0.185636639
5318.5,10.04131283,0.185874399
5324,10.04148092,0.186113912
5329.5,10.04175272,0.186345976
5335,10.04185643,0.186581796
5340.5,10.04156317,0.186809417
5346,10.0414237,0.18704336
5351.5,10.04167046,0.187274235
5357,10.04238572,0.187512308
5362.5,10.04273977,0.187742558
5368,10.04251089,0.187981194
5373.5,10.04293646,0.188220832
5379,10.04213895,0.188458279
5384.5,10.04280057,0.188694224
5390,10.04350509,0.188934487
5395.5,10.04420962,0.189175814
5401,10.04433121,0.189414701
5406.5,10.04434552,0.189651272
5412,10.04425969,0.189893538
5417.5,10.04407372,0.190132237
5423,10.0442132,0.190372187
5428.5,10.04419174,0.19061026
5434,10.04437771,0.19084827
5439.5,10.04510011,0.19108797
5445,10.04482832,0.191326794
5450.5,10.04428115,0.191565618
5456,10.04429545,0.191802564
5461.5,10.04437055,0.192045081
5467,10.04526462,0.192282841
5472.5,10.04641618,0.192521852
5478,10.04658427,0.19276149
5483.5,10.04610862,0.192999438
5489,10.04589047,0.1932387
5494.5,10.04557218,0.193475959
5500,10.04596557,0.193715596
5505.5,10.04639115,0.193955109
5511,10.04693474,0.194194246
5516.5,10.04697408,0.194434196
5522,10.04683103,0.194670454
5527.5,10.04658427,0.194911155
5533,10.04616227,0.19515073
5538.5,10.04692759,0.195390118
5544,10.04692044,0.19562819
5549.5,10.04699912,0.19586908
5555,10.04732098,0.196108967
5560.5,10.04699554,0.196347416
5566,10.04702415,0.196591622
5571.5,10.04711713,0.196836079
5577,10.04713502,0.197079659
5582.5,10.04702415,0.197326744
5588,10.04756059,0.197571263
5593.5,10.04899468,0.19781791
5599,10.04729237,0.198062742
5604.5,10.04688825,0.198304195
5610,10.04700985,0.198540953
5615.5,10.04729237,0.198781968
5621,10.04732456,0.199020166
5626.5,10.04742827,0.199258051
5632,10.04824009,0.199498878
5637.5,10.04788246,0.199744148
5643,10.04708495,0.199989668
5648.5,10.04709925,0.200239194
5654,10.04754986,0.200487906
5659.5,10.04910912,0.200737119
5665,10.04824009,0.200978259
5670.5,10.04958119,0.201216833
5676,10.04878726,0.201457597
5681.5,10.04744973,0.20169617
5687,10.04825439,0.201939813
5692.5,10.04920568,0.20218452
5698,10.04884448,0.202437864
5703.5,10.04948463,0.202691207
5709,10.04938807,0.202937854
5714.5,10.04920211,0.203179807
5720,10.047439,0.20341957
5725.5,10.04793253,0.20365758
5731,10.04938092,0.203901098
5736.5,10.04957046,0.20414956
5742,10.04948106,0.204406346
5747.5,10.04874434,0.204656873
5753,10.04938807,0.204900954
5758.5,10.04902687,0.205138088
5764,10.04925217,0.205377162
5769.5,10.04902687,0.205625061
5775,10.04962768,0.205882911
5780.5,10.04966345,0.206138257
5786,10.04960265,0.206380273
5791.5,10.04838671,0.206620912
5797,10.04883732,0.206864054
5802.5,10.04949536,0.207117272
5808,10.04966702,0.2073775
5813.5,10.04965629,0.207624335
5819,10.049549,0.207863159
5824.5,10.04929866,0.208108116
5830,10.04863348,0.208364088
5835.5,10.04919138,0.208618559
5841,10.04933085,0.208868585
5846.5,10.04950251,0.209107597
5852,10.0496706,0.209349049
5857.5,10.04968848,0.209606273
5863,10.04881587,0.209869317
5868.5,10.04857983,0.210110457
5874,10.04935231,0.210349469
5879.5,10.04954185,0.210591797
5885,10.04948106,0.210851587
5890.5,10.04963126,0.211111064
5896,10.04957761,0.211352892
5901.5,10.04953112,0.211591466
5907,10.04788603,0.211846061
5912.5,10.0486299,0.212112234
5918,10.04945244,0.21235569
5923.5,10.04957046,0.212596266
5929,10.0495955,0.212856744
5934.5,10.049127,0.213119037
5940,10.04928794,0.213359864
5945.5,10.04870858,0.213605197
5951,10.0482079,0.213875063
5956.5,10.04915204,0.214124463
5962,10.04945602,0.214366604
5967.5,10.0496098,0.214629649
5973,10.04936304,0.214891942
5978.5,10.04755344,0.215130828
5984,10.0472423,0.215384547
5989.5,10.04811134,0.215650033
5995,10.04840102,0.215895428
6000.5,10.04834022,0.216139947
6006,10.04892673,0.216410063
6011.5,10.04833665,0.21666009
6017,10.04809346,0.216901417
6022.5,10.04693117,0.217170219
6028,10.04697408,0.217424251
6033.5,10.04801478,0.217664765
6039,10.04833307,0.217930313
6044.5,10.04749622,0.218189351
6050,10.04714217,0.218429615
6055.5,10.04696335,0.218701358
6061,10.04692044,0.218954139
6066.5,10.04696335,0.219197531
6072,10.04692044,0.219468399
6077.5,10.04700985,0.219718238
6083,10.04701342,0.21997058
6088.5,10.04693117,0.220243262
6094,10.04649844,0.220485653
6099.5,10.04649486,0.220747446
6105,10.04694547,0.221012868
6110.5,10.04695978,0.221256136
6116,10.04692402,0.221531196
6121.5,10.04677739,0.221777593
6127,10.04656281,0.2220407
6132.5,10.04621949,0.222301428
6138,10.04629101,0.222550203
6143.5,10.04603352,0.222827642
6149,10.0462624,0.223067906
6154.5,10.04667725,0.223340338
6160,10.04643049,0.223593306
6165.5,10.04557576,0.223853346
6171,10.04423823,0.224118142
6176.5,10.04438128,0.22436698
6182,10.04437413,0.224642103
6187.5,10.04458155,0.224888249
6193,10.04483547,0.225167566
6198.5,10.04464593,0.225407704
6204,10.0442275,0.225687771
6209.5,10.04423823,0.225933605
6215,10.04422035,0.226207288
6220.5,10.0442132,0.226461821
6226,10.04422035,0.226734879
6231.5,10.04406299,0.226985344
6237,10.04408087,0.227259215
6242.5,10.04327979,0.227513873
6248,10.04302587,0.227783426
6253.5,10.04331197,0.228039336
6259,10.04341569,0.228311079
6264.5,10.04309024,0.228563484
6270,10.04340853,0.228839921
6275.5,10.04301514,0.229089698
6281,10.04186716,0.229372081
6286.5,10.04164185,0.22961854
6292,10.04152026,0.229900172
6297.5,10.0419065,0.230145755
6303,10.04155244,0.2304282
6308.5,10.04149165,0.230684298
6314,10.04142728,0.230953726
6319.5,10.04130568,0.23122403
6325,10.0412878,0.2314785
6330.5,10.04108395,0.23176445
6336,10.04091229,0.232018858
6341.5,10.04140939,0.23229179
6347,10.04063692,0.232566538
6352.5,10.03953185,0.232821071
6358,10.03877368,0.233106896
6363.5,10.03903117,0.233360427
6369,10.03902402,0.233632296
6374.5,10.03902402,0.233910423
6380,10.03885593,0.234167084
6385.5,10.03864851,0.234443897
6391,10.03839817,0.234719458
6396.5,10.03831949,0.234974992
6402,10.03852691,0.235256499
6407.5,10.03824796,0.23553012
6413,10.038273,0.23578484
6418.5,10.03844108,0.236069163
6424,10.03764357,0.236346164
6429.5,10.03624882,0.236597693
6435,10.03595914,0.236881077
6440.5,10.03630604,0.23715933
6446,10.0361773,0.237416866
6451.5,10.03599491,0.237693992
6457,10.03601637,0.237979692
6462.5,10.03601994,0.238248619
6468,10.03541555,0.238511538
6473.5,10.03456082,0.238795361
6479,10.03507938,0.239080748
6484.5,10.03585186,0.239350551
6490,10.03528323,0.239614472
6495.5,10.03467884,0.239896166
6501,10.03350224,0.240181741
6506.5,10.03338065,0.240461683
6512,10.03329482,0.240728358
6517.5,10.03315534,0.240996972
6523,10.03286209,0.241281045
6528.5,10.03318753,0.241566244
6534,10.03313388,0.241846374
6539.5,10.03268327,0.242120433
6545,10.03075924,0.24238742
6550.5,10.03054108,0.242665923
6556,10.03068771,0.242952749
6561.5,10.03060546,0.243240014
6567,10.03049101,0.243523711
6572.5,10.03034081,0.243802527
6578,10.03001537,0.244075898
6583.5,10.0285026,0.244355089
6589,10.02828803,0.244633341
6594.5,10.02802338,0.244918728
6600,10.02810921,0.245202175
6605.5,10.0282773,0.245491004
6611,10.02784457,0.245777268
6616.5,10.02722587,0.246063844
6622,10.02652134,0.246349732
6627.5,10.02727236,0.246634555
6633,10.02672162,0.246916062
6638.5,10.0268754,0.247201825
6644,10.02639617,0.247489903
6649.5,10.0254127,0.247775415
6655,10.02507653,0.248060239
6660.5,10.02459373,0.248343874
6666,10.02403583,0.248635081
6671.5,10.02441849,0.248926038
6677,10.02446141,0.2492113
6682.5,10.0236639,0.249498127
6688,10.022473,0.24978658
6693.5,10.02225484,0.250076661
6699,10.02217259,0.250364051
6704.5,10.02221908,0.250651503
6710,10.02116408,0.250940708
6715.5,10.02161827,0.251228098
6721,10.02114977,0.25151361
6726.5,10.01976933,0.251804755
6732,10.01934018,0.252095462
6737.5,10.01880373,0.252391676
6743,10.01919355,0.252692834
6748.5,10.01872148,0.252990926
6754,10.01854267,0.253281445
6759.5,10.0173017,0.253569899
6765,10.01685466,0.253856162
6770.5,10.01634683,0.254144053
6776,10.01634683,0.25444471
6781.5,10.01525607,0.254744429
6787,10.01563158,0.255046151
6792.5,10.01478757,0.25533473
6798,10.01418318,0.25562237
6803.5,10.01405444,0.255921213
6809,10.01229491,0.256227754
6814.5,10.01198377,0.256531478
6820,10.01185145,0.256819619
6825.5,10.01144018,0.257118024
6831,10.01131143,0.257431574
6836.5,10.01127924,0.257727412
6842,10.00954475,0.258020122
6847.5,10.00861492,0.258331732
6853,10.00815358,0.258635707
6858.5,10.00831808,0.258925788
6864,10.00832166,0.259240527
6869.5,10.00629749,0.25954469
6875,10.00596489,0.259835459
6880.5,10.00516381,0.260151638
6886,10.00404801,0.260452671
6891.5,10.00371899,0.260754268
6897,10.00326838,0.261071197
6902.5,10.00320043,0.261364658
6908,10.00300373,0.26168841
6913.5,10.0012907,0.261980681
6919,10.00042881,0.262298299
6924.5,9.999420303,0.262602399
6930,9.998762268,0.262918703
6935.5,9.998064893,0.263227497
6941,9.997925418,0.26353917
6946.5,9.997517723,0.263849278
6952,9.995708126,0.264165394
6957.5,9.994932073,0.264468555
6963,9.994781869,0.264787363
6968.5,9.993115323,0.265092151
6974,9.992464441,0.265422036
6979.5,9.992314237,0.265721129
6985,9.992289203,0.266047134
6990.5,9.990729945,0.266367881
6996,9.989306586,0.266671668
7001.5,9.988158601,0.26700293
7007,9.988183635,0.267321237
7012.5,9.986828225,0.267633786
7018,9.98625602,0.267958664
7023.5,9.985161679,0.268288674
7029,9.984110253,0.268605353
7034.5,9.981538909,0.268917527
7040,9.981413739,0.269252856
7045.5,9.98130645,0.269585683
7051,9.979936736,0.269907369
7056.5,9.978652852,0.270226364
7062,9.977129357,0.270545735
7067.5,9.976031439,0.270877873
7073,9.974414961,0.271209948
7078.5,9.973270552,0.271541085
7084,9.973052399,0.271864586
7089.5,9.971786396,0.272188588
7095,9.970466749,0.272516095
7100.5,9.96793832,0.272847544
7106,9.966354028,0.273176928
7111.5,9.964927093,0.273507064
7117,9.963664667,0.273842393
7122.5,9.962330715,0.27417547
7128,9.961930171,0.27450886
7133.5,9.959519759,0.274846505
7139,9.956955567,0.275183024
7144.5,9.955961362,0.275520482
7150,9.954201833,0.275865825
7155.5,9.951798573,0.276205849
7161,9.950228587,0.27655113
7166.5,9.948669329,0.276895785
7172,9.946373358,0.277234306
7177.5,9.943716183,0.27757095
7183,9.941048279,0.277910348
7188.5,9.939968243,0.278262951
7194,9.937758102,0.278612613
7199.5,9.935050859,0.278956267
7205,9.932193412,0.279295352
7210.5,9.929536237,0.279654213
7216,9.926442756,0.280005127
7221.5,9.923696174,0.280340582
7227,9.92118205,0.280694499
7232.5,9.918535603,0.281056302
7238,9.915882004,0.281395262
7243.5,9.913121117,0.281755313
7249,9.909405363,0.28211092
7254.5,9.905500067,0.282460895
7260,9.902177704,0.282825201
7265.5,9.899059188,0.28316704
7271,9.894853484,0.283532473
7276.5,9.89117707,0.283881321
7282,9.886699568,0.284240684
7287.5,9.883248459,0.284596979
7293,9.878352533,0.284954151
7298.5,9.872870098,0.285313764
7304,9.86946548,0.285672
7309.5,9.8650452,0.286031049
7315,9.861211429,0.286391851
7320.5,9.855796942,0.286748522
7326,9.85058988,0.287121716
7331.5,9.844917902,0.287474194
7337,9.839492687,0.287850141
7342.5,9.834074624,0.288199615
7348,9.828538545,0.288566488
7353.5,9.823342211,0.288933799
7359,9.817931301,0.289289156
7364.5,9.812080509,0.289664102
7370,9.8047849,0.290026718
7375.5,9.798344022,0.290384767
7381,9.792686349,0.290760776
7386.5,9.785312062,0.291120139
7392,9.779271727,0.291481254
7397.5,9.771332387,0.291859079
7403,9.764737729,0.292220193
7408.5,9.757048729,0.292579493
7414,9.749270323,0.292958382
7419.5,9.741080644,0.293318495
7425,9.73432863,0.293683741
7430.5,9.726864936,0.294060502
7436,9.718171002,0.294424996
7441.5,9.708522201,0.294784984
7447,9.699999928,0.295160807
7452.5,9.691516995,0.295528743
7458,9.682565569,0.295888231
7463.5,9.672848819,0.296259547
7469,9.664551852,0.296634618
7474.5,9.654849407,0.296997485
7480,9.645411607,0.297359476
7485.5,9.634478923,0.297731105
7491,9.625084038,0.298091594
7496.5,9.615327949,0.29845953
7502,9.604881639,0.298839921
7507.5,9.595082634,0.299205167
7513,9.583681457,0.299573979
7518.5,9.572273128,0.29994323
7524,9.560829035,0.300322307
7529.5,9.549910656,0.300692434
7535,9.538795581,0.301056678
7540.5,9.527680506,0.30142305
7546,9.515703548,0.301803441
7551.5,9.50341903,0.302177698
7557,9.490186798,0.30254188
7562.5,9.477340804,0.302909691
7568,9.465210066,0.3032852
7573.5,9.452435598,0.303659583
7579,9.439453706,0.304026456
7584.5,9.425459726,0.304394204
7590,9.412191731,0.304769651
7595.5,9.39701758,0.305148665
7601,9.383066516,0.305520044
7606.5,9.369097571,0.305891485
7612,9.354799608,0.306262488
7617.5,9.339335778,0.306635431
7623,9.323746778,0.307016386
7628.5,9.307860947,0.307395337
7634,9.291796302,0.30776271
7639.5,9.276314591,0.30813265
7645,9.260071132,0.30850528
7650.5,9.243627402,0.308880101
7656,9.22670445,0.309260241
7661.5,9.209352345,0.309635125
7667,9.191621154,0.310008506
7672.5,9.172920792,0.310377319
7678,9.154288379,0.310750137
7683.5,9.136356916,0.311127399
7689,9.118107165,0.311508791
7694.5,9.098770225,0.311889557
7700,9.07862147,0.312270762
7705.5,9.058204493,0.312649275
7711,9.037494262,0.313025473
7716.5,9.017002184,0.313401546
7722,8.995447951,0.313775803
7727.5,8.974040346,0.314154504
7733,8.953233555,0.314532642
7738.5,8.930112912,0.314906837
7744,8.906842065,0.315287791
7749.5,8.882870268,0.315668057
7755,8.859159539,0.316048823
7760.5,8.83473713,0.316432344
7766,8.810196704,0.316814362
7771.5,8.784883802,0.317197068
7777,8.758644644,0.317580651
7782.5,8.73169023,0.317963295
7788,8.70476085,0.318348067
7793.5,8.676876603,0.318729146
7799,8.64844161,0.319113104
7804.5,8.620042379,0.319494684
7810,8.590462976,0.319878643
7815.5,8.560350708,0.320261787
7821,8.528396656,0.320647185
7826.5,8.4968503,0.321033709
7832,8.464631603,0.321419357
7837.5,8.431465193,0.32180876
7843,8.396843236,0.322197162
7848.5,8.361852924,0.322590696
7854,8.325070895,0.322979849
7859.5,8.287219559,0.323362868
7865,8.248509917,0.323746639
7870.5,8.209088594,0.324137168
7876,8.16820815,0.324534457
7881.5,8.124795701,0.32493281
7887,8.078046583,0.325327095
7892.5,8.028021594,0.325721504
7898,7.972428338,0.32613275
7903.5,7.90293051,0.3265383
7909,6.955213026,0.327547043
7914.5,2.955470518,0.330647248
7920,2.513031174,0.331291434
7925.5,1.980430262,0.331940376
7931,1.433409794,0.332594013
7936.5,1.082008206,0.333223867
7942,0.681758224,0.333949852
7947.5,0.584036403,0.334562683
7953,0.480714129,0.33502725
7958.5,0.309853829,0.335544014
7964,0.066820643,0.336090442
7969.5,0.014499683,0.33646495
7975,0.012547035,0.336805475
7980.5,0.012511272,0.337181359
7986,0.012557764,0.337560686
7991.5,0.012568492,0.337927183
7997,0.012586374,0.338287547
8002.5,0.012829561,0.338568929
8005.5,0.01292612,0.338567927